Workbook

Sheet Apr2025-EXPENSE
B1: APR 2025 EXPENSES
A2: FLAT # | B2: 1 | C2: WATER USED IN LTRS | D2: COMMON AREA WATER EQUALLY DIVIDED (L) | E2: TOTAL FRESH WATER CONSUMED(L) | F2: %OF TOTAL WATER USED | G2: WATER EXPENSE SHARING BY % | H2: #METERS | I2: METER RENT (Rs) | J2: TOTAL VARIABLE = (COMMON AREA METER RENT + WATER EXPENSE+ FLAT METER RENT (Rs)) | K2: FIXED EXPENSE SHARE(Rs) | L2: PARKING FEE(Rs) | M2: CLUB HOUSE FEE (Rs) | N2: SHIFTING FEE (Rs) | O2: GYM USAGE FEE(Rs) | P2: COVID+ GARBAGE FEE (Rs) | Q2: ANNUAL MEMBERSHIP FEE - 2022-2023 (Rs) | R2: TOTAL EXPENSE TO BE PAID (Rs)
A3: CH | B3: MPFOWA | C3: 0 | D3: 0 | H3: 1 | I3: =T7 -> 112.21
A4: GYM | B4: MPFOWA | C4: 0 | D4: 0 | H4: 1 | I4: =T7 -> 112.21 | S4: TOTAL FIXED EXPENSE | T4: ='ANNUAL-EXPENSE-DETAILS'!BF3 -> 287528
A5: BSMT | B5: MPFOWA | C5: 0 | D5: 0 | H5: 1 | I5: =T7 -> 112.21 | S5: TOTAL WATER EXPENSE | T5: ='ANNUAL-EXPENSE-DETAILS'!BE3 -> 39800
A6: F1 | B6: Shailesh Srivastava / Azeem Nawaz | C6: 2141.5 | D6: =SUM($C$3:$C$5)/64 -> 0 | E6: =C6+D6 -> 2141.5 | F6: =IF($C$70=0, 0, E6/$C$70) -> 0.0055356014 | G6: =F6*$T$5 -> 220.31694 | H6: 3 | I6: =$T$7*H6 -> 336.63 | J6: =G6+$T$9+I6 -> 562.20678 | K6: =$T$4/64 -> 4492.625 | L6: 0 | M6: 0 | N6: 0 | O6: 0 | P6: 0 | Q6: 500 | R6: =(J6+K6+L6+M6+Q6+N6+O6+P6)*$B$2 -> 5554.8318
A7: F2 | B7: Shanthanu | C7: 13938 | D7: =SUM($C$3:$C$5)/64 -> 0 | E7: =C7+D7 -> 13938 | F7: =IF($C$70=0, 0, E7/$C$70) -> 0.036028584 | G7: =F7*$T$5 -> 1433.9376 | H7: 4 | I7: =$T$7*H7 -> 448.84 | J7: =G7+$T$9+I7 -> 1888.0375 | K7: =$T$4/64 -> 4492.625 | L7: 0 | M7: 0 | N7: 0 | O7: 0 | P7: 0 | Q7: 500 | R7: =(J7+K7+L7+M7+Q7+N7+O7+P7)*$B$2 -> 6880.6625 | S7: RENT PER METER (Rs) | T7: 112.21
A8: F3 | B8: Samrat Kar | C8: 12648.5 | D8: =SUM($C$3:$C$5)/64 -> 0 | E8: =C8+D8 -> 12648.5 | F8: =IF($C$70=0, 0, E8/$C$70) -> 0.032695333 | G8: =F8*$T$5 -> 1301.2742 | H8: 4 | I8: =$T$7*H8 -> 448.84 | J8: =G8+$T$9+I8 -> 1755.3741 | K8: =$T$4/64 -> 4492.625 | L8: 750 | M8: 0 | N8: 0 | O8: 0 | P8: 0 | Q8: 500 | R8: =(J8+K8+L8+M8+Q8+N8+O8+P8)*$B$2 -> 7497.9991 | S8: COMMON AREA METER RENT(Rs) | T8: =$T$7*3 -> 336.63
A9: F4 | B9: Renu R | C9: 2944 | D9: =SUM($C$3:$C$5)/64 -> 0 | E9: =C9+D9 -> 2944 | F9: =IF($C$70=0, 0, E9/$C$70) -> 0.0076099979 | G9: =F9*$T$5 -> 302.87792 | H9: 4 | I9: =$T$7*H9 -> 448.84 | J9: =G9+$T$9+I9 -> 756.97776 | K9: =$T$4/64 -> 4492.625 | L9: 0 | M9: 0 | N9: 0 | O9: 0 | P9: 0 | Q9: 500 | R9: =(J9+K9+L9+M9+Q9+N9+O9+P9)*$B$2 -> 5749.6028 | S9: COMMON AREA METER RENT/FLAT (Rs) | T9: =T8/64 -> 5.2598437
A10: F5 | B10: Vamsidhar Bethanabatla / Madhuri Anumula | C10: 645.5 | D10: =SUM($C$3:$C$5)/64 -> 0 | E10: =C10+D10 -> 645.5 | F10: =IF($C$70=0, 0, E10/$C$70) -> 0.0016685644 | G10: =F10*$T$5 -> 66.408864 | H10: 3 | I10: =$T$7*H10 -> 336.63 | J10: =G10+$T$9+I10 -> 408.29871 | K10: =$T$4/64 -> 4492.625 | L10: 0 | M10: 0 | N10: 0 | O10: 0 | P10: 0 | Q10: 500 | R10: =(J10+K10+L10+M10+Q10+N10+O10+P10)*$B$2 -> 5400.9237
A11: F6 | B11: Meghana Viral Shah and Vviral Shah (Owner) / Sangeet and Swagat (Tenent) | C11: 5452 | D11: =SUM($C$3:$C$5)/64 -> 0 | E11: =C11+D11 -> 5452 | F11: =IF($C$70=0, 0, E11/$C$70) -> 0.014092972 | G11: =F11*$T$5 -> 560.90028 | H11: 3 | I11: =$T$7*H11 -> 336.63 | J11: =G11+$T$9+I11 -> 902.79012 | K11: =$T$4/64 -> 4492.625 | L11: 0 | M11: 0 | N11: 0 | O11: 0 | P11: 0 | Q11: 500 | R11: =(J11+K11+L11+M11+Q11+N11+O11+P11)*$B$2 -> 5895.4151 | S11: BALANCE IN ACCOUNT ON 30-Apr-2023
A12: F7 | B12: Vimal NK | C12: 938 | D12: =SUM($C$3:$C$5)/64 -> 0 | E12: =C12+D12 -> 938 | F12: =IF($C$70=0, 0, E12/$C$70) -> 0.0024246529 | G12: =F12*$T$5 -> 96.501185 | H12: 3 | I12: =$T$7*H12 -> 336.63 | J12: =G12+$T$9+I12 -> 438.39103 | K12: =$T$4/64 -> 4492.625 | L12: 750 | M12: 0 | N12: 0 | O12: 0 | P12: 0 | Q12: 500 | R12: =(J12+K12+L12+M12+Q12+N12+O12+P12)*$B$2 -> 6181.016 | S12: TOTAL NON MAINTENANCE CORPUS COLLECTION
A13: F8 | B13: Sujeet Kumar (Tenant)/Sreejith Menon (Owner) | C13: 249 | D13: =SUM($C$3:$C$5)/64 -> 0 | E13: =C13+D13 -> 249 | F13: =IF($C$70=0, 0, E13/$C$70) -> 0.00064364453 | G13: =F13*$T$5 -> 25.617052 | H13: 3 | I13: =$T$7*H13 -> 336.63 | J13: =G13+$T$9+I13 -> 367.5069 | K13: =$T$4/64 -> 4492.625 | L13: 0 | M13: 0 | N13: 0 | O13: 0 | P13: 0 | Q13: 500 | R13: =(J13+K13+L13+M13+Q13+N13+O13+P13)*$B$2 -> 5360.1319 | S13: TOTAL FD DONE
A14: F9 | B14: Vijay Suswaram (Owner) / Divya Shikha (Tenant) | C14: 1109.5 | D14: =SUM($C$3:$C$5)/64 -> 0 | E14: =C14+D14 -> 1109.5 | F14: =IF($C$70=0, 0, E14/$C$70) -> 0.0028679663 | G14: =F14*$T$5 -> 114.14506 | H14: 4 | I14: =$T$7*H14 -> 448.84 | J14: =G14+$T$9+I14 -> 568.2449 | K14: =$T$4/64 -> 4492.625 | L14: 0 | M14: 0 | N14: 0 | O14: 0 | P14: 0 | Q14: 500 | R14: =(J14+K14+L14+M14+Q14+N14+O14+P14)*$B$2 -> 5560.8699 | S14: AMOUNT AVAILABLE FOR NON MAINTENANCE CORPUS IN CURRENT AC | T14: =T12-T13 -> 0
A15: F10 | B15: Aby Thomas | C15: 2961 | D15: =SUM($C$3:$C$5)/64 -> 0 | E15: =C15+D15 -> 2961 | F15: =IF($C$70=0, 0, E15/$C$70) -> 0.0076539415 | G15: =F15*$T$5 -> 304.62687 | H15: 3 | I15: =$T$7*H15 -> 336.63 | J15: =G15+$T$9+I15 -> 646.51672 | K15: =$T$4/64 -> 4492.625 | L15: 0 | M15: 0 | N15: 1000 | O15: 0 | P15: 0 | Q15: 500 | R15: =(J15+K15+L15+M15+Q15+N15+O15+P15)*$B$2 -> 6639.1417 | S15: Pending vendor payments
A16: F11 | B16: Niwin Anto | C16: 509 | D16: =SUM($C$3:$C$5)/64 -> 0 | E16: =C16+D16 -> 509 | F16: =IF($C$70=0, 0, E16/$C$70) -> 0.0013157232 | G16: =F16*$T$5 -> 52.365781 | H16: 3 | I16: =$T$7*H16 -> 336.63 | J16: =G16+$T$9+I16 -> 394.25563 | K16: =$T$4/64 -> 4492.625 | L16: 0 | M16: 0 | N16: 0 | O16: 0 | P16: 0 | Q16: 500 | R16: =(J16+K16+L16+M16+Q16+N16+O16+P16)*$B$2 -> 5386.8806 | S16: AMOUNT AVAILABLE FOR MAINTENANCE | T16: =T11-T14-T15 -> 0
A17: F12 | B17: Anirudh Singh | C17: 0 | D17: =SUM($C$3:$C$5)/64 -> 0 | E17: =C17+D17 -> 0 | F17: =IF($C$70=0, 0, E17/$C$70) -> 0 | G17: =F17*$T$5 -> 0 | H17: 3 | I17: =$T$7*H17 -> 336.63 | J17: =G17+$T$9+I17 -> 341.88984 | K17: =$T$4/64 -> 4492.625 | L17: 0 | M17: 0 | N17: 0 | O17: 0 | P17: 0 | Q17: 500 | R17: =(J17+K17+L17+M17+Q17+N17+O17+P17)*$B$2 -> 5334.5148 | S17: TOTAL EXPENSE FOR THE MONTH | T17: ='ANNUAL-EXPENSE-DETAILS'!BI9 -> 0
A18: F13 | B18: Sanchay Saxena | C18: 261.5 | D18: =SUM($C$3:$C$5)/64 -> 0 | E18: =C18+D18 -> 261.5 | F18: =IF($C$70=0, 0, E18/$C$70) -> 0.000675956 | G18: =F18*$T$5 -> 26.903049 | H18: 4 | I18: =$T$7*H18 -> 448.84 | J18: =G18+$T$9+I18 -> 481.00289 | K18: =$T$4/64 -> 4492.625 | L18: 0 | M18: 0 | N18: 0 | O18: 0 | P18: 0 | Q18: 500 | R18: =(J18+K18+L18+M18+Q18+N18+O18+P18)*$B$2 -> 5473.6279 | S18: Maintenance deficit | T18: =T16-T17 -> 0
A19: F14 | B19: Hemant Patel | C19: 1 | D19: =SUM($C$3:$C$5)/64 -> 0 | E19: =C19+D19 -> 1 | F19: =IF($C$70=0, 0, E19/$C$70) -> 2.5849178e-06 | G19: =F19*$T$5 -> 0.10287973 | H19: 4 | I19: =$T$7*H19 -> 448.84 | J19: =G19+$T$9+I19 -> 454.20272 | K19: =$T$4/64 -> 4492.625 | L19: 750 | M19: 0 | N19: 0 | O19: 0 | P19: 0 | Q19: 500 | R19: =(J19+K19+L19+M19+Q19+N19+O19+P19)*$B$2 -> 6196.8277
A20: F15 | B20: Senthil.Vijayaragavan | C20: 2992.5 | D20: =SUM($C$3:$C$5)/64 -> 0 | E20: =C20+D20 -> 2992.5 | F20: =IF($C$70=0, 0, E20/$C$70) -> 0.0077353665 | G20: =F20*$T$5 -> 307.86759 | H20: 4 | I20: =$T$7*H20 -> 448.84 | J20: =G20+$T$9+I20 -> 761.96743 | K20: =$T$4/64 -> 4492.625 | L20: 750 | M20: 0 | N20: 0 | O20: 0 | P20: 0 | Q20: 500 | R20: =(J20+K20+L20+M20+Q20+N20+O20+P20)*$B$2 -> 6504.5924
A21: F16 | B21: Sreeja Sudharma | C21: 11572 | D21: =SUM($C$3:$C$5)/64 -> 0 | E21: =C21+D21 -> 11572 | F21: =IF($C$70=0, 0, E21/$C$70) -> 0.029912669 | G21: =F21*$T$5 -> 1190.5242 | H21: 3 | I21: =$T$7*H21 -> 336.63 | J21: =G21+$T$9+I21 -> 1532.4141 | K21: =$T$4/64 -> 4492.625 | L21: 0 | M21: 0 | N21: 0 | O21: 0 | P21: 0 | Q21: 500 | R21: =(J21+K21+L21+M21+Q21+N21+O21+P21)*$B$2 -> 6525.0391
A22: G1 | B22: Venkataramanan C | C22: 9626.5 | D22: =SUM($C$3:$C$5)/64 -> 0 | E22: =C22+D22 -> 9626.5 | F22: =IF($C$70=0, 0, E22/$C$70) -> 0.024883711 | G22: =F22*$T$5 -> 990.3717 | H22: 3 | I22: =$T$7*H22 -> 336.63 | J22: =G22+$T$9+I22 -> 1332.2615 | K22: =$T$4/64 -> 4492.625 | L22: 0 | M22: 0 | N22: 0 | O22: 0 | P22: 0 | Q22: 500 | R22: =(J22+K22+L22+M22+Q22+N22+O22+P22)*$B$2 -> 6324.8865
A23: G2 | B23: Kaushik Kasibhatla | C23: 18123 | D23: =SUM($C$3:$C$5)/64 -> 0 | E23: =C23+D23 -> 18123 | F23: =IF($C$70=0, 0, E23/$C$70) -> 0.046846465 | G23: =F23*$T$5 -> 1864.4893 | H23: 4 | I23: =$T$7*H23 -> 448.84 | J23: =G23+$T$9+I23 -> 2318.5891 | K23: =$T$4/64 -> 4492.625 | L23: 0 | M23: 0 | N23: 0 | O23: 0 | P23: 0 | Q23: 500 | R23: =(J23+K23+L23+M23+Q23+N23+O23+P23)*$B$2 -> 7311.2141
A24: G3 | B24: Balakrishnan | C24: 10814 | D24: =SUM($C$3:$C$5)/64 -> 0 | E24: =C24+D24 -> 10814 | F24: =IF($C$70=0, 0, E24/$C$70) -> 0.027953301 | G24: =F24*$T$5 -> 1112.5414 | H24: 4 | I24: =$T$7*H24 -> 448.84 | J24: =G24+$T$9+I24 -> 1566.6412 | K24: =$T$4/64 -> 4492.625 | L24: 0 | M24: 0 | N24: 0 | O24: 0 | P24: 0 | Q24: 500 | R24: =(J24+K24+L24+M24+Q24+N24+O24+P24)*$B$2 -> 6559.2662
A25: G4 | B25: Ashwin Pandith | C25: 14242 | D25: =SUM($C$3:$C$5)/64 -> 0 | E25: =C25+D25 -> 14242 | F25: =IF($C$70=0, 0, E25/$C$70) -> 0.036814399 | G25: =F25*$T$5 -> 1465.2131 | H25: 4 | I25: =$T$7*H25 -> 448.84 | J25: =G25+$T$9+I25 -> 1919.3129 | K25: =$T$4/64 -> 4492.625 | L25: 0 | M25: 0 | N25: 0 | O25: 0 | P25: 0 | Q25: 500 | R25: =(J25+K25+L25+M25+Q25+N25+O25+P25)*$B$2 -> 6911.9379
A26: G5 | B26: Mayank Phophaliya | C26: 1868.5 | D26: =SUM($C$3:$C$5)/64 -> 0 | E26: =C26+D26 -> 1868.5 | F26: =IF($C$70=0, 0, E26/$C$70) -> 0.0048299189 | G26: =F26*$T$5 -> 192.23077 | H26: 3 | I26: =$T$7*H26 -> 336.63 | J26: =G26+$T$9+I26 -> 534.12061 | K26: =$T$4/64 -> 4492.625 | L26: 0 | M26: 0 | N26: 0 | O26: 0 | P26: 0 | Q26: 500 | R26: =(J26+K26+L26+M26+Q26+N26+O26+P26)*$B$2 -> 5526.7456
A27: G6 | B27: Mohit Daga | C27: 11222.5 | D27: =SUM($C$3:$C$5)/64 -> 0 | E27: =C27+D27 -> 11222.5 | F27: =IF($C$70=0, 0, E27/$C$70) -> 0.02900924 | G27: =F27*$T$5 -> 1154.5677 | H27: 3 | I27: =$T$7*H27 -> 336.63 | J27: =G27+$T$9+I27 -> 1496.4576 | K27: =$T$4/64 -> 4492.625 | L27: 0 | M27: 0 | N27: 0 | O27: 0 | P27: 0 | Q27: 500 | R27: =(J27+K27+L27+M27+Q27+N27+O27+P27)*$B$2 -> 6489.0826
A28: G7 | B28: Prince Richfield | C28: 4402.5 | D28: =SUM($C$3:$C$5)/64 -> 0 | E28: =C28+D28 -> 4402.5 | F28: =IF($C$70=0, 0, E28/$C$70) -> 0.011380101 | G28: =F28*$T$5 -> 452.928 | H28: 3 | I28: =$T$7*H28 -> 336.63 | J28: =G28+$T$9+I28 -> 794.81784 | K28: =$T$4/64 -> 4492.625 | L28: 0 | M28: 0 | N28: 0 | O28: 0 | P28: 0 | Q28: 500 | R28: =(J28+K28+L28+M28+Q28+N28+O28+P28)*$B$2 -> 5787.4428
A29: G8 | B29: Ranjithkumar R / Sameer (tenant) / Princy (tenant) | C29: 9830 | D29: =SUM($C$3:$C$5)/64 -> 0 | E29: =C29+D29 -> 9830 | F29: =IF($C$70=0, 0, E29/$C$70) -> 0.025409742 | G29: =F29*$T$5 -> 1011.3077 | H29: 3 | I29: =$T$7*H29 -> 336.63 | J29: =G29+$T$9+I29 -> 1353.1976 | K29: =$T$4/64 -> 4492.625 | L29: 0 | M29: 0 | N29: 0 | O29: 0 | P29: 0 | Q29: 500 | R29: =(J29+K29+L29+M29+Q29+N29+O29+P29)*$B$2 -> 6345.8226
A30: G9 | B30: Chandramouli | C30: 6673.5 | D30: =SUM($C$3:$C$5)/64 -> 0 | E30: =C30+D30 -> 6673.5 | F30: =IF($C$70=0, 0, E30/$C$70) -> 0.017250449 | G30: =F30*$T$5 -> 686.56786 | H30: 5 | I30: =$T$7*H30 -> 561.05 | J30: =G30+$T$9+I30 -> 1252.8777 | K30: =$T$4/64 -> 4492.625 | L30: 0 | M30: 0 | N30: 0 | O30: 0 | P30: 0 | Q30: 500 | R30: =(J30+K30+L30+M30+Q30+N30+O30+P30)*$B$2 -> 6245.5027
... A69: T16 | B69: Madhusoodanan P.R. | C69: 3201.5 | D69: =SUM($C$3:$C$5)/64 -> 0 | E69: =C69+D69 -> 3201.5 | F69: =IF($C$70=0, 0, E69/$C$70) -> 0.0082756143 | G69: =F69*$T$5 -> 329.36945 | H69: 3 | I69: =$T$7*H69 -> 336.63 | J69: =G69+$T$9+I69 -> 671.25929 | K69: =$T$4/64 -> 4492.625 | L69: 0 | M69: 0 | N69: 0 | O69: 0 | P69: 0 | Q69: 500 | R69: =(J69+K69+L69+M69+Q69+N69+O69+P69)*$B$2 -> 5663.8843
A70: TOTAL | B70: TOTAL | C70: =SUM(C3:C69) -> 386859.5 | D70: =SUM(D3:D69) -> 0 | E70: =SUM(E5:E69) -> 386859.5 | F70: =SUM(F6:F69) -> 1 | G70: =SUM(G6:G69) -> 39800 | H70: =SUM(H3:H69) -> 223 | I70: =SUM(I3:I69) -> 25022.83 | J70: =SUM(J6:J69) -> 64822.83 | K70: =SUM(K6:K69) -> 287528 | L70: =SUM(L6:L69) -> 3750 | M70: =SUM(M6:M69) -> 0 | N70: =SUM(N6:N69) -> 1000 | O70: =SUM(O6:O69) -> 0 | P70: =SUM(P6:P69) -> 0 | Q70: =SUM(Q6:Q69) -> 32000 | R70: =SUM(R6:R69) -> 389100.83

Sheet Apr2025-COLLECTION
A1: FLAT # | C1: Amount | D1: Date | E1: Amount | F1: Date | G1: Amount | H1: Date | I1: Amount | J1: Date | K1: Total
A2: F1 | B2: Shailesh Srivastava / Azeem Nawaz | C2: 4944 | D2: 45775 | K2: =SUM(C2,E2,G2,I2) -> 4944
A3: F2 | B3: Shanthanu | K3: =SUM(C3,E3,G3,I3) -> 0
A4: F3 | B4: Samrat Kar | C4: 6000 | D4: 45748 | E4: 6317 | F4: 45768 | K4: =SUM(C4,E4,G4,I4) -> 12317
A5: F4 | B5: Renu R | C5: 5000 | D5: 45761 | K5: =SUM(C5,E5,G5,I5) -> 5000
A6: F5 | B6: Vamsidhar Bethanabatla / Madhuri Anumula | C6: 9457 | D6: 45768 | K6: =SUM(C6,E6,G6,I6) -> 9457
A7: F6 | B7: Meghana Viral Shah and Vviral Shah (Owner) / Sangeet and Swagat (Tenent) | C7: 4155 | D7: 45756 | E7: 4871 | F7: 45775 | K7: =SUM(C7,E7,G7,I7) -> 9026
A8: F7 | B8: Vimal NK | K8: =SUM(C8,E8,G8,I8) -> 0
A9: F8 | B9: Sujeet Kumar (Tenant)/Sreejith Menon (Owner) | C9: 4603 | D9: 45762 | K9: =SUM(C9,E9,G9,I9) -> 4603
A10: F9 | B10: Vijay Suswaram (Owner) / Divya Shikha (Tenant) | C10: 4943 | D10: 45767 | K10: =SUM(C10,E10,G10,I10) -> 4943
A11: F10 | B11: Aby Thomas | C11: 5314 | D11: 45750 | K11: =SUM(C11,E11,G11,I11) -> 5314
A12: F11 | B12: N. Geetha | C12: 4632 | D12: 45762 | K12: =SUM(C12,E12,G12,I12) -> 4632
A13: F12 | B13: Anirudh Singh | C13: 4603 | D13: 45761 | K13: =SUM(C13,E13,G13,I13) -> 4603
A14: F13 | B14: Sanchay Saxena | C14: 4730 | D14: 45775 | K14: =SUM(C14,E14,G14,I14) -> 4730
A15: F14 | B15: Hemant Patel | C15: 5727 | D15: 45765 | K15: =SUM(C15,E15,G15,I15) -> 5727
A16: F15 | B16: Senthil.Vijayaragavan | C16: 5709 | D16: 45769 | K16: =SUM(C16,E16,G16,I16) -> 5709
A17: F16 | B17: Sreeja Sudharma | K17: =SUM(C17,E17,G17,I17) -> 0
A18: G1 | B18: Venkataramanan C | C18: 5139 | D18: 45770 | K18: =SUM(C18,E18,G18,I18) -> 5139
A19: G2 | B19: Kaushik Kasibhatla | C19: 5645 | D19: 45765 | K19: =SUM(C19,E19,G19,I19) -> 5645
A20: G3 | B20: Balakrishnan | C20: 5364 | D20: 45771 | K20: =SUM(C20,E20,G20,I20) -> 5364
A21: G4 | B21: Ashwin Pandith | C21: 5441 | D21: 45771 | K21: =SUM(C21,E21,G21,I21) -> 5441
A22: G5 | B22: Mayank Phophaliya | K22: =SUM(C22,E22,G22,I22) -> 0
A23: G6 | B23: Mohit Daga | K23: =SUM(C23,E23,G23,I23) -> 0
A24: G7 | B24: Prince Richfield | C24: 9614 | D24: 45762 | K24: =SUM(C24,E24,G24,I24) -> 9614
A25: G8 | B25: Ranjithkumar R / Sameer (tenant) / Princy (tenant) | C25: 15000 | D25: 45750 | K25: =SUM(C25,E25,G25,I25) -> 15000
A26: G9 | B26: Chandramouli | K26: =SUM(C26,E26,G26,I26) -> 0
A27: G10 | B27: Cijo Jacob / Thara Joy | C27: 4965 | D27: 45760 | K27: =SUM(C27,E27,G27,I27) -> 4965
A28: G11 | B28: Ketan Verlekar | K28: =SUM(C28,E28,G28,I28) -> 0
A29: G12 | B29: Shyam Nair | C29: 4112 | D29: 45749 | E29: 4868 | F29: 45762 | K29: =SUM(C29,E29,G29,I29) -> 8980
A30: G13 | B30: Ajai.B | K30: =SUM(C30,E30,G30,I30) -> 0
A31: G14 | B31: Surajit Borah | C31: 5081 | D31: 45762 | K31: =SUM(C31,E31,G31,I31) -> 5081
A32: G15 | B32: Suresh Nallusamy / Antriksh (tenant) | C32: 4403 | D32: 45749 | E32: 4935 | F32: 45765 | K32: =SUM(C32,E32,G32,I32) -> 9338
A33: G16 | B33: Praveen Ganesan | C33: 9047 | D33: 45767 | K33: =SUM(C33,E33,G33,I33) -> 9047
A34: S1 | B34: S.N.Behera | C34: 4592 | D34: 45766 | K34: =SUM(C34,E34,G34,I34) -> 4592
A35: S2 | B35: Sonal Singh | K35: =SUM(C35,E35,G35,I35) -> 0
A36: S3 | B36: Koteswararao | C36: 5088 | D36: 45770 | K36: =SUM(C36,E36,G36,I36) -> 5088
A37: S4 | B37: Swaminathan | C37: 4768 | D37: 45762 | K37: =SUM(C37,E37,G37,I37) -> 4768
A38: S5 | B38: Abhishek Gopalakrishnan | K38: =SUM(C38,E38,G38,I38) -> 0
A39: S6 | B39: Vivek Dhingra / Pratyush Das | K39: =SUM(C39,E39,G39,I39) -> 0
A40: S7 | B40: Harish B | C40: 4677 | D40: 45771 | K40: =SUM(C40,E40,G40,I40) -> 4677
...

Sheet May2025-EXPENSE
A1: 1 | B1: MAY 2025 EXPENSES
A2: FLAT # | B2: 1 | C2: WATER USED IN LTRS | D2: COMMON AREA EQUALLY DEVIDED | E2: TOTAL FRESH WATER CONSUMED | F2: %OF TOTAL USED | G2: WATER EXPENSE SHARING BY % | H2: #METERS | I2: METER RENT | J2: VARIABLE EXPENSE = COMMON AREA METER RENT + WATER EXPENSE+ FLAT METER RENT | K2: FIXED EXPENSE SHARE | L2: PARKING FEE | M2: CLUB HOUSE BOOKING | N2: SHIFTING FEE | O2: GYM USAGE FEE | P2: POLYCARBONATE SHEET REPAIR | R2: TOTAL EXPENSE TO BE PAID
A3: CH | B3: MPFOWA | C3: 0 | D3: 0 | H3: 1 | I3: =T7 -> 117.81166
A4: GYM | B4: MPFOWA | C4: 0 | D4: 0 | H4: 1 | I4: =T7 -> 117.81166 | S4: TOTAL FIXED EXPENSE | T4: ='ANNUAL-EXPENSE-DETAILS'!BF4 -> 234938
A5: BSMT | B5: MPFOWA | C5: 0 | D5: 0 | H5: 1 | I5: =T7 -> 117.81166 | S5: TOTAL WATER EXPENSE | T5: ='ANNUAL-EXPENSE-DETAILS'!BE4 -> 38600
A6: F1 | B6: Shailesh Srivastava / Azeem Nawaz | C6: 3713 | D6: =SUM($C$3:$C$5)/64 -> 0 | E6: =C6+D6 -> 3713 | F6: =IF($C$70=0, 0, E6/$C$70) -> 0.0093496421 | G6: =F6*$T$5 -> 360.89619 | H6: 3 | I6: =$T$7*H6 -> 353.43498 | J6: =G6+$T$9+I6 -> 719.85358 | K6: =$T$4/64 -> 3670.9062 | L6: 0 | M6: 0 | N6: 0 | O6: 0 | R6: =(SUM(J6:P6)*$B$2) -> 4390.7598
A7: F2 | B7: Shanthanu | C7: 14642 | D7: =SUM($C$3:$C$5)/64 -> 0 | E7: =C7+D7 -> 14642 | F7: =IF($C$70=0, 0, E7/$C$70) -> 0.036869771 | G7: =F7*$T$5 -> 1423.1732 | H7: 4 | I7: =$T$7*H7 -> 471.24664 | J7: =G7+$T$9+I7 -> 1899.9422 | K7: =$T$4/64 -> 3670.9062 | L7: 0 | M7: 0 | N7: 0 | O7: 0 | R7: =(SUM(J7:P7)*$B$2) -> 5570.8485 | S7: RENT PER METER | T7: 117.81166
A8: F3 | B8: Samrat Kar | C8: 11039 | D8: =SUM($C$3:$C$5)/64 -> 0 | E8: =C8+D8 -> 11039 | F8: =IF($C$70=0, 0, E8/$C$70) -> 0.027797118 | G8: =F8*$T$5 -> 1072.9688 | H8: 4 | I8: =$T$7*H8 -> 471.24664 | J8: =G8+$T$9+I8 -> 1549.7378 | K8: =$T$4/64 -> 3670.9062 | L8: 750 | M8: 0 | N8: 0 | O8: 0 | R8: =(SUM(J8:P8)*$B$2) -> 5970.6441 | S8: COMMON AREA METER RENT | T8: =$T$7*3 -> 353.43498
A9: F4 | B9: Renu R | C9: 3180 | D9: =SUM($C$3:$C$5)/64 -> 0 | E9: =C9+D9 -> 3180 | F9: =IF($C$70=0, 0, E9/$C$70) -> 0.0080075039 | G9: =F9*$T$5 -> 309.08965 | H9: 4 | I9: =$T$7*H9 -> 471.24664 | J9: =G9+$T$9+I9 -> 785.85871 | K9: =$T$4/64 -> 3670.9062 | L9: 0 | M9: 0 | N9: 0 | O9: 0 | R9: =(SUM(J9:P9)*$B$2) -> 4456.765 | S9: COMMON AREA METER RENT/FLAT | T9: =T8/64 -> 5.5224215
A10: F5 | B10: Vamsidhar Bethanabatla / Madhuri Anumula | C10: 94.5 | D10: =SUM($C$3:$C$5)/64 -> 0 | E10: =C10+D10 -> 94.5 | F10: =IF($C$70=0, 0, E10/$C$70) -> 0.00023795884 | G10: =F10*$T$5 -> 9.1852113 | H10: 3 | I10: =$T$7*H10 -> 353.43498 | J10: =G10+$T$9+I10 -> 368.14261 | K10: =$T$4/64 -> 3670.9062 | L10: 0 | M10: 0 | N10: 0 | O10: 0 | R10: =(SUM(J10:P10)*$B$2) -> 4039.0489
A11: F6 | B11: Meghana Viral Shah and Vviral Shah (Owner) / Sangeet and Swagat (Tenent) | C11: 3278 | D11: =SUM($C$3:$C$5)/64 -> 0 | E11: =C11+D11 -> 3278 | F11: =IF($C$70=0, 0, E11/$C$70) -> 0.008254276 | G11: =F11*$T$5 -> 318.61505 | H11: 3 | I11: =$T$7*H11 -> 353.43498 | J11: =G11+$T$9+I11 -> 677.57245 | K11: =$T$4/64 -> 3670.9062 | L11: 0 | M11: 0 | N11: 0 | O11: 0 | R11: =(SUM(J11:P11)*$B$2) -> 4348.4787
A12: F7 | B12: Vimal NK | C12: 384.5 | D12: =SUM($C$3:$C$5)/64 -> 0 | E12: =C12+D12 -> 384.5 | F12: =IF($C$70=0, 0, E12/$C$70) -> 0.00096820291 | G12: =F12*$T$5 -> 37.372632 | H12: 3 | I12: =$T$7*H12 -> 353.43498 | J12: =G12+$T$9+I12 -> 396.33003 | K12: =$T$4/64 -> 3670.9062 | L12: 750 | M12: 0 | N12: 0 | O12: 0 | R12: =(SUM(J12:P12)*$B$2) -> 4817.2363 | S12: BALANCE IN ACCOUNT TILL 31MAY2023
A13: F8 | B13: Sujeet Kumar (Tenant)/Sreejith Menon (Owner) | C13: 323 | D13: =SUM($C$3:$C$5)/64 -> 0 | E13: =C13+D13 -> 323 | F13: =IF($C$70=0, 0, E13/$C$70) -> 0.0008133408 | G13: =F13*$T$5 -> 31.394955 | H13: 3 | I13: =$T$7*H13 -> 353.43498 | J13: =G13+$T$9+I13 -> 390.35235 | K13: =$T$4/64 -> 3670.9062 | L13: 0 | M13: 0 | N13: 0 | O13: 0 | R13: =(SUM(J13:P13)*$B$2) -> 4061.2586 | S13: TOTAL NON MAINTENANCE CORPUS COLLECTION
A14: F9 | B14: Vijay Suswaram (Owner) / Divya Shikha (Tenant) | C14: 1898.5 | D14: =SUM($C$3:$C$5)/64 -> 0 | E14: =C14+D14 -> 1898.5 | F14: =IF($C$70=0, 0, E14/$C$70) -> 0.0047805805 | G14: =F14*$T$5 -> 184.53041 | H14: 4 | I14: =$T$7*H14 -> 471.24664 | J14: =G14+$T$9+I14 -> 661.29947 | K14: =$T$4/64 -> 3670.9062 | L14: 0 | M14: 0 | N14: 0 | O14: 0 | R14: =(SUM(J14:P14)*$B$2) -> 4332.2057 | S14: TOTAL FD DONE
A15: F10 | B15: Aby Thomas | C15: 2399.5 | D15: =SUM($C$3:$C$5)/64 -> 0 | E15: =C15+D15 -> 2399.5 | F15: =IF($C$70=0, 0, E15/$C$70) -> 0.0060421401 | G15: =F15*$T$5 -> 233.22661 | H15: 3 | I15: =$T$7*H15 -> 353.43498 | J15: =G15+$T$9+I15 -> 592.18401 | K15: =$T$4/64 -> 3670.9062 | L15: 0 | M15: 0 | N15: 0 | O15: 0 | R15: =(SUM(J15:P15)*$B$2) -> 4263.0903 | S15: Pending vendor payments
A16: F11 | B16: Niwin Anto | C16: 2663.5 | D16: =SUM($C$3:$C$5)/64 -> 0 | E16: =C16+D16 -> 2663.5 | F16: =IF($C$70=0, 0, E16/$C$70) -> 0.006706914 | G16: =F16*$T$5 -> 258.88688 | H16: 3 | I16: =$T$7*H16 -> 353.43498 | J16: =G16+$T$9+I16 -> 617.84428 | K16: =$T$4/64 -> 3670.9062 | L16: 0 | M16: 0 | N16: 0 | O16: 0 | R16: =(SUM(J16:P16)*$B$2) -> 4288.7505 | S16: AMOUNT AVAILABLE FOR NON MAINTENANCE CORPUS | T16: =T13-T14 -> 0
A17: F12 | B17: Anirudh Singh | C17: 6.5 | D17: =SUM($C$3:$C$5)/64 -> 0 | E17: =C17+D17 -> 6.5 | F17: =IF($C$70=0, 0, E17/$C$70) -> 1.6367539e-05 | G17: =F17*$T$5 -> 0.63178702 | H17: 3 | I17: =$T$7*H17 -> 353.43498 | J17: =G17+$T$9+I17 -> 359.58919 | K17: =$T$4/64 -> 3670.9062 | L17: 0 | M17: 0 | N17: 0 | O17: 0 | R17: =(SUM(J17:P17)*$B$2) -> 4030.4954 | S17: AMOUNT AVAILABLE FOR MAINTENANCE | T17: =T12-T15-T16 -> 0
A18: F13 | B18: Sanchay Saxena | C18: 11835 | D18: =SUM($C$3:$C$5)/64 -> 0 | E18: =C18+D18 -> 11835 | F18: =IF($C$70=0, 0, E18/$C$70) -> 0.029801512 | G18: =F18*$T$5 -> 1150.3384 | H18: 4 | I18: =$T$7*H18 -> 471.24664 | J18: =G18+$T$9+I18 -> 1627.1074 | K18: =$T$4/64 -> 3670.9062 | L18: 0 | M18: 0 | N18: 1000 | O18: 0 | R18: =(SUM(J18:P18)*$B$2) -> 6298.0137 | S18: Maintenance Deficit | T18: =T17-(T4+T5+23830) -> -297368
A19: F14 | B19: Hemant Patel | C19: 169 | D19: =SUM($C$3:$C$5)/64 -> 0 | E19: =C19+D19 -> 169 | F19: =IF($C$70=0, 0, E19/$C$70) -> 0.00042555602 | G19: =F19*$T$5 -> 16.426463 | H19: 4 | I19: =$T$7*H19 -> 471.24664 | J19: =G19+$T$9+I19 -> 493.19552 | K19: =$T$4/64 -> 3670.9062 | L19: 750 | M19: 0 | N19: 0 | O19: 0 | R19: =(SUM(J19:P19)*$B$2) -> 4914.1018
A20: F15 | B20: Senthil.Vijayaragavan | C20: 6077 | D20: =SUM($C$3:$C$5)/64 -> 0 | E20: =C20+D20 -> 6077 | F20: =IF($C$70=0, 0, E20/$C$70) -> 0.01530239 | G20: =F20*$T$5 -> 590.67227 | H20: 4 | I20: =$T$7*H20 -> 471.24664 | J20: =G20+$T$9+I20 -> 1067.4413 | K20: =$T$4/64 -> 3670.9062 | L20: 750 | M20: 0 | N20: 0 | O20: 0 | R20: =(SUM(J20:P20)*$B$2) -> 5488.3476
A21: F16 | B21: Sreeja Sudharma | C21: 14053.5 | D21: =SUM($C$3:$C$5)/64 -> 0 | E21: =C21+D21 -> 14053.5 | F21: =IF($C$70=0, 0, E21/$C$70) -> 0.035387879 | G21: =F21*$T$5 -> 1365.9721 | H21: 3 | I21: =$T$7*H21 -> 353.43498 | J21: =G21+$T$9+I21 -> 1724.9295 | K21: =$T$4/64 -> 3670.9062 | L21: 0 | M21: 0 | N21: 0 | O21: 0 | R21: =(SUM(J21:P21)*$B$2) -> 5395.8358
A22: G1 | B22: Venkataramanan C | C22: 10047 | D22: =SUM($C$3:$C$5)/64 -> 0 | E22: =C22+D22 -> 10047 | F22: =IF($C$70=0, 0, E22/$C$70) -> 0.02529918 | G22: =F22*$T$5 -> 976.54834 | H22: 3 | I22: =$T$7*H22 -> 353.43498 | J22: =G22+$T$9+I22 -> 1335.5057 | K22: =$T$4/64 -> 3670.9062 | L22: 0 | M22: 0 | N22: 0 | O22: 0 | R22: =(SUM(J22:P22)*$B$2) -> 5006.412
A23: G2 | B23: Kaushik Kasibhatla | C23: 10642 | D23: =SUM($C$3:$C$5)/64 -> 0 | E23: =C23+D23 -> 10642 | F23: =IF($C$70=0, 0, E23/$C$70) -> 0.026797439 | G23: =F23*$T$5 -> 1034.3811 | H23: 4 | I23: =$T$7*H23 -> 471.24664 | J23: =G23+$T$9+I23 -> 1511.1502 | K23: =$T$4/64 -> 3670.9062 | L23: 0 | M23: 0 | N23: 0 | O23: 0 | R23: =(SUM(J23:P23)*$B$2) -> 5182.0565
A24: G3 | B24: Balakrishnan | C24: 10536.5 | D24: =SUM($C$3:$C$5)/64 -> 0 | E24: =C24+D24 -> 10536.5 | F24: =IF($C$70=0, 0, E24/$C$70) -> 0.026531781 | G24: =F24*$T$5 -> 1024.1268 | H24: 4 | I24: =$T$7*H24 -> 471.24664 | J24: =G24+$T$9+I24 -> 1500.8958 | K24: =$T$4/64 -> 3670.9062 | L24: 0 | M24: 0 | N24: 0 | O24: 0 | R24: =(SUM(J24:P24)*$B$2) -> 5171.8021
A25: G4 | B25: Ashwin Pandith | C25: 10096 | D25: =SUM($C$3:$C$5)/64 -> 0 | E25: =C25+D25 -> 10096 | F25: =IF($C$70=0, 0, E25/$C$70) -> 0.025422566 | G25: =F25*$T$5 -> 981.31104 | H25: 4 | I25: =$T$7*H25 -> 471.24664 | J25: =G25+$T$9+I25 -> 1458.0801 | K25: =$T$4/64 -> 3670.9062 | L25: 0 | M25: 0 | N25: 0 | O25: 0 | R25: =(SUM(J25:P25)*$B$2) -> 5128.9863
A26: G5 | B26: Mayank Phophaliya | C26: 3222 | D26: =SUM($C$3:$C$5)/64 -> 0 | E26: =C26+D26 -> 3222 | F26: =IF($C$70=0, 0, E26/$C$70) -> 0.0081132634 | G26: =F26*$T$5 -> 313.17197 | H26: 3 | I26: =$T$7*H26 -> 353.43498 | J26: =G26+$T$9+I26 -> 672.12936 | K26: =$T$4/64 -> 3670.9062 | L26: 0 | M26: 0 | N26: 0 | O26: 0 | R26: =(SUM(J26:P26)*$B$2) -> 4343.0356
A27: G6 | B27: Mohit Daga | C27: 4532.5 | D27: =SUM($C$3:$C$5)/64 -> 0 | E27: =C27+D27 -> 4532.5 | F27: =IF($C$70=0, 0, E27/$C$70) -> 0.011413211 | G27: =F27*$T$5 -> 440.54995 | H27: 3 | I27: =$T$7*H27 -> 353.43498 | J27: =G27+$T$9+I27 -> 799.50735 | K27: =$T$4/64 -> 3670.9062 | L27: 0 | M27: 0 | N27: 0 | O27: 0 | R27: =(SUM(J27:P27)*$B$2) -> 4470.4136
A28: G7 | B28: Prince Richfield | C28: 720 | D28: =SUM($C$3:$C$5)/64 -> 0 | E28: =C28+D28 -> 720 | F28: =IF($C$70=0, 0, E28/$C$70) -> 0.0018130197 | G28: =F28*$T$5 -> 69.982562 | H28: 3 | I28: =$T$7*H28 -> 353.43498 | J28: =G28+$T$9+I28 -> 428.93996 | K28: =$T$4/64 -> 3670.9062 | L28: 0 | M28: 0 | N28: 0 | O28: 0 | R28: =(SUM(J28:P28)*$B$2) -> 4099.8462
A29: G8 | B29: Ranjithkumar R / Sameer (tenant) / Princy (tenant) | C29: 7814.5 | D29: =SUM($C$3:$C$5)/64 -> 0 | E29: =C29+D29 -> 7814.5 | F29: =IF($C$70=0, 0, E29/$C$70) -> 0.019677559 | G29: =F29*$T$5 -> 759.5538 | H29: 3 | I29: =$T$7*H29 -> 353.43498 | J29: =G29+$T$9+I29 -> 1118.5112 | K29: =$T$4/64 -> 3670.9062 | L29: 0 | M29: 0 | N29: 0 | O29: 0 | R29: =(SUM(J29:P29)*$B$2) -> 4789.4174
A30: G9 | B30: Chandramouli | C30: 4775 | D30: =SUM($C$3:$C$5)/64 -> 0 | E30: =C30+D30 -> 4775 | F30: =IF($C$70=0, 0, E30/$C$70) -> 0.012023846 | G30: =F30*$T$5 -> 464.12047 | H30: 5 | I30: =$T$7*H30 -> 589.0583 | J30: =G30+$T$9+I30 -> 1058.7012 | K30: =$T$4/64 -> 3670.9062 | L30: 0 | M30: 0 | N30: 0 | O30: 0 | R30: =(SUM(J30:P30)*$B$2) -> 4729.6074
... A69: T16 | B69: Madhusoodanan P.R. | C69: 1094 | D69: =SUM($C$3:$C$5)/64 -> 0 | E69: =C69+D69 -> 1094 | F69: =IF($C$70=0, 0, E69/$C$70) -> 0.0027547828 | G69: =F69*$T$5 -> 106.33462 | H69: 3 | I69: =$T$7*H69 -> 353.43498 | J69: =G69+$T$9+I69 -> 465.29201 | K69: =$T$4/64 -> 3670.9062 | L69: 0 | M69: 0 | N69: 0 | O69: 0 | R69: =(SUM(J69:P69)*$B$2) -> 4136.1983
A70: TOTAL | B70: TOTAL | C70: =SUM(C3:C69) -> 397127.5 | D70: =SUM(D3:D69) -> 0 | E70: =SUM(E5:E69) -> 397127.5 | F70: =SUM(F6:F69) -> 1 | G70: =SUM(G6:G69) -> 38600 | H70: =SUM(H3:H69) -> 223 | I70: =SUM(I3:I69) -> 26272 | J70: =SUM(J6:J69) -> 64872 | K70: =SUM(K6:K69) -> 234938 | L70: =SUM(L3:L69) -> 3750 | M70: =SUM(M3:M69) -> 0 | N70: =SUM(N3:N69) -> 5000 | O70: =SUM(O3:O69) -> 0 | P70: =SUM(P3:P69) -> 0 | R70: =SUM(R3:R69) -> 308560

Sheet May2025-COLLECTION
A1: FLAT # | C1: Amount | D1: Date | E1: Amount | F1: Date | G1: Amount | H1: Date | I1: Amount | J1: Date | K1: Total
A2: F1 | B2: Shailesh Srivastava / Azeem Nawaz | C2: 5513 | D2: 45800 | K2: =SUM(C2,E2,G2,I2) -> 5513
A3: F2 | B3: Shanthanu | C3: 9182 | D3: 45798 | K3: =SUM(C3,E3,G3,I3) -> 9182
A4: F3 | B4: Samrat Kar | C4: 6000 | D4: 45778 | K4: =SUM(C4,E4,G4,I4) -> 6000
A5: F4 | B5: Renu R | C5: 5710 | D5: 45792 | K5: =SUM(C5,E5,G5,I5) -> 5710
A6: F5 | B6: Vamsidhar Bethanabatla / Madhuri Anumula | C6: 5354 | D6: 45792 | K6: =SUM(C6,E6,G6,I6) -> 5354
A7: F6 | B7: Meghana Viral Shah and Vviral Shah (Owner) / Sangeet and Swagat (Tenent) | C7: 5864 | D7: 45807 | K7: =SUM(C7,E7,G7,I7) -> 5864
A8: F7 | B8: Vimal NK | C8: 5466 | D8: 45781 | E8: 6136 | F8: 45798 | K8: =SUM(C8,E8,G8,I8) -> 11602
A9: F8 | B9: Sujeet Kumar (Tenant)/Sreejith Menon (Owner) | C9: 5312 | D9: 45792 | K9: =SUM(C9,E9,G9,I9) -> 5312
A10: F9 | B10: Vijay Suswaram (Owner) / Divya Shikha (Tenant) | C10: 5516 | D10: 45796 | K10: =SUM(C10,E10,G10,I10) -> 5516
A11: F10 | B11: Aby Thomas | C11: 5600 | D11: 45806 | K11: =SUM(C11,E11,G11,I11) -> 5600
A12: F11 | B12: Niwin Anto | C12: 5340 | D12: 45794 | K12: =SUM(C12,E12,G12,I12) -> 5340
A13: F12 | B13: Anirudh Singh | C13: 5286 | D13: 45796 | K13: =SUM(C13,E13,G13,I13) -> 5286
A14: F13 | B14: Sanchay Saxena | C14: 5426 | D14: 45806 | K14: =SUM(C14,E14,G14,I14) -> 5426
A15: F14 | B15: Hemant Patel | C15: 6148 | D15: 45793 | K15: =SUM(C15,E15,G15,I15) -> 6148
A16: F15 | B16: Senthil.Vijayaragavan | C16: 6465 | D16: 45797 | K16: =SUM(C16,E16,G16,I16) -> 6465
A17: F16 | B17: Sreeja Sudharma | K17: =SUM(C17,E17,G17,I17) -> 0
A18: G1 | B18: Venkataramanan C | K18: =SUM(C18,E18,G18,I18) -> 0
A19: G2 | B19: Kaushik Kasibhatla | K19: =SUM(C19,E19,G19,I19) -> 0
A20: G3 | B20: Balakrishnan | C20: 6545 | D20: 45796 | K20: =SUM(C20,E20,G20,I20) -> 6545
A21: G4 | B21: Ashwin Pandith | C21: 6908 | D21: 45793 | K21: =SUM(C21,E21,G21,I21) -> 6908
A22: G5 | B22: Mayank Phophaliya | C22: 6000 | D22: 45797 | K22: =SUM(C22,E22,G22,I22) -> 6000
A23: G6 | B23: Mohit Daga | K23: =SUM(C23,E23,G23,I23) -> 0
A24: G7 | B24: Prince Richfield | C24: 5752 | D24: 45798 | K24: =SUM(C24,E24,G24,I24) -> 5752
A25: G8 | B25: Ranjithkumar R / Sameer (tenant) / Princy (tenant) | C25: 6328 | D25: 45806 | K25: =SUM(C25,E25,G25,I25) -> 6328
A26: G9 | B26: Chandramouli | C26: 5203 | D26: 45781 | K26: =SUM(C26,E26,G26,I26) -> 5203
A27: G10 | B27: Cijo Jacob / Thara Joy | C27: 6240 | D27: 45799 | K27: =SUM(C27,E27,G27,I27) -> 6240
A28: G11 | B28: Ketan Verlekar | C28: 4689 | D28: 45780 | E28: 5599 | F28: 45792 | K28: =SUM(C28,E28,G28,I28) -> 10288
A29: G12 | B29: Shyam Nair | C29: 5803 | D29: 45806 | K29: =SUM(C29,E29,G29,I29) -> 5803
A30: G13 | B30: Ajai.B | C30: 6379 | D30: 45807 | K30: =SUM(C30,E30,G30,I30) -> 6379
A31: G14 | B31: Surajit Borah | C31: 5734 | D31: 45806 | K31: =SUM(C31,E31,G31,I31) -> 5734
A32: G15 | B32: Suresh Nallusamy / Antriksh (tenant) | K32: =SUM(C32,E32,G32,I32) -> 0
A33: G16 | B33: Praveen Ganesan | K33: =SUM(C33,E33,G33,I33) -> 0
A34: S1 | B34: S.N.Behera | C34: 5286 | D34: 45796 | K34: =SUM(C34,E34,G34,I34) -> 5286
A35: S2 | B35: Sonal Singh | C35: 12856 | D35: 45780 | E35: 8243 | F35: 45806 | K35: =SUM(C35,E35,G35,I35) -> 21099
A36: S3 | B36: Koteswararao | C36: 5553 | D36: 45798 | K36: =SUM(C36,E36,G36,I36) -> 5553
A37: S4 | B37: Swaminathan | C37: 6853 | D37: 45792 | K37: =SUM(C37,E37,G37,I37) -> 6853
A38: S5 | B38: Abhishek Gopalakrishnan | C38: 6314 | D38: 45797 | K38: =SUM(C38,E38,G38,I38) -> 6314
A39: S6 | B39: Vivek Dhingra / Pratyush Das | C39: 5320 | D39: 45795 | K39: =SUM(C39,E39,G39,I39) -> 5320
A40: S7 | B40: Harish B | C40: 5402 | D40: 45804 | K40: =SUM(C40,E40,G40,I40) -> 5402
...

Sheet June2025-EXPENSE
B1: JUN 2025 EXPENSES
A2: FLAT # | B2: 1 | C2: WATER USED IN LTRS (L) | D2: COMMON AREA EQUALLY DEVIDED | E2: TOTAL FRESH WATER CONSUMED | F2: %OF TOTAL USED | G2: WATER EXPENSE SHARING BY % | H2: #METERS | I2: METER RENT | J2: VARIABLE EXPENSE = COMMON AREA METER RENT + WATER EXPENSE+ FLAT METER RENT | K2: FIXED EXPENSE SHARE | L2: PARKING FEE | M2: CLUB BOOKING FEE | N2: POLYCARBONATE PROJECT CANCELLATION CREDIT AMOUNT | O2: SHIFTING FEE | P2: GYM USAGE FEE | R2: TOTAL EXPENSE TO BE PAID
A3: CH | B3: MPFOWA | C3: 0 | D3: 0 | H3: 1 | I3: =H3*$T$7 -> 117.81166
A4: GYM | B4: MPFOWA | C4: 0 | D4: 0 | H4: 1 | I4: =H4*$T$7 -> 117.81166 | S4: TOTAL FIXED EXPENSE | T4: ='ANNUAL-EXPENSE-DETAILS'!BF5 -> 250490
A5: BSMT | B5: MPFOWA | C5: 0 | D5: 0 | H5: 1 | I5: =H5*$T$7 -> 117.81166 | S5: TOTAL WATER EXPENSE | T5: ='ANNUAL-EXPENSE-DETAILS'!BE5 -> 36000
A6: F1 | B6: Shailesh Srivastava / Azeem Nawaz | C6: 3271 | D6: =SUM($C$3:$C$5)/64 -> 0 | E6: =C6+D6 -> 3271 | F6: =IF($C$70=0, 0, E6/$C$70) -> 0.0075966859 | G6: =F6*$T$5 -> 273.48069 | H6: 3 | I6: =$T$7*H6 -> 353.43498 | J6: =G6+$T$9+I6 -> 632.43809 | K6: =$T$11/64 -> 3913.9062 | L6: 0 | M6: 0 | O6: 0 | P6: 0 | R6: =(SUM(J6:P6))*$B$2 -> 4546.3443
A7: F2 | B7: Shanthanu | C7: 14633 | D7: =SUM($C$3:$C$5)/64 -> 0 | E7: =C7+D7 -> 14633 | F7: =IF($C$70=0, 0, E7/$C$70) -> 0.033984196 | G7: =F7*$T$5 -> 1223.431 | H7: 4 | I7: =$T$7*H7 -> 471.24664 | J7: =G7+$T$9+I7 -> 1700.2001 | K7: =$T$11/64 -> 3913.9062 | L7: 0 | M7: 0 | O7: 0 | P7: 0 | R7: =(SUM(J7:P7))*$B$2 -> 5614.1064 | S7: RENT PER METER | T7: 117.81166
A8: F3 | B8: Samrat Kar | C8: 11395 | D8: =SUM($C$3:$C$5)/64 -> 0 | E8: =C8+D8 -> 11395 | F8: =IF($C$70=0, 0, E8/$C$70) -> 0.02646415 | G8: =F8*$T$5 -> 952.70941 | H8: 4 | I8: =$T$7*H8 -> 471.24664 | J8: =G8+$T$9+I8 -> 1429.4785 | K8: =$T$11/64 -> 3913.9062 | L8: 750 | M8: 0 | O8: 0 | P8: 0 | R8: =(SUM(J8:P8))*$B$2 -> 6093.3847 | S8: COMMON AREA METER RENT | T8: =$T$7*3 -> 353.43498
A9: F4 | B9: Renu R | C9: 3264.5 | D9: =SUM($C$3:$C$5)/64 -> 0 | E9: =C9+D9 -> 3264.5 | F9: =IF($C$70=0, 0, E9/$C$70) -> 0.0075815901 | G9: =F9*$T$5 -> 272.93724 | H9: 4 | I9: =$T$7*H9 -> 471.24664 | J9: =G9+$T$9+I9 -> 749.7063 | K9: =$T$11/64 -> 3913.9062 | L9: 0 | M9: 0 | O9: 0 | P9: 0 | R9: =(SUM(J9:P9))*$B$2 -> 4663.6125 | S9: COMMON AREA METER RENT/FLAT | T9: =T8/64 -> 5.5224215
A10: F5 | B10: Vamsidhar Bethanabatla / Madhuri Anumula | C10: 0 | D10: =SUM($C$3:$C$5)/64 -> 0 | E10: =C10+D10 -> 0 | F10: =IF($C$70=0, 0, E10/$C$70) -> 0 | G10: =F10*$T$5 -> 0 | H10: 3 | I10: =$T$7*H10 -> 353.43498 | J10: =G10+$T$9+I10 -> 358.9574 | K10: =$T$11/64 -> 3913.9062 | L10: 0 | M10: 0 | O10: 0 | P10: 0 | R10: =(SUM(J10:P10))*$B$2 -> 4272.8636
A11: F6 | B11: Meghana Viral Shah and Vviral Shah (Owner) / Sangeet and Swagat (Tenent) | C11: 4251 | D11: =SUM($C$3:$C$5)/64 -> 0 | E11: =C11+D11 -> 4251 | F11: =IF($C$70=0, 0, E11/$C$70) -> 0.0098726725 | G11: =F11*$T$5 -> 355.41621 | H11: 3 | I11: =$T$7*H11 -> 353.43498 | J11: =G11+$T$9+I11 -> 714.37361 | K11: =$T$11/64 -> 3913.9062 | L11: 0 | M11: 0 | O11: 0 | P11: 0 | R11: =(SUM(J11:P11))*$B$2 -> 4628.2799 | S11: TOTAL FIXED EXPENSE | T11: ='ANNUAL-EXPENSE-DETAILS'!BF5 -> 250490
A12: F7 | B12: Vimal NK | C12: 335.5 | D12: =SUM($C$3:$C$5)/64 -> 0 | E12: =C12+D12 -> 335.5 | F12: =IF($C$70=0, 0, E12/$C$70) -> 0.00077917705 | G12: =F12*$T$5 -> 28.050374 | H12: 3 | I12: =$T$7*H12 -> 353.43498 | J12: =G12+$T$9+I12 -> 387.00777 | K12: =$T$11/64 -> 3913.9062 | L12: 750 | M12: 0 | O12: 0 | P12: 0 | R12: =(SUM(J12:P12))*$B$2 -> 5050.914
A13: F8 | B13: Sujeet Kumar (Tenant)/Sreejith Menon (Owner) | C13: 220.5 | D13: =SUM($C$3:$C$5)/64 -> 0 | E13: =C13+D13 -> 220.5 | F13: =IF($C$70=0, 0, E13/$C$70) -> 0.00051209698 | G13: =F13*$T$5 -> 18.435491 | H13: 3 | I13: =$T$7*H13 -> 353.43498 | J13: =G13+$T$9+I13 -> 377.39289 | K13: =$T$11/64 -> 3913.9062 | L13: 0 | M13: 0 | O13: 0 | P13: 0 | R13: =(SUM(J13:P13))*$B$2 -> 4291.2991
A14: F9 | B14: Vijay Suswaram (Owner) / Divya Shikha (Tenant) | C14: 2107 | D14: =SUM($C$3:$C$5)/64 -> 0 | E14: =C14+D14 -> 2107 | F14: =IF($C$70=0, 0, E14/$C$70) -> 0.0048933712 | G14: =F14*$T$5 -> 176.16136 | H14: 4 | I14: =$T$7*H14 -> 471.24664 | J14: =G14+$T$9+I14 -> 652.93042 | K14: =$T$11/64 -> 3913.9062 | L14: 0 | M14: 0 | O14: 0 | P14: 0 | R14: =(SUM(J14:P14))*$B$2 -> 4566.8367 | S14: BALANCE IN ACCOUNT ON 30-JUN-2023
A15: F10 | B15: Aby Thomas | C15: 3152.5 | D15: =SUM($C$3:$C$5)/64 -> 0 | E15: =C15+D15 -> 3152.5 | F15: =IF($C$70=0, 0, E15/$C$70) -> 0.0073214773 | G15: =F15*$T$5 -> 263.57318 | H15: 3 | I15: =$T$7*H15 -> 353.43498 | J15: =G15+$T$9+I15 -> 622.53058 | K15: =$T$11/64 -> 3913.9062 | L15: 0 | M15: 0 | O15: 0 | P15: 0 | R15: =(SUM(J15:P15))*$B$2 -> 4536.4368 | S15: TOTAL NON MAINTENANCE CORPUS COLLECTION
A16: F11 | B16: Niwin Anto | C16: 3724.5 | D16: =SUM($C$3:$C$5)/64 -> 0 | E16: =C16+D16 -> 3724.5 | F16: =IF($C$70=0, 0, E16/$C$70) -> 0.0086499103 | G16: =F16*$T$5 -> 311.39677 | H16: 3 | I16: =$T$7*H16 -> 353.43498 | J16: =G16+$T$9+I16 -> 670.35417 | K16: =$T$11/64 -> 3913.9062 | L16: 0 | M16: 0 | O16: 0 | P16: 0 | R16: =(SUM(J16:P16))*$B$2 -> 4584.2604 | S16: TOTAL FD DONE
A17: F12 | B17: Anirudh Singh | C17: 0 | D17: =SUM($C$3:$C$5)/64 -> 0 | E17: =C17+D17 -> 0 | F17: =IF($C$70=0, 0, E17/$C$70) -> 0 | G17: =F17*$T$5 -> 0 | H17: 3 | I17: =$T$7*H17 -> 353.43498 | J17: =G17+$T$9+I17 -> 358.9574 | K17: =$T$11/64 -> 3913.9062 | L17: 0 | M17: 0 | O17: 0 | P17: 0 | R17: =(SUM(J17:P17))*$B$2 -> 4272.8636 | S17: AMOUNT AVAILABLE FOR NON MAINTENANCE CORPUS | T17: =T15-T16 -> 0
A18: F13 | B18: Sanchay Saxena | C18: 14443 | D18: =SUM($C$3:$C$5)/64 -> 0 | E18: =C18+D18 -> 14443 | F18: =IF($C$70=0, 0, E18/$C$70) -> 0.033542933 | G18: =F18*$T$5 -> 1207.5456 | H18: 4 | I18: =$T$7*H18 -> 471.24664 | J18: =G18+$T$9+I18 -> 1684.3146 | K18: =$T$11/64 -> 3913.9062 | L18: 0 | M18: 0 | O18: 0 | P18: 0 | R18: =(SUM(J18:P18))*$B$2 -> 5598.2209 | S18: AMOUNT AVAILABLE FOR MAINTENANCE | T18: =T14-T17 -> 0
A19: F14 | B19: Hemant Patel | C19: 2996.5 | D19: =SUM($C$3:$C$5)/64 -> 0 | E19: =C19+D19 -> 2996.5 | F19: =IF($C$70=0, 0, E19/$C$70) -> 0.0069591774 | G19: =F19*$T$5 -> 250.53039 | H19: 4 | I19: =$T$7*H19 -> 471.24664 | J19: =G19+$T$9+I19 -> 727.29944 | K19: =$T$11/64 -> 3913.9062 | L19: 750 | M19: 0 | O19: 0 | P19: 0 | R19: =(SUM(J19:P19))*$B$2 -> 5391.2057
A20: F15 | B20: Senthil.Vijayaragavan | C20: 6829.5 | D20: =SUM($C$3:$C$5)/64 -> 0 | E20: =C20+D20 -> 6829.5 | F20: =IF($C$70=0, 0, E20/$C$70) -> 0.015861072 | G20: =F20*$T$5 -> 570.99859 | H20: 4 | I20: =$T$7*H20 -> 471.24664 | J20: =G20+$T$9+I20 -> 1047.7676 | K20: =$T$11/64 -> 3913.9062 | L20: 750 | M20: 0 | O20: 0 | P20: 0 | R20: =(SUM(J20:P20))*$B$2 -> 5711.6739
A21: F16 | B21: Sreeja Sudharma | C21: 14374.5 | D21: =SUM($C$3:$C$5)/64 -> 0 | E21: =C21+D21 -> 14374.5 | F21: =IF($C$70=0, 0, E21/$C$70) -> 0.033383846 | G21: =F21*$T$5 -> 1201.8185 | H21: 3 | I21: =$T$7*H21 -> 353.43498 | J21: =G21+$T$9+I21 -> 1560.7759 | K21: =$T$11/64 -> 3913.9062 | L21: 0 | M21: 0 | O21: 0 | P21: 0 | R21: =(SUM(J21:P21))*$B$2 -> 5474.6821
A22: G1 | B22: Venkataramanan C | C22: 10757.5 | D22: =SUM($C$3:$C$5)/64 -> 0 | E22: =C22+D22 -> 10757.5 | F22: =IF($C$70=0, 0, E22/$C$70) -> 0.024983598 | G22: =F22*$T$5 -> 899.40952 | H22: 3 | I22: =$T$7*H22 -> 353.43498 | J22: =G22+$T$9+I22 -> 1258.3669 | K22: =$T$11/64 -> 3913.9062 | L22: 0 | M22: 0 | O22: 0 | P22: 0 | R22: =(SUM(J22:P22))*$B$2 -> 5172.2732
A23: G2 | B23: Kaushik Kasibhatla | C23: 20300.5 | D23: =SUM($C$3:$C$5)/64 -> 0 | E23: =C23+D23 -> 20300.5 | F23: =IF($C$70=0, 0, E23/$C$70) -> 0.047146598 | G23: =F23*$T$5 -> 1697.2775 | H23: 4 | I23: =$T$7*H23 -> 471.24664 | J23: =G23+$T$9+I23 -> 2174.0466 | K23: =$T$11/64 -> 3913.9062 | L23: 0 | M23: 0 | O23: 0 | P23: 0 | R23: =(SUM(J23:P23))*$B$2 -> 6087.9528
A24: G3 | B24: Balakrishnan | C24: 8713.5 | D24: =SUM($C$3:$C$5)/64 -> 0 | E24: =C24+D24 -> 8713.5 | F24: =IF($C$70=0, 0, E24/$C$70) -> 0.02023654 | G24: =F24*$T$5 -> 728.51544 | H24: 4 | I24: =$T$7*H24 -> 471.24664 | J24: =G24+$T$9+I24 -> 1205.2845 | K24: =$T$11/64 -> 3913.9062 | L24: 0 | M24: 0 | O24: 0 | P24: 0 | R24: =(SUM(J24:P24))*$B$2 -> 5119.1907
A25: G4 | B25: Ashwin Pandith | C25: 8961.5 | D25: =SUM($C$3:$C$5)/64 -> 0 | E25: =C25+D25 -> 8961.5 | F25: =IF($C$70=0, 0, E25/$C$70) -> 0.020812504 | G25: =F25*$T$5 -> 749.25014 | H25: 4 | I25: =$T$7*H25 -> 471.24664 | J25: =G25+$T$9+I25 -> 1226.0192 | K25: =$T$11/64 -> 3913.9062 | L25: 0 | M25: 0 | O25: 0 | P25: 0 | R25: =(SUM(J25:P25))*$B$2 -> 5139.9255
A26: G5 | B26: Mayank Phophaliya | C26: 3003 | D26: =SUM($C$3:$C$5)/64 -> 0 | E26: =C26+D26 -> 3003 | F26: =IF($C$70=0, 0, E26/$C$70) -> 0.0069742732 | G26: =F26*$T$5 -> 251.07384 | H26: 3 | I26: =$T$7*H26 -> 353.43498 | J26: =G26+$T$9+I26 -> 610.03123 | K26: =$T$11/64 -> 3913.9062 | L26: 0 | M26: 0 | O26: 0 | P26: 0 | R26: =(SUM(J26:P26))*$B$2 -> 4523.9375
A27: G6 | B27: Mohit Daga | C27: 10558.5 | D27: =SUM($C$3:$C$5)/64 -> 0 | E27: =C27+D27 -> 10558.5 | F27: =IF($C$70=0, 0, E27/$C$70) -> 0.024521433 | G27: =F27*$T$5 -> 882.77159 | H27: 3 | I27: =$T$7*H27 -> 353.43498 | J27: =G27+$T$9+I27 -> 1241.729 | K27: =$T$11/64 -> 3913.9062 | L27: 0 | M27: 0 | O27: 0 | P27: 0 | R27: =(SUM(J27:P27))*$B$2 -> 5155.6352
A28: G7 | B28: Prince Richfield | C28: 3958.5 | D28: =SUM($C$3:$C$5)/64 -> 0 | E28: =C28+D28 -> 3958.5 | F28: =IF($C$70=0, 0, E28/$C$70) -> 0.0091933602 | G28: =F28*$T$5 -> 330.96097 | H28: 3 | I28: =$T$7*H28 -> 353.43498 | J28: =G28+$T$9+I28 -> 689.91836 | K28: =$T$11/64 -> 3913.9062 | L28: 0 | M28: 0 | O28: 0 | P28: 0 | R28: =(SUM(J28:P28))*$B$2 -> 4603.8246
A29: G8 | B29: Ranjithkumar R / Sameer (tenant) / Princy (tenant) | C29: 5275.5 | D29: =SUM($C$3:$C$5)/64 -> 0 | E29: =C29+D29 -> 5275.5 | F29: =IF($C$70=0, 0, E29/$C$70) -> 0.012252007 | G29: =F29*$T$5 -> 441.07227 | H29: 3 | I29: =$T$7*H29 -> 353.43498 | J29: =G29+$T$9+I29 -> 800.02967 | K29: =$T$11/64 -> 3913.9062 | L29: 0 | M29: 0 | O29: 0 | P29: 0 | R29: =(SUM(J29:P29))*$B$2 -> 4713.9359
A30: G9 | B30: Chandramouli | C30: 8302 | D30: =SUM($C$3:$C$5)/64 -> 0 | E30: =C30+D30 -> 8302 | F30: =IF($C$70=0, 0, E30/$C$70) -> 0.019280858 | G30: =F30*$T$5 -> 694.11088 | H30: 5 | I30: =$T$7*H30 -> 589.0583 | J30: =G30+$T$9+I30 -> 1288.6916 | K30: =$T$11/64 -> 3913.9062 | L30: 0 | M30: 0 | O30: 0 | P30: 0 | R30: =(SUM(J30:P30))*$B$2 -> 5202.5979
... A69: T16 | B69: Madhusoodanan P.R. | C69: 8239.5 | D69: =SUM($C$3:$C$5)/64 -> 0 | E69: =C69+D69 -> 8239.5 | F69: =IF($C$70=0, 0, E69/$C$70) -> 0.019135706 | G69: =F69*$T$5 -> 688.88541 | H69: 3 | I69: =$T$7*H69 -> 353.43498 | J69: =G69+$T$9+I69 -> 1047.8428 | K69: =$T$11/64 -> 3913.9062 | L69: 0 | M69: 0 | O69: 0 | P69: 0 | R69: =(SUM(J69:P69))*$B$2 -> 4961.7491
B70: TOTAL | C70: =SUM(C3:C69) -> 430582.5 | D70: =SUM(D3:D69) -> 0 | E70: =SUM(E3:E69) -> 430582.5 | F70: =IF($C$70=0, 0, E70/$C$70) -> 1 | G70: =SUM(G3:G69) -> 36000 | H70: =SUM(H3:H69) -> 223 | I70: =SUM(I3:I69) -> 26272 | J70: =SUM(J3:J69) -> 62272 | K70: =SUM(K3:K69) -> 250490 | L70: =SUM(L3:L69) -> 3750 | M70: =SUM(M3:M69) -> 0 | N70: =SUM(N3:N69) -> 0 | ... P70: =SUM(P3:P69) -> 0 | R70: =SUM(R3:R69) -> 316512

Sheet June2025-COLLECTION
A1: FLAT # | C1: Amount | D1: Date | E1: Amount | F1: Date | G1: Amount | H1: Date | I1: Amount | J1: Date | K1: Total
A2: F1 | B2: Shailesh Srivastava / Azeem Nawaz | C2: 4374 | D2: 45831 | K2: =SUM(C2,E2,G2,I2) -> 4374
A3: F2 | B3: Shanthanu | C3: 33159 | D3: 45818 | E3: 8466 | F3: 45818 | K3: =SUM(C3,E3,G3,I3) -> 41625
A4: F3 | B4: Samrat Kar | C4: 6000 | D4: 45809 | K4: =SUM(C4,E4,G4,I4) -> 6000
A5: F4 | B5: Renu R | C5: 4434 | D5: 45819 | K5: =SUM(C5,E5,G5,I5) -> 4434
A6: F5 | B6: Vamsidhar Bethanabatla / Madhuri Anumula | C6: 4022 | D6: 45828 | E6: 4000 | F6: 45837 | K6: =SUM(C6,E6,G6,I6) -> 8022
A7: F6 | B7: Meghana Viral Shah and Vviral Shah (Owner) / Sangeet and Swagat (Tenent) | C7: 4331 | D7: 45821 | K7: =SUM(C7,E7,G7,I7) -> 4331
A8: F7 | B8: Vimal NK | C8: 4800.17 | D8: 45828 | K8: =SUM(C8,E8,G8,I8) -> 4800.17
A9: F8 | B9: Sujeet Kumar (Tenant)/Sreejith Menon (Owner) | C9: 4044 | D9: 45819 | K9: =SUM(C9,E9,G9,I9) -> 4044
A10: F9 | B10: Vijay Suswaram (Owner) / Divya Shikha (Tenant) | C10: 4310 | D10: 45821 | K10: =SUM(C10,E10,G10,I10) -> 4310
A11: F10 | B11: Aby Thomas | C11: 4246 | D11: 45832 | K11: =SUM(C11,E11,G11,I11) -> 4246
A12: F11 | B12: Niwin Anto | C12: 4272 | D12: 45819 | K12: =SUM(C12,E12,G12,I12) -> 4272
A13: F12 | B13: Anirudh Singh | C13: 4013 | D13: 45819 | K13: =SUM(C13,E13,G13,I13) -> 4013
A14: F13 | B14: Sanchay Saxena | C14: 6275 | D14: 45822 | K14: =SUM(C14,E14,G14,I14) -> 6275
A15: F14 | B15: Hemant Patel | C15: 4891 | D15: 45819 | K15: =SUM(C15,E15,G15,I15) -> 4891
A16: F15 | B16: Senthil.Vijayaragavan | C16: 5466 | D16: 45820 | K16: =SUM(C16,E16,G16,I16) -> 5466
A17: F16 | B17: Sreeja Sudharma | K17: =SUM(C17,E17,G17,I17) -> 0
A18: G1 | B18: Venkataramanan C | C18: 6306 | D18: 45809 | E18: 4989 | F18: 45821 | K18: =SUM(C18,E18,G18,I18) -> 11295
A19: G2 | B19: Kaushik Kasibhatla | C19: 5159 | D19: 45824 | E19: 7318 | F19: 45824 | K19: =SUM(C19,E19,G19,I19) -> 12477
A20: G3 | B20: Balakrishnan | C20: 5150 | D20: 45827 | K20: =SUM(C20,E20,G20,I20) -> 5150
A21: G4 | B21: Ashwin Pandith | C21: 5107 | D21: 45820 | K21: =SUM(C21,E21,G21,I21) -> 5107
A22: G5 | B22: Mayank Phophaliya | K22: =SUM(C22,E22,G22,I22) -> 0
A23: G6 | B23: Mohit Daga | C23: 85000 | D23: 45819 | K23: =SUM(C23,E23,G23,I23) -> 85000
A24: G7 | B24: Prince Richfield | K24: =SUM(C24,E24,G24,I24) -> 0
A25: G8 | B25: Ranjithkumar R / Sameer (tenant) / Princy (tenant) | C25: 4772 | D25: 45822 | K25: =SUM(C25,E25,G25,I25) -> 4772
A26: G9 | B26: Ankur Agarwal | C26: 6218 | D26: 45822 | E26: 4701 | F26: 45822 | K26: =SUM(C26,E26,G26,I26) -> 10919
A27: G10 | B27: Cijo Jacob / Thara Joy | C27: 4790 | D27: 45819 | K27: =SUM(C27,E27,G27,I27) -> 4790
A28: G11 | B28: Ketan Verlekar | C28: 4399 | D28: 45829 | K28: =SUM(C28,E28,G28,I28) -> 4399
A29: G12 | B29: Shyam Nair | C29: 9519 | D29: 45817 | E29: 5127 | F29: 45831 | K29: =SUM(C29,E29,G29,I29) -> 14646
A30: G13 | B30: Ajai.B | K30: =SUM(C30,E30,G30,I30) -> 0
A31: G14 | B31: Surajit Borah | C31: 5435 | D31: 45829 | K31: =SUM(C31,E31,G31,I31) -> 5435
A32: G15 | B32: Suresh Nallusamy / Antriksh (tenant) | C32: 4568 | D32: 45819 | K32: =SUM(C32,E32,G32,I32) -> 4568
A33: G16 | B33: Praveen Ganesan | C33: 5425 | D33: 45809 | E33: 4733 | F33: 45820 | K33: =SUM(C33,E33,G33,I33) -> 10158
A34: S1 | B34: S.N.Behera | C34: 4012 | D34: 45823 | K34: =SUM(C34,E34,G34,I34) -> 4012
A35: S2 | B35: Sonal Singh | C35: 50000 | D35: 45817 | E35: 20000 | F35: 45827 | G35: 7099 | H35: 45836 | K35: =SUM(C35,E35,G35,I35) -> 77099
A36: S3 | B36: Koteswararao | C36: 39966.54 | D36: 45827 | E36: 4272 | F36: 45829 | K36: =SUM(C36,E36,G36,I36) -> 44238.54
A37: S4 | B37: Swaminathan | C37: 4897 | D37: 45819 | K37: =SUM(C37,E37,G37,I37) -> 4897
A38: S5 | B38: Abhishek Gopalakrishnan | K38: =SUM(C38,E38,G38,I38) -> 0
A39: S6 | B39: Vivek Dhingra / Pratyush Das | K39: =SUM(C39,E39,G39,I39) -> 0
A40: S7 | B40: Harish B | C40: 4060 | D40: 45832 | K40: =SUM(C40,E40,G40,I40) -> 4060
...

Sheet July2025-EXPENSE
B1: JUL 2025 EXPENSES
A2: FLAT # | B2: 1 | C2: WATER USED IN LTRS | D2: COMMON AREA EQUALLY DEVIDED | E2: TOTAL FRESH WATER CONSUMED | F2: %OF TOTAL USED | G2: WATER EXPENSE SHARING BY % | H2: #METERS | I2: METER RENT | J2: VARIABLE EXPENSE = COMMON AREA METER RENT + WATER EXPENSE+ FLAT METER RENT | K2: FIXED EXPENSE SHARE | L2: PARKING FEE | M2: CLUB BOOKING FEE | N2: SHIFTING FEE | O2: GYM USAGE FEE | R2: TOTAL EXPENSE TO BE PAID
A3: CH | B3: MPFOWA | C3: 570.5 | D3: 0 | H3: 1 | I3: =T7 -> 117.81166
A4: GYM | B4: MPFOWA | C4: 0 | D4: 0 | H4: 1 | I4: =T7 -> 117.81166 | S4: TOTAL FIXED EXPENSE | T4: ='ANNUAL-EXPENSE-DETAILS'!BF6 -> 303879
A5: BSMT | B5: MPFOWA | C5: 0 | D5: 0 | H5: 1 | I5: =T7 -> 117.81166 | S5: TOTAL WATER EXPENSE | T5: ='ANNUAL-EXPENSE-DETAILS'!BE6 -> 39800
A6: F1 | B6: Shailesh Srivastava / Azeem Nawaz | C6: 4312 | D6: =SUM($C$3:$C$5)/64 -> 8.9140625 | E6: =C6+D6 -> 4320.9141 | F6: =IF($C$70=0, 0, E6/$C$70) -> 0.0097901545 | G6: =F6*$T$5 -> 389.64815 | H6: 3 | I6: =$T$7*H6 -> 353.43498 | J6: =G6+$T$9+I6 -> 748.60555 | K6: =$T$11/64 -> 4748.1094 | L6: 0 | M6: 0 | N6: 0 | O6: 0 | R6: =(J6+K6+L6+M6+N6+O6)*$B$2 -> 5496.7149
A7: F2 | B7: Shanthanu | C7: 17011.5 | D7: =SUM($C$3:$C$5)/64 -> 8.9140625 | E7: =C7+D7 -> 17020.414 | F7: =IF($C$70=0, 0, E7/$C$70) -> 0.038564174 | G7: =F7*$T$5 -> 1534.8541 | H7: 4 | I7: =$T$7*H7 -> 471.24664 | J7: =G7+$T$9+I7 -> 2011.6232 | K7: =$T$11/64 -> 4748.1094 | L7: 0 | M7: 0 | N7: 0 | O7: 0 | R7: =(J7+K7+L7+M7+N7+O7)*$B$2 -> 6759.7326 | S7: RENT PER METER | T7: 117.81166
A8: F3 | B8: Samrat Kar | C8: 17231.5 | D8: =SUM($C$3:$C$5)/64 -> 8.9140625 | E8: =C8+D8 -> 17240.414 | F8: =IF($C$70=0, 0, E8/$C$70) -> 0.039062642 | G8: =F8*$T$5 -> 1554.6931 | H8: 4 | I8: =$T$7*H8 -> 471.24664 | J8: =G8+$T$9+I8 -> 2031.4622 | K8: =$T$11/64 -> 4748.1094 | L8: 750 | M8: 0 | N8: 0 | O8: 0 | R8: =(J8+K8+L8+M8+N8+O8)*$B$2 -> 7529.5716 | S8: COMMON AREA METER RENT | T8: =$T$7*3 -> 353.43498
A9: F4 | B9: Renu R | C9: 3636 | D9: =SUM($C$3:$C$5)/64 -> 8.9140625 | E9: =C9+D9 -> 3644.9141 | F9: =IF($C$70=0, 0, E9/$C$70) -> 0.0082585007 | G9: =F9*$T$5 -> 328.68833 | H9: 4 | I9: =$T$7*H9 -> 471.24664 | J9: =G9+$T$9+I9 -> 805.45739 | K9: =$T$11/64 -> 4748.1094 | L9: 0 | M9: 0 | N9: 0 | O9: 0 | R9: =(J9+K9+L9+M9+N9+O9)*$B$2 -> 5553.5668 | S9: COMMON AREA METER RENT/FLAT | T9: =T8/64 -> 5.5224215
A10: F5 | B10: Vamsidhar Bethanabatla / Madhuri Anumula | C10: 715.5 | D10: =SUM($C$3:$C$5)/64 -> 8.9140625 | E10: =C10+D10 -> 724.41406 | F10: =IF($C$70=0, 0, E10/$C$70) -> 0.0016413485 | G10: =F10*$T$5 -> 65.325668 | H10: 3 | I10: =$T$7*H10 -> 353.43498 | J10: =G10+$T$9+I10 -> 424.28307 | K10: =$T$11/64 -> 4748.1094 | L10: 0 | M10: 0 | N10: 0 | O10: 0 | R10: =(J10+K10+L10+M10+N10+O10)*$B$2 -> 5172.3924
A11: F6 | B11: Meghana Viral Shah and Vviral Shah (Owner) / Sangeet and Swagat (Tenent) | C11: 3962.5 | D11: =SUM($C$3:$C$5)/64 -> 8.9140625 | E11: =C11+D11 -> 3971.4141 | F11: =IF($C$70=0, 0, E11/$C$70) -> 0.0089982714 | G11: =F11*$T$5 -> 358.1312 | H11: 3 | I11: =$T$7*H11 -> 353.43498 | J11: =G11+$T$9+I11 -> 717.0886 | K11: =$T$11/64 -> 4748.1094 | L11: 0 | M11: 0 | N11: 0 | O11: 0 | R11: =(J11+K11+L11+M11+N11+O11)*$B$2 -> 5465.198 | S11: TOTAL FIXED EXPENSE | T11: ='ANNUAL-EXPENSE-DETAILS'!BF6 -> 303879
A12: F7 | B12: Vimal NK | C12: 895.5 | D12: =SUM($C$3:$C$5)/64 -> 8.9140625 | E12: =C12+D12 -> 904.41406 | F12: =IF($C$70=0, 0, E12/$C$70) -> 0.0020491853 | G12: =F12*$T$5 -> 81.557573 | H12: 3 | I12: =$T$7*H12 -> 353.43498 | J12: =G12+$T$9+I12 -> 440.51497 | K12: =$T$11/64 -> 4748.1094 | L12: 750 | M12: 0 | N12: 0 | O12: 0 | R12: =(J12+K12+L12+M12+N12+O12)*$B$2 -> 5938.6243
A13: F8 | B13: Sujeet Kumar (Tenant)/Sreejith Menon (Owner) | C13: 148.5 | D13: =SUM($C$3:$C$5)/64 -> 8.9140625 | E13: =C13+D13 -> 157.41406 | F13: =IF($C$70=0, 0, E13/$C$70) -> 0.0003566625 | G13: =F13*$T$5 -> 14.195167 | H13: 3 | I13: =$T$7*H13 -> 353.43498 | J13: =G13+$T$9+I13 -> 373.15257 | K13: =$T$11/64 -> 4748.1094 | L13: 0 | M13: 0 | N13: 0 | O13: 0 | R13: =(J13+K13+L13+M13+N13+O13)*$B$2 -> 5121.2619
A14: F9 | B14: Vijay Suswaram (Owner) / Divya Shikha (Tenant) | C14: 2308 | D14: =SUM($C$3:$C$5)/64 -> 8.9140625 | E14: =C14+D14 -> 2316.9141 | F14: =IF($C$70=0, 0, E14/$C$70) -> 0.0052495713 | G14: =F14*$T$5 -> 208.93294 | H14: 4 | I14: =$T$7*H14 -> 471.24664 | J14: =G14+$T$9+I14 -> 685.702 | K14: =$T$11/64 -> 4748.1094 | L14: 0 | M14: 0 | N14: 0 | O14: 0 | R14: =(J14+K14+L14+M14+N14+O14)*$B$2 -> 5433.8114 | S14: BALANCE IN ACCOUNT ON 31-JULY-2023
A15: F10 | B15: Aby Thomas | C15: 3221 | D15: =SUM($C$3:$C$5)/64 -> 8.9140625 | E15: =C15+D15 -> 3229.9141 | F15: =IF($C$70=0, 0, E15/$C$70) -> 0.0073182103 | G15: =F15*$T$5 -> 291.26477 | H15: 3 | I15: =$T$7*H15 -> 353.43498 | J15: =G15+$T$9+I15 -> 650.22217 | K15: =$T$11/64 -> 4748.1094 | L15: 0 | M15: 0 | N15: 0 | O15: 0 | R15: =(J15+K15+L15+M15+N15+O15)*$B$2 -> 5398.3315 | S15: TOTAL NON MAINTENANCE CORPUS COLLECTION
A16: F11 | B16: Niwin Anto | C16: 1220.5 | D16: =SUM($C$3:$C$5)/64 -> 8.9140625 | E16: =C16+D16 -> 1229.4141 | F16: =IF($C$70=0, 0, E16/$C$70) -> 0.0027855573 | G16: =F16*$T$5 -> 110.86518 | H16: 3 | I16: =$T$7*H16 -> 353.43498 | J16: =G16+$T$9+I16 -> 469.82258 | K16: =$T$11/64 -> 4748.1094 | L16: 0 | M16: 0 | N16: 0 | O16: 0 | R16: =(J16+K16+L16+M16+N16+O16)*$B$2 -> 5217.932 | S16: TOTAL FD DONE
A17: F12 | B17: Anirudh Singh | C17: 1.5 | D17: =SUM($C$3:$C$5)/64 -> 8.9140625 | E17: =C17+D17 -> 10.414062 | F17: =IF($C$70=0, 0, E17/$C$70) -> 2.3595767e-05 | G17: =F17*$T$5 -> 0.93911152 | H17: 3 | I17: =$T$7*H17 -> 353.43498 | J17: =G17+$T$9+I17 -> 359.89651 | K17: =$T$11/64 -> 4748.1094 | L17: 0 | M17: 0 | N17: 0 | O17: 0 | R17: =(J17+K17+L17+M17+N17+O17)*$B$2 -> 5108.0059 | S17: AMOUNT AVAILABLE FOR NON MAINTENANCE CORPUS | T17: =T15-T16 -> 0
A18: F13 | B18: Sanchay Saxena | C18: 11200.5 | D18: =SUM($C$3:$C$5)/64 -> 8.9140625 | E18: =C18+D18 -> 11209.414 | F18: =IF($C$70=0, 0, E18/$C$70) -> 0.025397843 | G18: =F18*$T$5 -> 1010.8341 | H18: 4 | I18: =$T$7*H18 -> 471.24664 | J18: =G18+$T$9+I18 -> 1487.6032 | K18: =$T$11/64 -> 4748.1094 | L18: 0 | M18: 0 | N18: 0 | O18: 0 | R18: =(J18+K18+L18+M18+N18+O18)*$B$2 -> 6235.7126 | S18: AMOUNT AVAILABLE FOR MAINTENANCE | T18: =T14-T17 -> 0
A19: F14 | B19: Hemant Patel | C19: 2363.5 | D19: =SUM($C$3:$C$5)/64 -> 8.9140625 | E19: =C19+D19 -> 2372.4141 | F19: =IF($C$70=0, 0, E19/$C$70) -> 0.005375321 | G19: =F19*$T$5 -> 213.93778 | H19: 4 | I19: =$T$7*H19 -> 471.24664 | J19: =G19+$T$9+I19 -> 690.70683 | K19: =$T$11/64 -> 4748.1094 | L19: 0 | M19: 0 | N19: 0 | O19: 0 | R19: =(J19+K19+L19+M19+N19+O19)*$B$2 -> 5438.8162
A20: F15 | B20: Senthil.Vijayaragavan | C20: 5665 | D20: =SUM($C$3:$C$5)/64 -> 8.9140625 | E20: =C20+D20 -> 5673.9141 | F20: =IF($C$70=0, 0, E20/$C$70) -> 0.012855728 | G20: =F20*$T$5 -> 511.65797 | H20: 4 | I20: =$T$7*H20 -> 471.24664 | J20: =G20+$T$9+I20 -> 988.42703 | K20: =$T$11/64 -> 4748.1094 | L20: 750 | M20: 0 | N20: 0 | O20: 0 | R20: =(J20+K20+L20+M20+N20+O20)*$B$2 -> 6486.5364
A21: F16 | B21: Sreeja Sudharma | C21: 12832.5 | D21: =SUM($C$3:$C$5)/64 -> 8.9140625 | E21: =C21+D21 -> 12841.414 | F21: =IF($C$70=0, 0, E21/$C$70) -> 0.029095563 | G21: =F21*$T$5 -> 1158.0034 | H21: 3 | I21: =$T$7*H21 -> 353.43498 | J21: =G21+$T$9+I21 -> 1516.9608 | K21: =$T$11/64 -> 4748.1094 | L21: 0 | M21: 0 | N21: 0 | O21: 0 | R21: =(J21+K21+L21+M21+N21+O21)*$B$2 -> 6265.0702
A22: G1 | B22: Venkataramanan C | C22: 10356 | D22: =SUM($C$3:$C$5)/64 -> 8.9140625 | E22: =C22+D22 -> 10364.914 | F22: =IF($C$70=0, 0, E22/$C$70) -> 0.023484408 | G22: =F22*$T$5 -> 934.67945 | H22: 3 | I22: =$T$7*H22 -> 353.43498 | J22: =G22+$T$9+I22 -> 1293.6368 | K22: =$T$11/64 -> 4748.1094 | L22: 0 | M22: 0 | N22: 0 | O22: 0 | R22: =(J22+K22+L22+M22+N22+O22)*$B$2 -> 6041.7462
A23: G2 | B23: Kaushik Kasibhatla | C23: 13897 | D23: =SUM($C$3:$C$5)/64 -> 8.9140625 | E23: =C23+D23 -> 13905.914 | F23: =IF($C$70=0, 0, E23/$C$70) -> 0.031507465 | G23: =F23*$T$5 -> 1253.9971 | H23: 4 | I23: =$T$7*H23 -> 471.24664 | J23: =G23+$T$9+I23 -> 1730.7662 | K23: =$T$11/64 -> 4748.1094 | L23: 0 | M23: 0 | N23: 0 | O23: 0 | R23: =(J23+K23+L23+M23+N23+O23)*$B$2 -> 6478.8755
A24: G3 | B24: Balakrishnan | C24: 14771 | D24: =SUM($C$3:$C$5)/64 -> 8.9140625 | E24: =C24+D24 -> 14779.914 | F24: =IF($C$70=0, 0, E24/$C$70) -> 0.033487739 | G24: =F24*$T$5 -> 1332.812 | H24: 4 | I24: =$T$7*H24 -> 471.24664 | J24: =G24+$T$9+I24 -> 1809.5811 | K24: =$T$11/64 -> 4748.1094 | L24: 0 | M24: 0 | N24: 0 | O24: 0 | R24: =(J24+K24+L24+M24+N24+O24)*$B$2 -> 6557.6904
A25: G4 | B25: Ashwin Pandith | C25: 20576 | D25: =SUM($C$3:$C$5)/64 -> 8.9140625 | E25: =C25+D25 -> 20584.914 | F25: =IF($C$70=0, 0, E25/$C$70) -> 0.046640476 | G25: =F25*$T$5 -> 1856.291 | H25: 4 | I25: =$T$7*H25 -> 471.24664 | J25: =G25+$T$9+I25 -> 2333.06 | K25: =$T$11/64 -> 4748.1094 | L25: 0 | M25: 0 | N25: 0 | O25: 0 | R25: =(J25+K25+L25+M25+N25+O25)*$B$2 -> 7081.1694
A26: G5 | B26: Mayank Phophaliya | C26: 4303.5 | D26: =SUM($C$3:$C$5)/64 -> 8.9140625 | E26: =C26+D26 -> 4312.4141 | F26: =IF($C$70=0, 0, E26/$C$70) -> 0.0097708955 | G26: =F26*$T$5 -> 388.88164 | H26: 3 | I26: =$T$7*H26 -> 353.43498 | J26: =G26+$T$9+I26 -> 747.83904 | K26: =$T$11/64 -> 4748.1094 | L26: 0 | M26: 0 | N26: 0 | O26: 0 | R26: =(J26+K26+L26+M26+N26+O26)*$B$2 -> 5495.9484
A27: G6 | B27: Mohit Daga | C27: 7473.5 | D27: =SUM($C$3:$C$5)/64 -> 8.9140625 | E27: =C27+D27 -> 7482.4141 | F27: =IF($C$70=0, 0, E27/$C$70) -> 0.016953355 | G27: =F27*$T$5 -> 674.74353 | H27: 3 | I27: =$T$7*H27 -> 353.43498 | J27: =G27+$T$9+I27 -> 1033.7009 | K27: =$T$11/64 -> 4748.1094 | L27: 0 | M27: 0 | N27: 0 | O27: 0 | R27: =(J27+K27+L27+M27+N27+O27)*$B$2 -> 5781.8103
A28: G7 | B28: Prince Richfield | C28: 5843 | D28: =SUM($C$3:$C$5)/64 -> 8.9140625 | E28: =C28+D28 -> 5851.9141 | F28: =IF($C$70=0, 0, E28/$C$70) -> 0.013259033 | G28: =F28*$T$5 -> 527.70952 | H28: 3 | I28: =$T$7*H28 -> 353.43498 | J28: =G28+$T$9+I28 -> 886.66692 | K28: =$T$11/64 -> 4748.1094 | L28: 0 | M28: 0 | N28: 0 | O28: 0 | R28: =(J28+K28+L28+M28+N28+O28)*$B$2 -> 5634.7763
A29: G8 | B29: Ranjithkumar R / Sameer (tenant) / Princy (tenant) | C29: 9415.5 | D29: =SUM($C$3:$C$5)/64 -> 8.9140625 | E29: =C29+D29 -> 9424.4141 | F29: =IF($C$70=0, 0, E29/$C$70) -> 0.021353461 | G29: =F29*$T$5 -> 849.86775 | H29: 3 | I29: =$T$7*H29 -> 353.43498 | J29: =G29+$T$9+I29 -> 1208.8251 | K29: =$T$11/64 -> 4748.1094 | L29: 0 | M29: 0 | N29: 0 | O29: 0 | R29: =(J29+K29+L29+M29+N29+O29)*$B$2 -> 5956.9345
A30: G9 | B30: Chandramouli | C30: 5828.5 | D30: =SUM($C$3:$C$5)/64 -> 8.9140625 | E30: =C30+D30 -> 5837.4141 | F30: =IF($C$70=0, 0, E30/$C$70) -> 0.01322618 | G30: =F30*$T$5 -> 526.40195 | H30: 5 | I30: =$T$7*H30 -> 589.0583 | J30: =G30+$T$9+I30 -> 1120.9827 | K30: =$T$11/64 -> 4748.1094 | L30: 0 | M30: 0 | N30: 0 | O30: 0 | R30: =(J30+K30+L30+M30+N30+O30)*$B$2 -> 5869.092
... A69: T16 | B69: Madhusoodanan P.R. | C69: 8509.5 | D69: =SUM($C$3:$C$5)/64 -> 8.9140625 | E69: =C69+D69 -> 8518.4141 | F69: =IF($C$70=0, 0, E69/$C$70) -> 0.019300682 | G69: =F69*$T$5 -> 768.16716 | H69: 3 | I69: =$T$7*H69 -> 353.43498 | J69: =G69+$T$9+I69 -> 1127.1246 | K69: =$T$11/64 -> 4748.1094 | L69: 0 | M69: 0 | N69: 0 | O69: 0 | R69: =(J69+K69+L69+M69+N69+O69)*$B$2 -> 5875.2339
B70: TOTAL | C70: =SUM(C3:C69) -> 441353 | D70: =SUM(D3:D69) -> 570.5 | E70: =SUM(E3:E69) -> 441353 | F70: =SUM(F3:F69) -> 1 | G70: =SUM(G3:G69) -> 39800 | H70: =SUM(H3:H69) -> 223 | I70: =SUM(I3:I69) -> 26272 | J70: =SUM(J3:J69) -> 66072 | ... O70: =SUM(O3:O69) -> 0 | R70: =SUM(R3:R69) -> 372951

Sheet July2025-EXPENSE-Flatwise
A1: Expense Head | C1: {=TRANSPOSE('INCOME-EXPENSE-CYCLES'!A3:A66)} -> F1 | D1: F2 | E1: F3 | F1: F4 | G1: F5 | H1: F6 | I1: F7 | J1: F8 | K1: F9 | L1: F10 | M1: F11 | N1: F12 | O1: F13 | P1: F14 | Q1: F15 | R1: F16 | S1: G1 | T1: G2 | U1: G3 | V1: G4 | W1: G5 | X1: G6 | Y1: G7 | Z1: G8 | AA1: G9 | AB1: G10 | AC1: G11 | AD1: G12 | AE1: G13 | AF1: G14 | AG1: G15 | AH1: G16 | AI1: S1 | AJ1: S2 | AK1: S3 | AL1: S4 | AM1: S5 | AN1: S6 | AO1: S7 | AP1: S8 | AQ1: S9 | AR1: S10 | AS1: S11 | AT1: S12 | AU1: S13 | AV1: S14 | AW1: S15 | AX1: S16 | AY1: T1 | AZ1: T2 | BA1: T3 | BB1: T4 | BC1: T5 | BD1: T6 | BE1: T7 | BF1: T8 | BG1: T9 | BH1: T10 | BI1: T11 | BJ1: T12 | BK1: T13 | BL1: T14 | BM1: T15 | BN1: T16
A2: Water consumption (Litres) | C2: {=TRANSPOSE('July2025-EXPENSE'!E6:E69)} -> 4320.9141 | D2: 17020.414 | E2: 17240.414 | F2: 3644.9141 | G2: 724.41406 | H2: 3971.4141 | I2: 904.41406 | J2: 157.41406 | K2: 2316.9141 | L2: 3229.9141 | M2: 1229.4141 | N2: 10.414062 | O2: 11209.414 | P2: 2372.4141 | Q2: 5673.9141 | R2: 12841.414 | S2: 10364.914 | T2: 13905.914 | U2: 14779.914 | V2: 20584.914 | W2: 4312.4141 | X2: 7482.4141 | Y2: 5851.9141 | Z2: 9424.4141 | AA2: 5837.4141 | AB2: 9988.4141 | AC2: 2990.9141 | AD2: 11232.914 | AE2: 7763.9141 | AF2: 6269.4141 | AG2: 8.9140625 | AH2: 2110.4141 | AI2: 784.41406 | AJ2: 34111.914 | AK2: 2577.9141 | AL2: 2026.9141 | AM2: 8225.9141 | AN2: 308.91406 | AO2: 674.91406 | AP2: 19106.414 | AQ2: 2420.4141 | AR2: 548.41406 | AS2: 8929.4141 | AT2: 8847.9141 | AU2: 3298.4141 | AV2: 5220.4141 | AW2: 14166.414 | AX2: 4644.9141 | AY2: 14535.414 | AZ2: 15236.914 | BA2: 9869.4141 | BB2: 11494.414 | BC2: 2155.9141 | BD2: 13178.914 | BE2: 1564.4141 | BF2: 1035.9141 | BG2: 6817.9141 | BH2: 310.41406 | BI2: 2707.9141 | BJ2: 1237.9141 | BK2: 3438.4141 | BL2: 3199.4141 | BM2: 10380.414 | BN2: 8518.4141
