Workbook

Sheet Members
A1: FLAT | B1: NAME | C1: EMAIL | D1: PHONE | F1: FY_START_YEAR | G1: FY_END_YEAR | H1: FY_LABEL
A2: F1 | B2: Shailesh Srivastava | C2: shailesh.srivastav@gmail.com | F2: 2026 | G2: =F2+1 -> 2027 | H2: =F2&"-"&RIGHT(F2+1,2) -> 2026-27
A3: F2 | B3: Rama P | C3: ramazen1@gmail.com
A4: F3 | B4: Samrat Kar | C4: samratk@gmail.com | D4: 919342554680
A5: F4 | B5: Renu R | C5: renu.sabapathy@gmail.com
A6: F5 | B6: Vamsidhar Bethanabatla
A7: F6 | B7: Viral Shah | C7: viralshah79@gmail.com
A8: F7 | B8: Vimal NK | C8: nkvimal@gmail.com
A9: F8 | B9: Ruhi Agrawal | C9: ruhi.agrawal321@gmail.com
A10: F9 | B10: Vijay Suswaram | C10: vijay.suswaram@gmail.com | D10: 9066901046
A11: F10 | B11: Aby Thomas | C11: abythomas99@gmail.com | D11: 9900502987
A12: F11 | B12: Renu R
A13: F12 | B13: Kavitha T | C13: kaveeonline@gmail.com | D13: 9945796695
A14: F13 | B14: Srinivasa Rao
A15: F14 | B15: Hemant Patel | C15: hemant.patel.ec@gmail.com | D15: 9880934229
A16: F15 | B16: Senthil.Vijayaragavan | C16: senthil.web@gmail.com | D16: 919035031349
A17: F16 | B17: Sreeja Sudharma | C17: sudharma.sreeja@gmail.com
A18: G1 | B18: Digvijay Verma | C18: jyothij1979@gmail.com | D18: 9686438624
A19: G2 | B19: Kaushik Kasibhatla
A20: G3 | B20: Balakrishnan | C20: balakrishnan.k@gmail.com
A21: G4 | B21: Ashwin Pandith | C21: ashwinpandith@gmail.com
A22: G5 | B22: Mayank Phophaliya
A23: G6 | B23: Srinath | D23: 09910099526
A24: G7 | B24: Prince Richfield | C24: princerichfield@gmail.com | D24: 7760487323
A25: G8 | B25: Arun M | C25: arun.pharmaplus@gmail.com
A26: G9 | B26: Chandramouli | C26: chandra.gumma@gmail.com
A27: G10 | B27: Richa Singh | C27: richasingh.kaharwar@gmail.com | D27: 9986432045
A28: G11 | B28: Prashant Jaitley | C28: prashantjaitly656@gmail.com | D28: 9654889504
A29: G12 | B29: Shyam Nair | C29: g12.shyam@gmail.com | D29: 7709047957
A30: G13 | B30: Ajai.B | C30: ajai.abc@gmail.com
A31: G14 | B31: Surajit Borah | C31: surajit.borah@gmail.com | D31: 7829872270
A32: G15 | B32: Suresh Nallusamy | C32: suresh.nallusamy@gmail.com
A33: G16 | B33: Praveen Ganesan | C33: praveengb@gmail.com | D33: 8050164658
A34: S1 | B34: S.N.Behera | C34: snbeheras1@gmail.com | D34: 919980008526
A35: S2 | B35: Sonal Singh | C35: sonal.singhal86@gmail.com
A36: S3 | B36: Manikandan N
A37: S4 | B37: Swami | C37: swami2007@gmail.com
A38: S5 | B38: Abhishek Gopalakrishnan | C38: abhishek.harekrishna@gmail.com | D38: 7042447356
A39: S6 | B39: Vivek Dhingra | C39: vivek.dhingra@gmail.com
A40: S7 | B40: Harish B | C40: harishb80@gmail.com | D40: 9980848757
...

Sheet Apr2026-EXPENSE
B1: APR 2026 EXPENSES
A2: FLAT # | B2: 1 | C2: WATER USED IN LTRS | D2: COMMON AREA WATER EQUALLY DIVIDED (L) | E2: TOTAL FRESH WATER CONSUMED(L) | F2: %OF TOTAL WATER USED | G2: WATER EXPENSE SHARING BY % | H2: #METERS | I2: METER RENT (Rs) | J2: TOTAL VARIABLE = (COMMON AREA METER RENT + WATER EXPENSE+ FLAT METER RENT (Rs)) | K2: FIXED EXPENSE SHARE(Rs) | L2: PARKING FEE(Rs) | M2: CLUB HOUSE FEE (Rs) | N2: SHIFTING FEE (Rs) | O2: GYM USAGE FEE(Rs) | P2: COVID+ GARBAGE FEE (Rs) | Q2: ANNUAL MEMBERSHIP FEE (Rs) | R2: TOTAL EXPENSE TO BE PAID (Rs)
A3: CH | B3: MPFOWA | C3: 0 | D3: 0 | H3: 1 | I3: =T7 -> 117.8112
A4: GYM | B4: MPFOWA | C4: 0 | D4: 0 | H4: 1 | I4: =T7 -> 117.8112 | S4: TOTAL FIXED EXPENSE | T4: ='ANNUAL-EXPENSE-DETAILS'!V3 -> 269762
A5: BSMT | B5: MPFOWA | C5: 0 | D5: 0 | H5: 1 | I5: =T7 -> 117.8112 | S5: TOTAL WATER EXPENSE | T5: ='ANNUAL-EXPENSE-DETAILS'!U3 -> 48800
A6: F1 | B6: =VLOOKUP(A6,Members!$A$2:$B$65,2,FALSE) -> Shailesh Srivastava | C6: 4356.5 | D6: =SUM($C$3:$C$5)/64 -> 0 | E6: =C6+D6 -> 4356.5 | F6: =IF($C$70=0, 0, E6/$C$70) -> 0.010850614 | G6: =F6*$T$5 -> 529.50999 | H6: 3 | I6: =$T$7*H6 -> 353.4336 | J6: =G6+$T$9+I6 -> 888.46599 | K6: =$T$4/64 -> 4215.0312 | L6: 0 | M6: 0 | N6: 0 | O6: 0 | P6: 0 | Q6: 0 | R6: =(J6+K6+L6+M6+Q6+N6+O6+P6)*$B$2 -> 5103.4972
A7: F2 | B7: =VLOOKUP(A7,Members!$A$2:$B$65,2,FALSE) -> Rama P | C7: 10484 | D7: =SUM($C$3:$C$5)/64 -> 0 | E7: =C7+D7 -> 10484 | F7: =IF($C$70=0, 0, E7/$C$70) -> 0.02611221 | G7: =F7*$T$5 -> 1274.2758 | H7: 4 | I7: =$T$7*H7 -> 471.2448 | J7: =G7+$T$9+I7 -> 1751.043 | K7: =$T$4/64 -> 4215.0312 | L7: 0 | M7: 0 | N7: 0 | O7: 0 | P7: 0 | Q7: 0 | R7: =(J7+K7+L7+M7+Q7+N7+O7+P7)*$B$2 -> 5966.0743 | S7: RENT PER METER (Rs) | T7: =(99.84+0.18*99.84) -> 117.8112
A8: F3 | B8: =VLOOKUP(A8,Members!$A$2:$B$65,2,FALSE) -> Samrat Kar | C8: 10870 | D8: =SUM($C$3:$C$5)/64 -> 0 | E8: =C8+D8 -> 10870 | F8: =IF($C$70=0, 0, E8/$C$70) -> 0.027073609 | G8: =F8*$T$5 -> 1321.1921 | H8: 4 | I8: =$T$7*H8 -> 471.2448 | J8: =G8+$T$9+I8 -> 1797.9593 | K8: =$T$4/64 -> 4215.0312 | L8: 750 | M8: 0 | N8: 0 | O8: 0 | P8: 0 | Q8: 0 | R8: =(J8+K8+L8+M8+Q8+N8+O8+P8)*$B$2 -> 6762.9906 | S8: COMMON AREA METER RENT(Rs) | T8: =$T$7*3 -> 353.4336
A9: F4 | B9: =VLOOKUP(A9,Members!$A$2:$B$65,2,FALSE) -> Renu R | C9: 4632 | D9: =SUM($C$3:$C$5)/64 -> 0 | E9: =C9+D9 -> 4632 | F9: =IF($C$70=0, 0, E9/$C$70) -> 0.011536795 | G9: =F9*$T$5 -> 562.99558 | H9: 4 | I9: =$T$7*H9 -> 471.2448 | J9: =G9+$T$9+I9 -> 1039.7628 | K9: =$T$4/64 -> 4215.0312 | L9: 0 | M9: 0 | N9: 0 | O9: 0 | P9: 0 | Q9: 0 | R9: =(J9+K9+L9+M9+Q9+N9+O9+P9)*$B$2 -> 5254.794 | S9: COMMON AREA METER RENT/FLAT (Rs) | T9: =T8/64 -> 5.5224
A10: F5 | B10: =VLOOKUP(A10,Members!$A$2:$B$65,2,FALSE) -> Vamsidhar Bethanabatla | C10: 3771 | D10: =SUM($C$3:$C$5)/64 -> 0 | E10: =C10+D10 -> 3771 | F10: =IF($C$70=0, 0, E10/$C$70) -> 0.0093923257 | G10: =F10*$T$5 -> 458.3455 | H10: 3 | I10: =$T$7*H10 -> 353.4336 | J10: =G10+$T$9+I10 -> 817.3015 | K10: =$T$4/64 -> 4215.0312 | L10: 0 | M10: 0 | N10: 0 | O10: 0 | P10: 0 | Q10: 0 | R10: =(J10+K10+L10+M10+Q10+N10+O10+P10)*$B$2 -> 5032.3327
A11: F6 | B11: =VLOOKUP(A11,Members!$A$2:$B$65,2,FALSE) -> Viral Shah | C11: 6789.5 | D11: =SUM($C$3:$C$5)/64 -> 0 | E11: =C11+D11 -> 6789.5 | F11: =IF($C$70=0, 0, E11/$C$70) -> 0.01691042 | G11: =F11*$T$5 -> 825.22852 | H11: 3 | I11: =$T$7*H11 -> 353.4336 | J11: =G11+$T$9+I11 -> 1184.1845 | K11: =$T$4/64 -> 4215.0312 | L11: 0 | M11: 0 | N11: 0 | O11: 0 | P11: 0 | Q11: 0 | R11: =(J11+K11+L11+M11+Q11+N11+O11+P11)*$B$2 -> 5399.2158 | S11: BALANCE IN ACCOUNT ON 30-Apr-2023
A12: F7 | B12: =VLOOKUP(A12,Members!$A$2:$B$65,2,FALSE) -> Vimal NK | C12: 59 | D12: =SUM($C$3:$C$5)/64 -> 0 | E12: =C12+D12 -> 59 | F12: =IF($C$70=0, 0, E12/$C$70) -> 0.00014694967 | G12: =F12*$T$5 -> 7.1711441 | H12: 3 | I12: =$T$7*H12 -> 353.4336 | J12: =G12+$T$9+I12 -> 366.12714 | K12: =$T$4/64 -> 4215.0312 | L12: 750 | M12: 0 | N12: 0 | O12: 0 | P12: 0 | Q12: 0 | R12: =(J12+K12+L12+M12+Q12+N12+O12+P12)*$B$2 -> 5331.1584 | S12: TOTAL NON MAINTENANCE CORPUS COLLECTION
A13: F8 | B13: =VLOOKUP(A13,Members!$A$2:$B$65,2,FALSE) -> Ruhi Agrawal | C13: 3714 | D13: =SUM($C$3:$C$5)/64 -> 0 | E13: =C13+D13 -> 3714 | F13: =IF($C$70=0, 0, E13/$C$70) -> 0.0092503574 | G13: =F13*$T$5 -> 451.41744 | H13: 3 | I13: =$T$7*H13 -> 353.4336 | J13: =G13+$T$9+I13 -> 810.37344 | K13: =$T$4/64 -> 4215.0312 | L13: 0 | M13: 0 | N13: 0 | O13: 0 | P13: 0 | Q13: 0 | R13: =(J13+K13+L13+M13+Q13+N13+O13+P13)*$B$2 -> 5025.4047 | S13: TOTAL FD DONE
A14: F9 | B14: =VLOOKUP(A14,Members!$A$2:$B$65,2,FALSE) -> Vijay Suswaram | C14: 2051 | D14: =SUM($C$3:$C$5)/64 -> 0 | E14: =C14+D14 -> 2051 | F14: =IF($C$70=0, 0, E14/$C$70) -> 0.0051083692 | G14: =F14*$T$5 -> 249.28841 | H14: 4 | I14: =$T$7*H14 -> 471.2448 | J14: =G14+$T$9+I14 -> 726.05561 | K14: =$T$4/64 -> 4215.0312 | L14: 0 | M14: 0 | N14: 0 | O14: 0 | P14: 0 | Q14: 0 | R14: =(J14+K14+L14+M14+Q14+N14+O14+P14)*$B$2 -> 4941.0869 | S14: AMOUNT AVAILABLE FOR NON MAINTENANCE CORPUS IN CURRENT AC | T14: =T12-T13 -> 0
A15: F10 | B15: =VLOOKUP(A15,Members!$A$2:$B$65,2,FALSE) -> Aby Thomas | C15: 9535 | D15: =SUM($C$3:$C$5)/64 -> 0 | E15: =C15+D15 -> 9535 | F15: =IF($C$70=0, 0, E15/$C$70) -> 0.023748562 | G15: =F15*$T$5 -> 1158.9298 | H15: 3 | I15: =$T$7*H15 -> 353.4336 | J15: =G15+$T$9+I15 -> 1517.8858 | K15: =$T$4/64 -> 4215.0312 | L15: 0 | M15: 0 | N15: 0 | O15: 0 | P15: 0 | Q15: 0 | R15: =(J15+K15+L15+M15+Q15+N15+O15+P15)*$B$2 -> 5732.9171 | S15: Pending vendor payments
A16: F11 | B16: =VLOOKUP(A16,Members!$A$2:$B$65,2,FALSE) -> Renu R | C16: 874 | D16: =SUM($C$3:$C$5)/64 -> 0 | E16: =C16+D16 -> 874 | F16: =IF($C$70=0, 0, E16/$C$70) -> 0.0021768477 | G16: =F16*$T$5 -> 106.23017 | H16: 3 | I16: =$T$7*H16 -> 353.4336 | J16: =G16+$T$9+I16 -> 465.18617 | K16: =$T$4/64 -> 4215.0312 | L16: 0 | M16: 0 | N16: 0 | O16: 0 | P16: 0 | Q16: 0 | R16: =(J16+K16+L16+M16+Q16+N16+O16+P16)*$B$2 -> 4680.2174 | S16: AMOUNT AVAILABLE FOR MAINTENANCE | T16: =T11-T14-T15 -> 0
A17: F12 | B17: =VLOOKUP(A17,Members!$A$2:$B$65,2,FALSE) -> Kavitha T | C17: 30.5 | D17: =SUM($C$3:$C$5)/64 -> 0 | E17: =C17+D17 -> 30.5 | F17: =IF($C$70=0, 0, E17/$C$70) -> 7.5965509e-05 | G17: =F17*$T$5 -> 3.7071168 | H17: 3 | I17: =$T$7*H17 -> 353.4336 | J17: =G17+$T$9+I17 -> 362.66312 | K17: =$T$4/64 -> 4215.0312 | L17: 0 | M17: 0 | N17: 0 | O17: 0 | P17: 0 | Q17: 0 | R17: =(J17+K17+L17+M17+Q17+N17+O17+P17)*$B$2 -> 4577.6944 | S17: TOTAL EXPENSE FOR THE MONTH | T17: ='ANNUAL-EXPENSE-DETAILS'!Y9 -> 0
A18: F13 | B18: =VLOOKUP(A18,Members!$A$2:$B$65,2,FALSE) -> Srinivasa Rao | C18: 2465 | D18: =SUM($C$3:$C$5)/64 -> 0 | E18: =C18+D18 -> 2465 | F18: =IF($C$70=0, 0, E18/$C$70) -> 0.0061395075 | G18: =F18*$T$5 -> 299.60797 | H18: 4 | I18: =$T$7*H18 -> 471.2448 | J18: =G18+$T$9+I18 -> 776.37517 | K18: =$T$4/64 -> 4215.0312 | L18: 0 | M18: 0 | N18: 0 | O18: 0 | P18: 0 | Q18: 0 | R18: =(J18+K18+L18+M18+Q18+N18+O18+P18)*$B$2 -> 4991.4064 | S18: Maintenance deficit | T18: =T16-T17 -> 0
A19: F14 | B19: =VLOOKUP(A19,Members!$A$2:$B$65,2,FALSE) -> Hemant Patel | C19: 492.5 | D19: =SUM($C$3:$C$5)/64 -> 0 | E19: =C19+D19 -> 492.5 | F19: =IF($C$70=0, 0, E19/$C$70) -> 0.0012266562 | G19: =F19*$T$5 -> 59.860821 | H19: 4 | I19: =$T$7*H19 -> 471.2448 | J19: =G19+$T$9+I19 -> 536.62802 | K19: =$T$4/64 -> 4215.0312 | L19: 0 | M19: 0 | N19: 0 | O19: 0 | P19: 0 | Q19: 0 | R19: =(J19+K19+L19+M19+Q19+N19+O19+P19)*$B$2 -> 4751.6593
A20: F15 | B20: =VLOOKUP(A20,Members!$A$2:$B$65,2,FALSE) -> Senthil.Vijayaragavan | C20: 3827 | D20: =SUM($C$3:$C$5)/64 -> 0 | E20: =C20+D20 -> 3827 | F20: =IF($C$70=0, 0, E20/$C$70) -> 0.0095318034 | G20: =F20*$T$5 -> 465.15201 | H20: 4 | I20: =$T$7*H20 -> 471.2448 | J20: =G20+$T$9+I20 -> 941.91921 | K20: =$T$4/64 -> 4215.0312 | L20: 750 | M20: 0 | N20: 0 | O20: 0 | P20: 0 | Q20: 0 | R20: =(J20+K20+L20+M20+Q20+N20+O20+P20)*$B$2 -> 5906.9505
A21: F16 | B21: =VLOOKUP(A21,Members!$A$2:$B$65,2,FALSE) -> Sreeja Sudharma | C21: 14264 | D21: =SUM($C$3:$C$5)/64 -> 0 | E21: =C21+D21 -> 14264 | F21: =IF($C$70=0, 0, E21/$C$70) -> 0.035526952 | G21: =F21*$T$5 -> 1733.7152 | H21: 3 | I21: =$T$7*H21 -> 353.4336 | J21: =G21+$T$9+I21 -> 2092.6712 | K21: =$T$4/64 -> 4215.0312 | L21: 0 | M21: 0 | N21: 0 | O21: 0 | P21: 0 | Q21: 0 | R21: =(J21+K21+L21+M21+Q21+N21+O21+P21)*$B$2 -> 6307.7025
A22: G1 | B22: =VLOOKUP(A22,Members!$A$2:$B$65,2,FALSE) -> Digvijay Verma | C22: 11858 | D22: =SUM($C$3:$C$5)/64 -> 0 | E22: =C22+D22 -> 11858 | F22: =IF($C$70=0, 0, E22/$C$70) -> 0.029534394 | G22: =F22*$T$5 -> 1441.2784 | H22: 3 | I22: =$T$7*H22 -> 353.4336 | J22: =G22+$T$9+I22 -> 1800.2344 | K22: =$T$4/64 -> 4215.0312 | L22: 0 | M22: 0 | N22: 0 | O22: 0 | P22: 0 | Q22: 0 | R22: =(J22+K22+L22+M22+Q22+N22+O22+P22)*$B$2 -> 6015.2657
A23: G2 | B23: =VLOOKUP(A23,Members!$A$2:$B$65,2,FALSE) -> Kaushik Kasibhatla | C23: 16175.5 | D23: =SUM($C$3:$C$5)/64 -> 0 | E23: =C23+D23 -> 16175.5 | F23: =IF($C$70=0, 0, E23/$C$70) -> 0.040287872 | G23: =F23*$T$5 -> 1966.0481 | H23: 4 | I23: =$T$7*H23 -> 471.2448 | J23: =G23+$T$9+I23 -> 2442.8153 | K23: =$T$4/64 -> 4215.0312 | L23: 0 | M23: 0 | N23: 0 | O23: 0 | P23: 0 | Q23: 0 | R23: =(J23+K23+L23+M23+Q23+N23+O23+P23)*$B$2 -> 6657.8466
A24: G3 | B24: =VLOOKUP(A24,Members!$A$2:$B$65,2,FALSE) -> Balakrishnan | C24: 11046.5 | D24: =SUM($C$3:$C$5)/64 -> 0 | E24: =C24+D24 -> 11046.5 | F24: =IF($C$70=0, 0, E24/$C$70) -> 0.027513213 | G24: =F24*$T$5 -> 1342.6448 | H24: 4 | I24: =$T$7*H24 -> 471.2448 | J24: =G24+$T$9+I24 -> 1819.412 | K24: =$T$4/64 -> 4215.0312 | L24: 0 | M24: 0 | N24: 0 | O24: 0 | P24: 0 | Q24: 0 | R24: =(J24+K24+L24+M24+Q24+N24+O24+P24)*$B$2 -> 6034.4432
A25: G4 | B25: =VLOOKUP(A25,Members!$A$2:$B$65,2,FALSE) -> Ashwin Pandith | C25: 19074 | D25: =SUM($C$3:$C$5)/64 -> 0 | E25: =C25+D25 -> 19074 | F25: =IF($C$70=0, 0, E25/$C$70) -> 0.047507086 | G25: =F25*$T$5 -> 2318.3458 | H25: 4 | I25: =$T$7*H25 -> 471.2448 | J25: =G25+$T$9+I25 -> 2795.113 | K25: =$T$4/64 -> 4215.0312 | L25: 0 | M25: 0 | N25: 0 | O25: 0 | P25: 0 | Q25: 0 | R25: =(J25+K25+L25+M25+Q25+N25+O25+P25)*$B$2 -> 7010.1442
A26: G5 | B26: =VLOOKUP(A26,Members!$A$2:$B$65,2,FALSE) -> Mayank Phophaliya | C26: 9713 | D26: =SUM($C$3:$C$5)/64 -> 0 | E26: =C26+D26 -> 9713 | F26: =IF($C$70=0, 0, E26/$C$70) -> 0.024191901 | G26: =F26*$T$5 -> 1180.5648 | H26: 3 | I26: =$T$7*H26 -> 353.4336 | J26: =G26+$T$9+I26 -> 1539.5208 | K26: =$T$4/64 -> 4215.0312 | L26: 0 | M26: 0 | N26: 0 | O26: 0 | P26: 0 | Q26: 0 | R26: =(J26+K26+L26+M26+Q26+N26+O26+P26)*$B$2 -> 5754.552
A27: G6 | B27: =VLOOKUP(A27,Members!$A$2:$B$65,2,FALSE) -> Srinath | C27: 6507.5 | D27: =SUM($C$3:$C$5)/64 -> 0 | E27: =C27+D27 -> 6507.5 | F27: =IF($C$70=0, 0, E27/$C$70) -> 0.016208051 | G27: =F27*$T$5 -> 790.95288 | H27: 3 | I27: =$T$7*H27 -> 353.4336 | J27: =G27+$T$9+I27 -> 1149.9089 | K27: =$T$4/64 -> 4215.0312 | L27: 0 | M27: 0 | N27: 0 | O27: 0 | P27: 0 | Q27: 0 | R27: =(J27+K27+L27+M27+Q27+N27+O27+P27)*$B$2 -> 5364.9401
A28: G7 | B28: =VLOOKUP(A28,Members!$A$2:$B$65,2,FALSE) -> Prince Richfield | C28: 1733.5 | D28: =SUM($C$3:$C$5)/64 -> 0 | E28: =C28+D28 -> 1733.5 | F28: =IF($C$70=0, 0, E28/$C$70) -> 0.0043175807 | G28: =F28*$T$5 -> 210.69794 | H28: 3 | I28: =$T$7*H28 -> 353.4336 | J28: =G28+$T$9+I28 -> 569.65394 | K28: =$T$4/64 -> 4215.0312 | L28: 0 | M28: 0 | N28: 0 | O28: 0 | P28: 0 | Q28: 0 | R28: =(J28+K28+L28+M28+Q28+N28+O28+P28)*$B$2 -> 4784.6852
A29: G8 | B29: =VLOOKUP(A29,Members!$A$2:$B$65,2,FALSE) -> Arun M | C29: 3464.5 | D29: =SUM($C$3:$C$5)/64 -> 0 | E29: =C29+D29 -> 3464.5 | F29: =IF($C$70=0, 0, E29/$C$70) -> 0.0086289346 | G29: =F29*$T$5 -> 421.09201 | H29: 3 | I29: =$T$7*H29 -> 353.4336 | J29: =G29+$T$9+I29 -> 780.04801 | K29: =$T$4/64 -> 4215.0312 | L29: 0 | M29: 0 | N29: 0 | O29: 0 | P29: 0 | Q29: 0 | R29: =(J29+K29+L29+M29+Q29+N29+O29+P29)*$B$2 -> 4995.0793
A30: G9 | B30: =VLOOKUP(A30,Members!$A$2:$B$65,2,FALSE) -> Chandramouli | C30: 8075.5 | D30: =SUM($C$3:$C$5)/64 -> 0 | E30: =C30+D30 -> 8075.5 | F30: =IF($C$70=0, 0, E30/$C$70) -> 0.020113425 | G30: =F30*$T$5 -> 981.53515 | H30: 5 | I30: =$T$7*H30 -> 589.056 | J30: =G30+$T$9+I30 -> 1576.1136 | K30: =$T$4/64 -> 4215.0312 | L30: 0 | M30: 0 | N30: 0 | O30: 0 | P30: 0 | Q30: 0 | R30: =(J30+K30+L30+M30+Q30+N30+O30+P30)*$B$2 -> 5791.1448
... A69: T16 | B69: =VLOOKUP(A69,Members!$A$2:$B$65,2,FALSE) -> Madhusoodanan P.R. | C69: 10490.5 | D69: =SUM($C$3:$C$5)/64 -> 0 | E69: =C69+D69 -> 10490.5 | F69: =IF($C$70=0, 0, E69/$C$70) -> 0.026128399 | G69: =F69*$T$5 -> 1275.0659 | H69: 3 | I69: =$T$7*H69 -> 353.4336 | J69: =G69+$T$9+I69 -> 1634.0219 | K69: =$T$4/64 -> 4215.0312 | L69: 0 | M69: 0 | N69: 0 | O69: 0 | P69: 0 | Q69: 0 | R69: =(J69+K69+L69+M69+Q69+N69+O69+P69)*$B$2 -> 5849.0531
A70: TOTAL | C70: =SUM(C3:C69) -> 401498 | D70: =SUM(D3:D69) -> 0 | E70: =SUM(E5:E69) -> 401498 | F70: =SUM(F6:F69) -> 1 | G70: =SUM(G6:G69) -> 48800 | H70: =SUM(H3:H69) -> 223 | I70: =SUM(I3:I69) -> 26271.898 | J70: =SUM(J6:J69) -> 75071.898 | K70: =SUM(K6:K69) -> 269762 | L70: =SUM(L6:L69) -> 3000 | M70: =SUM(M6:M69) -> 0 | N70: =SUM(N6:N69) -> 0 | O70: =SUM(O6:O69) -> 0 | P70: =SUM(P6:P69) -> 0 | Q70: =SUM(Q6:Q69) -> 0 | R70: =SUM(R6:R69) -> 347833.9

Sheet Apr2026-COLLECTION
A1: FLAT # | C1: Amount | D1: Date | E1: Amount | F1: Date | G1: Amount | H1: Date | I1: Amount | J1: Date | K1: Total
A2: F1 | B2: =VLOOKUP(A2,Members!$A$2:$B$65,2,FALSE) -> Shailesh Srivastava | C2: 9230 | D2: 13 Apr 2026 | K2: =SUM(C2,E2,G2,I2) -> 9230
A3: F2 | B3: =VLOOKUP(A3,Members!$A$2:$B$65,2,FALSE) -> Rama P | K3: =SUM(C3,E3,G3,I3) -> 0
A4: F3 | B4: =VLOOKUP(A4,Members!$A$2:$B$65,2,FALSE) -> Samrat Kar | C4: 6000 | D4: 1 Apr 2026 | K4: =SUM(C4,E4,G4,I4) -> 6000
A5: F4 | B5: =VLOOKUP(A5,Members!$A$2:$B$65,2,FALSE) -> Renu R | C5: 5549 | D5: 9 Apr 2026 | E5: 440 | F5: 9 Apr 2026 | K5: =SUM(C5,E5,G5,I5) -> 5989
A6: F5 | B6: =VLOOKUP(A6,Members!$A$2:$B$65,2,FALSE) -> Vamsidhar Bethanabatla | K6: =SUM(C6,E6,G6,I6) -> 0
A7: F6 | B7: =VLOOKUP(A7,Members!$A$2:$B$65,2,FALSE) -> Viral Shah | C7: 4867.34 | D7: 3 Apr 2026 | K7: =SUM(C7,E7,G7,I7) -> 4867.34
A8: F7 | B8: =VLOOKUP(A8,Members!$A$2:$B$65,2,FALSE) -> Vimal NK | C8: 5384 | D8: 28 Apr 2026 | K8: =SUM(C8,E8,G8,I8) -> 5384
A9: F8 | B9: =VLOOKUP(A9,Members!$A$2:$B$65,2,FALSE) -> Ruhi Agrawal | C9: 6070 | D9: 19 Apr 2026 | K9: =SUM(C9,E9,G9,I9) -> 6070
A10: F9 | B10: =VLOOKUP(A10,Members!$A$2:$B$65,2,FALSE) -> Vijay Suswaram | K10: =SUM(C10,E10,G10,I10) -> 0
A11: F10 | B11: =VLOOKUP(A11,Members!$A$2:$B$65,2,FALSE) -> Aby Thomas | C11: 27822 | D11: 19 Apr 2026 | K11: =SUM(C11,E11,G11,I11) -> 27822
A12: F11 | B12: =VLOOKUP(A12,Members!$A$2:$B$65,2,FALSE) -> Renu R | C12: 5549 | D12: 9 Apr 2026 | K12: =SUM(C12,E12,G12,I12) -> 5549
A13: F12 | B13: =VLOOKUP(A13,Members!$A$2:$B$65,2,FALSE) -> Kavitha T | E13: 5959 | F13: 19 Apr 2026 | K13: =SUM(C13,E13,G13,I13) -> 5959
A14: F13 | B14: =VLOOKUP(A14,Members!$A$2:$B$65,2,FALSE) -> Srinivasa Rao | C14: 4934 | D14: 22 Apr 2026 | K14: =SUM(C14,E14,G14,I14) -> 4934
A15: F14 | B15: =VLOOKUP(A15,Members!$A$2:$B$65,2,FALSE) -> Hemant Patel | C15: 7000 | D15: 4 Apr 2026 | K15: =SUM(C15,E15,G15,I15) -> 7000
A16: F15 | B16: =VLOOKUP(A16,Members!$A$2:$B$65,2,FALSE) -> Senthil.Vijayaragavan | C16: 5764 | D16: 29 Apr 2026 | K16: =SUM(C16,E16,G16,I16) -> 5764
A17: F16 | B17: =VLOOKUP(A17,Members!$A$2:$B$65,2,FALSE) -> Sreeja Sudharma | C17: 5903.12 | D17: 4 Apr 2026 | E17: 20000 | F17: 16 Apr 2026 | K17: =SUM(C17,E17,G17,I17) -> 25903.12
A18: G1 | B18: =VLOOKUP(A18,Members!$A$2:$B$65,2,FALSE) -> Digvijay Verma | K18: =SUM(C18,E18,G18,I18) -> 0
A19: G2 | B19: =VLOOKUP(A19,Members!$A$2:$B$65,2,FALSE) -> Kaushik Kasibhatla | C19: 6121 | D19: 22 Apr 2026 | K19: =SUM(C19,E19,G19,I19) -> 6121
A20: G3 | B20: =VLOOKUP(A20,Members!$A$2:$B$65,2,FALSE) -> Balakrishnan | C20: 5796 | D20: 25 Apr 2026 | K20: =SUM(C20,E20,G20,I20) -> 5796
A21: G4 | B21: =VLOOKUP(A21,Members!$A$2:$B$65,2,FALSE) -> Ashwin Pandith | C21: 5604 | D21: 21 Apr 2026 | K21: =SUM(C21,E21,G21,I21) -> 5604
A22: G5 | B22: =VLOOKUP(A22,Members!$A$2:$B$65,2,FALSE) -> Mayank Phophaliya | K22: =SUM(C22,E22,G22,I22) -> 0
A23: G6 | B23: =VLOOKUP(A23,Members!$A$2:$B$65,2,FALSE) -> Srinath | C23: 5260 | D23: 12 Apr 2026 | K23: =SUM(C23,E23,G23,I23) -> 5260
A24: G7 | B24: =VLOOKUP(A24,Members!$A$2:$B$65,2,FALSE) -> Prince Richfield | C24: 10621 | D24: 20 Apr 2026 | K24: =SUM(C24,E24,G24,I24) -> 10621
A25: G8 | B25: =VLOOKUP(A25,Members!$A$2:$B$65,2,FALSE) -> Arun M | C25: 495.94 | D25: 8 Apr 2026 | K25: =SUM(C25,E25,G25,I25) -> 495.94
A26: G9 | B26: =VLOOKUP(A26,Members!$A$2:$B$65,2,FALSE) -> Chandramouli | C26: 5590 | D26: 26 Apr 2026 | K26: =SUM(C26,E26,G26,I26) -> 5590
A27: G10 | B27: =VLOOKUP(A27,Members!$A$2:$B$65,2,FALSE) -> Richa Singh | K27: =SUM(C27,E27,G27,I27) -> 0
A28: G11 | B28: =VLOOKUP(A28,Members!$A$2:$B$65,2,FALSE) -> Prashant Jaitley | C28: 16648 | D28: 5 Apr 2026 | E28: 4928 | F28: 19 Apr 2026 | K28: =SUM(C28,E28,G28,I28) -> 21576
A29: G12 | B29: =VLOOKUP(A29,Members!$A$2:$B$65,2,FALSE) -> Shyam Nair | C29: 4487 | D29: 19 Apr 2026 | K29: =SUM(C29,E29,G29,I29) -> 4487
A30: G13 | B30: =VLOOKUP(A30,Members!$A$2:$B$65,2,FALSE) -> Ajai.B | C30: 10677 | D30: 4 Apr 2026 | K30: =SUM(C30,E30,G30,I30) -> 10677
A31: G14 | B31: =VLOOKUP(A31,Members!$A$2:$B$65,2,FALSE) -> Surajit Borah | C31: 5970 | D31: 19 Apr 2026 | K31: =SUM(C31,E31,G31,I31) -> 5970
A32: G15 | B32: =VLOOKUP(A32,Members!$A$2:$B$65,2,FALSE) -> Suresh Nallusamy | K32: =SUM(C32,E32,G32,I32) -> 0
A33: G16 | B33: =VLOOKUP(A33,Members!$A$2:$B$65,2,FALSE) -> Praveen Ganesan | C33: 4819 | D33: 26 Apr 2026 | K33: =SUM(C33,E33,G33,I33) -> 4819
A34: S1 | B34: =VLOOKUP(A34,Members!$A$2:$B$65,2,FALSE) -> S.N.Behera | C34: 4890 | D34: 25 Apr 2026 | K34: =SUM(C34,E34,G34,I34) -> 4890
A35: S2 | B35: =VLOOKUP(A35,Members!$A$2:$B$65,2,FALSE) -> Sonal Singh | C35: 5635 | D35: 1 Apr 2026 | K35: =SUM(C35,E35,G35,I35) -> 5635
A36: S3 | B36: =VLOOKUP(A36,Members!$A$2:$B$65,2,FALSE) -> Manikandan N | C36: 5092 | D36: 29 Apr 2026 | K36: =SUM(C36,E36,G36,I36) -> 5092
A37: S4 | B37: =VLOOKUP(A37,Members!$A$2:$B$65,2,FALSE) -> Swami | K37: =SUM(C37,E37,G37,I37) -> 0
A38: S5 | B38: =VLOOKUP(A38,Members!$A$2:$B$65,2,FALSE) -> Abhishek Gopalakrishnan | C38: 28414.74 | D38: 4 Apr 2026 | E38: 4935 | F38: 19 Apr 2026 | G38: 1000 | H38: 28 Apr 2026 | K38: =SUM(C38,E38,G38,I38) -> 34349.74
A39: S6 | B39: =VLOOKUP(A39,Members!$A$2:$B$65,2,FALSE) -> Vivek Dhingra | C39: 35878 | D39: 5 Apr 2026 | E39: 4903 | F39: 22 Apr 2026 | K39: =SUM(C39,E39,G39,I39) -> 40781
A40: S7 | B40: =VLOOKUP(A40,Members!$A$2:$B$65,2,FALSE) -> Harish B | C40: 4936 | D40: 24 Apr 2026 | K40: =SUM(C40,E40,G40,I40) -> 4936
...

Sheet May2026-EXPENSE
A1: 1 | B1: MAY 2026 EXPENSES
A2: FLAT # | B2: 1 | C2: WATER USED IN LTRS | D2: COMMON AREA EQUALLY DEVIDED | E2: TOTAL FRESH WATER CONSUMED | F2: %OF TOTAL USED | G2: WATER EXPENSE SHARING BY % | H2: #METERS | I2: METER RENT | J2: VARIABLE EXPENSE = COMMON AREA METER RENT + WATER EXPENSE+ FLAT METER RENT | K2: FIXED EXPENSE SHARE | L2: PARKING FEE | M2: CLUB HOUSE BOOKING | N2: SHIFTING FEE | O2: GYM USAGE FEE | P2: ANNUAL MEMBERSHIP FEE | R2: TOTAL EXPENSE TO BE PAID
A3: CH | B3: MPFOWA | C3: 0 | D3: 0 | H3: 1 | I3: =T7 -> 123.6994
A4: GYM | B4: MPFOWA | C4: 0 | D4: 0 | H4: 1 | I4: =T7 -> 123.6994 | S4: TOTAL FIXED EXPENSE | T4: ='ANNUAL-EXPENSE-DETAILS'!V4 -> 281008
A5: BSMT | B5: MPFOWA | C5: 0 | D5: 0 | H5: 1 | I5: =T7 -> 123.6994 | S5: TOTAL WATER EXPENSE | T5: ='ANNUAL-EXPENSE-DETAILS'!U4 -> 42100
A6: F1 | B6: =VLOOKUP(A6,Members!$A$2:$B$65,2,FALSE) -> Shailesh Srivastava | C6: 3678 | D6: =SUM($C$3:$C$5)/64 -> 0 | E6: =C6+D6 -> 3678 | F6: =IF($C$70=0, 0, E6/$C$70) -> 0.0064623024 | G6: =F6*$T$5 -> 272.06293 | H6: 3 | I6: =$T$7*H6 -> 371.0982 | J6: =G6+$T$9+I6 -> 648.95954 | K6: =$T$4/64 -> 4390.75 | L6: 0 | M6: 0 | N6: 0 | O6: 0 | P6: 500 | R6: =(SUM(J6:P6)*$B$2) -> 5539.7095
A7: F2 | B7: =VLOOKUP(A7,Members!$A$2:$B$65,2,FALSE) -> Rama P | C7: 9240 | D7: =SUM($C$3:$C$5)/64 -> 0 | E7: =C7+D7 -> 9240 | F7: =IF($C$70=0, 0, E7/$C$70) -> 0.016234822 | G7: =F7*$T$5 -> 683.48599 | H7: 4 | I7: =$T$7*H7 -> 494.7976 | J7: =G7+$T$9+I7 -> 1184.082 | K7: =$T$4/64 -> 4390.75 | L7: 0 | M7: 0 | N7: 0 | O7: 0 | P7: 500 | R7: =(SUM(J7:P7)*$B$2) -> 6074.832 | S7: RENT PER METER | T7: =(104.83+0.18*104.83) -> 123.6994
A8: F3 | B8: =VLOOKUP(A8,Members!$A$2:$B$65,2,FALSE) -> Samrat Kar | C8: 8604 | D8: =SUM($C$3:$C$5)/64 -> 0 | E8: =C8+D8 -> 8604 | F8: =IF($C$70=0, 0, E8/$C$70) -> 0.01511736 | G8: =F8*$T$5 -> 636.44085 | H8: 4 | I8: =$T$7*H8 -> 494.7976 | J8: =G8+$T$9+I8 -> 1137.0369 | K8: =$T$4/64 -> 4390.75 | L8: 750 | M8: 0 | N8: 0 | O8: 0 | P8: 500 | R8: =(SUM(J8:P8)*$B$2) -> 6777.7869 | S8: COMMON AREA METER RENT | T8: =$T$7*3 -> 371.0982
A9: F4 | B9: =VLOOKUP(A9,Members!$A$2:$B$65,2,FALSE) -> Renu R | C9: 4846.5 | D9: =SUM($C$3:$C$5)/64 -> 0 | E9: =C9+D9 -> 4846.5 | F9: =IF($C$70=0, 0, E9/$C$70) -> 0.0085153748 | G9: =F9*$T$5 -> 358.49728 | H9: 4 | I9: =$T$7*H9 -> 494.7976 | J9: =G9+$T$9+I9 -> 859.09329 | K9: =$T$4/64 -> 4390.75 | L9: 0 | M9: 0 | N9: 0 | O9: 0 | P9: 500 | R9: =(SUM(J9:P9)*$B$2) -> 5749.8433 | S9: COMMON AREA METER RENT/FLAT | T9: =T8/64 -> 5.7984094
A10: F5 | B10: =VLOOKUP(A10,Members!$A$2:$B$65,2,FALSE) -> Vamsidhar Bethanabatla | C10: 3884.5 | D10: =SUM($C$3:$C$5)/64 -> 0 | E10: =C10+D10 -> 3884.5 | F10: =IF($C$70=0, 0, E10/$C$70) -> 0.006825126 | G10: =F10*$T$5 -> 287.33781 | H10: 3 | I10: =$T$7*H10 -> 371.0982 | J10: =G10+$T$9+I10 -> 664.23441 | K10: =$T$4/64 -> 4390.75 | L10: 0 | M10: 0 | N10: 0 | O10: 0 | P10: 500 | R10: =(SUM(J10:P10)*$B$2) -> 5554.9844
A11: F6 | B11: =VLOOKUP(A11,Members!$A$2:$B$65,2,FALSE) -> Viral Shah | C11: 7004.5 | D11: =SUM($C$3:$C$5)/64 -> 0 | E11: =C11+D11 -> 7004.5 | F11: =IF($C$70=0, 0, E11/$C$70) -> 0.012307014 | G11: =F11*$T$5 -> 518.12528 | H11: 3 | I11: =$T$7*H11 -> 371.0982 | J11: =G11+$T$9+I11 -> 895.02189 | K11: =$T$4/64 -> 4390.75 | L11: 0 | M11: 0 | N11: 0 | O11: 0 | P11: 500 | R11: =(SUM(J11:P11)*$B$2) -> 5785.7719
A12: F7 | B12: =VLOOKUP(A12,Members!$A$2:$B$65,2,FALSE) -> Vimal NK | C12: 4 | D12: =SUM($C$3:$C$5)/64 -> 0 | E12: =C12+D12 -> 4 | F12: =IF($C$70=0, 0, E12/$C$70) -> 7.0280613e-06 | G12: =F12*$T$5 -> 0.29588138 | H12: 3 | I12: =$T$7*H12 -> 371.0982 | J12: =G12+$T$9+I12 -> 377.19249 | K12: =$T$4/64 -> 4390.75 | L12: 750 | M12: 0 | N12: 0 | O12: 0 | P12: 500 | R12: =(SUM(J12:P12)*$B$2) -> 6017.9425
A13: F8 | B13: =VLOOKUP(A13,Members!$A$2:$B$65,2,FALSE) -> Ruhi Agrawal | C13: 886.5 | D13: =SUM($C$3:$C$5)/64 -> 0 | E13: =C13+D13 -> 886.5 | F13: =IF($C$70=0, 0, E13/$C$70) -> 0.0015575941 | G13: =F13*$T$5 -> 65.574711 | H13: 3 | I13: =$T$7*H13 -> 371.0982 | J13: =G13+$T$9+I13 -> 442.47132 | K13: =$T$4/64 -> 4390.75 | L13: 0 | M13: 0 | N13: 0 | O13: 0 | P13: 500 | R13: =(SUM(J13:P13)*$B$2) -> 5333.2213
A14: F9 | B14: =VLOOKUP(A14,Members!$A$2:$B$65,2,FALSE) -> Vijay Suswaram | C14: 1981 | D14: =SUM($C$3:$C$5)/64 -> 0 | E14: =C14+D14 -> 1981 | F14: =IF($C$70=0, 0, E14/$C$70) -> 0.0034806474 | G14: =F14*$T$5 -> 146.53525 | H14: 4 | I14: =$T$7*H14 -> 494.7976 | J14: =G14+$T$9+I14 -> 647.13126 | K14: =$T$4/64 -> 4390.75 | L14: 0 | M14: 0 | N14: 0 | O14: 0 | P14: 500 | R14: =(SUM(J14:P14)*$B$2) -> 5537.8813
A15: F10 | B15: =VLOOKUP(A15,Members!$A$2:$B$65,2,FALSE) -> Aby Thomas | C15: 11864.5 | D15: =SUM($C$3:$C$5)/64 -> 0 | E15: =C15+D15 -> 11864.5 | F15: =IF($C$70=0, 0, E15/$C$70) -> 0.020846108 | G15: =F15*$T$5 -> 877.62116 | H15: 3 | I15: =$T$7*H15 -> 371.0982 | J15: =G15+$T$9+I15 -> 1254.5178 | K15: =$T$4/64 -> 4390.75 | L15: 0 | M15: 0 | N15: 0 | O15: 0 | P15: 500 | R15: =(SUM(J15:P15)*$B$2) -> 6145.2678
A16: F11 | B16: =VLOOKUP(A16,Members!$A$2:$B$65,2,FALSE) -> Renu R | C16: 925.5 | D16: =SUM($C$3:$C$5)/64 -> 0 | E16: =C16+D16 -> 925.5 | F16: =IF($C$70=0, 0, E16/$C$70) -> 0.0016261177 | G16: =F16*$T$5 -> 68.459554 | H16: 3 | I16: =$T$7*H16 -> 371.0982 | J16: =G16+$T$9+I16 -> 445.35616 | K16: =$T$4/64 -> 4390.75 | L16: 0 | M16: 0 | N16: 0 | O16: 0 | P16: 500 | R16: =(SUM(J16:P16)*$B$2) -> 5336.1062
A17: F12 | B17: =VLOOKUP(A17,Members!$A$2:$B$65,2,FALSE) -> Kavitha T | C17: 7188.5 | D17: =SUM($C$3:$C$5)/64 -> 0 | E17: =C17+D17 -> 7188.5 | F17: =IF($C$70=0, 0, E17/$C$70) -> 0.012630305 | G17: =F17*$T$5 -> 531.73583 | H17: 3 | I17: =$T$7*H17 -> 371.0982 | J17: =G17+$T$9+I17 -> 908.63244 | K17: =$T$4/64 -> 4390.75 | L17: 0 | M17: 0 | N17: 0 | O17: 0 | P17: 500 | R17: =(SUM(J17:P17)*$B$2) -> 5799.3824
A18: F13 | B18: =VLOOKUP(A18,Members!$A$2:$B$65,2,FALSE) -> Srinivasa Rao | C18: 1784.5 | D18: =SUM($C$3:$C$5)/64 -> 0 | E18: =C18+D18 -> 1784.5 | F18: =IF($C$70=0, 0, E18/$C$70) -> 0.0031353938 | G18: =F18*$T$5 -> 132.00008 | H18: 4 | I18: =$T$7*H18 -> 494.7976 | J18: =G18+$T$9+I18 -> 632.59609 | K18: =$T$4/64 -> 4390.75 | L18: 0 | M18: 0 | N18: 0 | O18: 0 | P18: 500 | R18: =(SUM(J18:P18)*$B$2) -> 5523.3461
A19: F14 | B19: =VLOOKUP(A19,Members!$A$2:$B$65,2,FALSE) -> Hemant Patel | C19: 5166.5 | D19: =SUM($C$3:$C$5)/64 -> 0 | E19: =C19+D19 -> 5166.5 | F19: =IF($C$70=0, 0, E19/$C$70) -> 0.0090776197 | G19: =F19*$T$5 -> 382.16779 | H19: 4 | I19: =$T$7*H19 -> 494.7976 | J19: =G19+$T$9+I19 -> 882.7638 | K19: =$T$4/64 -> 4390.75 | L19: 0 | M19: 0 | N19: 0 | O19: 0 | P19: 500 | R19: =(SUM(J19:P19)*$B$2) -> 5773.5138
A20: F15 | B20: =VLOOKUP(A20,Members!$A$2:$B$65,2,FALSE) -> Senthil.Vijayaragavan | C20: 4994.5 | D20: =SUM($C$3:$C$5)/64 -> 0 | E20: =C20+D20 -> 4994.5 | F20: =IF($C$70=0, 0, E20/$C$70) -> 0.008775413 | G20: =F20*$T$5 -> 369.44489 | H20: 4 | I20: =$T$7*H20 -> 494.7976 | J20: =G20+$T$9+I20 -> 870.0409 | K20: =$T$4/64 -> 4390.75 | L20: 750 | M20: 0 | N20: 0 | O20: 0 | P20: 500 | R20: =(SUM(J20:P20)*$B$2) -> 6510.7909
A21: F16 | B21: =VLOOKUP(A21,Members!$A$2:$B$65,2,FALSE) -> Sreeja Sudharma | C21: 15096.5 | D21: =SUM($C$3:$C$5)/64 -> 0 | E21: =C21+D21 -> 15096.5 | F21: =IF($C$70=0, 0, E21/$C$70) -> 0.026524782 | G21: =F21*$T$5 -> 1116.6933 | H21: 3 | I21: =$T$7*H21 -> 371.0982 | J21: =G21+$T$9+I21 -> 1493.5899 | K21: =$T$4/64 -> 4390.75 | L21: 0 | M21: 0 | N21: 0 | O21: 0 | P21: 500 | R21: =(SUM(J21:P21)*$B$2) -> 6384.3399
... A69: T16 | B69: =VLOOKUP(A69,Members!$A$2:$B$65,2,FALSE) -> Madhusoodanan P.R. | C69: 12278.5 | D69: =SUM($C$3:$C$5)/64 -> 0 | E69: =C69+D69 -> 12278.5 | F69: =IF($C$70=0, 0, E69/$C$70) -> 0.021573513 | G69: =F69*$T$5 -> 908.24488 | H69: 3 | I69: =$T$7*H69 -> 371.0982 | J69: =G69+$T$9+I69 -> 1285.1415 | K69: =$T$4/64 -> 4390.75 | L69: 0 | M69: 0 | N69: 0 | O69: 0 | P69: 500 | R69: =(SUM(J69:P69)*$B$2) -> 6175.8915
A70: TOTAL | B70: TOTAL | C70: =SUM(C3:C69) -> 569147 | D70: =SUM(D3:D69) -> 0 | E70: =SUM(E5:E69) -> 569147 | F70: =SUM(F6:F69) -> 1 | G70: =SUM(G6:G69) -> 42100 | H70: =SUM(H3:H69) -> 223 | I70: =SUM(I3:I69) -> 27584.966 | J70: =SUM(J6:J69) -> 69684.966 | K70: =SUM(K6:K69) -> 281008 | L70: =SUM(L3:L69) -> 3000 | M70: =SUM(M3:M69) -> 0 | N70: =SUM(N3:N69) -> 0 | O70: =SUM(O3:O69) -> 0 | P70: =SUM(P3:P69) -> 32000 | R70: =SUM(R3:R69) -> 385692.97

Sheet May2026-COLLECTION
A1: FLAT # | C1: Amount | D1: Date | E1: Amount | F1: Date | G1: Amount | H1: Date | I1: Amount | J1: Date | K1: Total
A2: F1 | B2: =VLOOKUP(A2,Members!$A$2:$B$65,2,FALSE) -> Shailesh Srivastava | K2: =SUM(C2,E2,G2,I2) -> 0
A3: F2 | B3: =VLOOKUP(A3,Members!$A$2:$B$65,2,FALSE) -> Rama P | K3: =SUM(C3,E3,G3,I3) -> 0
A4: F3 | B4: =VLOOKUP(A4,Members!$A$2:$B$65,2,FALSE) -> Samrat Kar | C4: 6000 | D4: 1-May-26 | K4: =SUM(C4,E4,G4,I4) -> 6000
A5: F4 | B5: =VLOOKUP(A5,Members!$A$2:$B$65,2,FALSE) -> Renu R | K5: =SUM(C5,E5,G5,I5) -> 0
A6: F5 | B6: =VLOOKUP(A6,Members!$A$2:$B$65,2,FALSE) -> Vamsidhar Bethanabatla | C6: 4827 | D6: 10-May-26 | E6: 205 | F6: 15-May-26 | G6: 205 | H6: 15-May-26 | K6: =SUM(C6,E6,G6,I6) -> 5237
A7: F6 | B7: =VLOOKUP(A7,Members!$A$2:$B$65,2,FALSE) -> Viral Shah | C7: 9442.71 | D7: 2-May-26 | K7: =SUM(C7,E7,G7,I7) -> 9442.71
A8: F7 | B8: =VLOOKUP(A8,Members!$A$2:$B$65,2,FALSE) -> Vimal NK | C8: 7174 | D8: 24-May-26 | K8: =SUM(C8,E8,G8,I8) -> 7174
A9: F8 | B9: =VLOOKUP(A9,Members!$A$2:$B$65,2,FALSE) -> Ruhi Agrawal | C9: 453 | D9: 10-May-26 | E9: 468 | F9: 15-May-26 | K9: =SUM(C9,E9,G9,I9) -> 921
A10: F9 | B10: =VLOOKUP(A10,Members!$A$2:$B$65,2,FALSE) -> Vijay Suswaram | C10: 4867 | D10: 1-May-26 | E10: 5366 | F10: 16-May-26 | K10: =SUM(C10,E10,G10,I10) -> 10233
A11: F10 | B11: =VLOOKUP(A11,Members!$A$2:$B$65,2,FALSE) -> Aby Thomas | K11: =SUM(C11,E11,G11,I11) -> 0
A12: F11 | B12: =VLOOKUP(A12,Members!$A$2:$B$65,2,FALSE) -> Renu R | K12: =SUM(C12,E12,G12,I12) -> 0
A13: F12 | B13: =VLOOKUP(A13,Members!$A$2:$B$65,2,FALSE) -> Kavitha T | C13: 6536.41 | D13: 10-May-26 | K13: =SUM(C13,E13,G13,I13) -> 6536.41
A14: F13 | B14: =VLOOKUP(A14,Members!$A$2:$B$65,2,FALSE) -> Srinivasa Rao | K14: =SUM(C14,E14,G14,I14) -> 0
A15: F14 | B15: =VLOOKUP(A15,Members!$A$2:$B$65,2,FALSE) -> Hemant Patel | K15: =SUM(C15,E15,G15,I15) -> 0
A16: F15 | B16: =VLOOKUP(A16,Members!$A$2:$B$65,2,FALSE) -> Senthil.Vijayaragavan | C16: 5907 | D16: 25-May-26 | K16: =SUM(C16,E16,G16,I16) -> 5907
A17: F16 | B17: =VLOOKUP(A17,Members!$A$2:$B$65,2,FALSE) -> Sreeja Sudharma | C17: 5887.24 | D17: 11-May-26 | K17: =SUM(C17,E17,G17,I17) -> 5887.24
A18: G1 | B18: =VLOOKUP(A18,Members!$A$2:$B$65,2,FALSE) -> Digvijay Verma | K18: =SUM(C18,E18,G18,I18) -> 0
A19: G2 | B19: =VLOOKUP(A19,Members!$A$2:$B$65,2,FALSE) -> Kaushik Kasibhatla | K19: =SUM(C19,E19,G19,I19) -> 0
A20: G3 | B20: =VLOOKUP(A20,Members!$A$2:$B$65,2,FALSE) -> Balakrishnan | C20: 2100 | D20: 26-May-26 | K20: =SUM(C20,E20,G20,I20) -> 2100
A21: G4 | B21: =VLOOKUP(A21,Members!$A$2:$B$65,2,FALSE) -> Ashwin Pandith | C21: 11592 | D21: 10-May-26 | K21: =SUM(C21,E21,G21,I21) -> 11592
A22: G5 | B22: =VLOOKUP(A22,Members!$A$2:$B$65,2,FALSE) -> Mayank Phophaliya | K22: =SUM(C22,E22,G22,I22) -> 0
A23: G6 | B23: =VLOOKUP(A23,Members!$A$2:$B$65,2,FALSE) -> Srinath | K23: =SUM(C23,E23,G23,I23) -> 0
A24: G7 | B24: =VLOOKUP(A24,Members!$A$2:$B$65,2,FALSE) -> Prince Richfield | K24: =SUM(C24,E24,G24,I24) -> 0
A25: G8 | B25: =VLOOKUP(A25,Members!$A$2:$B$65,2,FALSE) -> Arun M | C25: 5067 | D25: 5-May-26 | E25: 3879.31 | F25: 13-May-26 | K25: =SUM(C25,E25,G25,I25) -> 8946.31
A26: G9 | B26: =VLOOKUP(A26,Members!$A$2:$B$65,2,FALSE) -> Chandramouli | K26: =SUM(C26,E26,G26,I26) -> 0
A27: G10 | B27: =VLOOKUP(A27,Members!$A$2:$B$65,2,FALSE) -> Richa Singh | C27: 4440 | D27: 23-May-26 | K27: =SUM(C27,E27,G27,I27) -> 4440
A28: G11 | B28: =VLOOKUP(A28,Members!$A$2:$B$65,2,FALSE) -> Prashant Jaitley | K28: =SUM(C28,E28,G28,I28) -> 0
A29: G12 | B29: =VLOOKUP(A29,Members!$A$2:$B$65,2,FALSE) -> Shyam Nair | C29: 6335 | D29: 12-May-26 | K29: =SUM(C29,E29,G29,I29) -> 6335
A30: G13 | B30: =VLOOKUP(A30,Members!$A$2:$B$65,2,FALSE) -> Ajai.B | K30: =SUM(C30,E30,G30,I30) -> 0
A31: G14 | B31: =VLOOKUP(A31,Members!$A$2:$B$65,2,FALSE) -> Surajit Borah | C31: 6116.55 | D31: 21-May-26 | K31: =SUM(C31,E31,G31,I31) -> 6116.55
A32: G15 | B32: =VLOOKUP(A32,Members!$A$2:$B$65,2,FALSE) -> Suresh Nallusamy | K32: =SUM(C32,E32,G32,I32) -> 0
A33: G16 | B33: =VLOOKUP(A33,Members!$A$2:$B$65,2,FALSE) -> Praveen Ganesan | K33: =SUM(C33,E33,G33,I33) -> 0
A34: S1 | B34: =VLOOKUP(A34,Members!$A$2:$B$65,2,FALSE) -> S.N.Behera | C34: 4556.92 | D34: 17-May-26 | K34: =SUM(C34,E34,G34,I34) -> 4556.92
A35: S2 | B35: =VLOOKUP(A35,Members!$A$2:$B$65,2,FALSE) -> Sonal Singh | C35: 6948 | D35: 1-May-26 | K35: =SUM(C35,E35,G35,I35) -> 6948
A36: S3 | B36: =VLOOKUP(A36,Members!$A$2:$B$65,2,FALSE) -> Manikandan N | K36: =SUM(C36,E36,G36,I36) -> 0
A37: S4 | B37: =VLOOKUP(A37,Members!$A$2:$B$65,2,FALSE) -> Swami | C37: 6000 | D37: 10-May-26 | E37: 5000 | F37: 30-May-26 | K37: =SUM(C37,E37,G37,I37) -> 11000
A38: S5 | B38: =VLOOKUP(A38,Members!$A$2:$B$65,2,FALSE) -> Abhishek Gopalakrishnan | C38: 4363.79 | D38: 12-May-26 | K38: =SUM(C38,E38,G38,I38) -> 4363.79
A39: S6 | B39: =VLOOKUP(A39,Members!$A$2:$B$65,2,FALSE) -> Vivek Dhingra | K39: =SUM(C39,E39,G39,I39) -> 0
A40: S7 | B40: =VLOOKUP(A40,Members!$A$2:$B$65,2,FALSE) -> Harish B | C40: 5067.7 | D40: 23-May-26 | K40: =SUM(C40,E40,G40,I40) -> 5067.7
...

Sheet June2026-EXPENSE
B1: JUN 2026 EXPENSES
A2: FLAT # | B2: 0 | C2: WATER USED IN LTRS (L) | D2: COMMON AREA EQUALLY DEVIDED | E2: TOTAL FRESH WATER CONSUMED | F2: %OF TOTAL USED | G2: WATER EXPENSE SHARING BY % | H2: #METERS | I2: METER RENT | J2: VARIABLE EXPENSE = COMMON AREA METER RENT + WATER EXPENSE+ FLAT METER RENT | K2: FIXED EXPENSE SHARE | L2: PARKING FEE | M2: CLUB BOOKING FEE | N2: POLYCARBONATE PROJECT CANCELLATION CREDIT AMOUNT | O2: SHIFTING FEE | P2: GYM USAGE FEE | R2: TOTAL EXPENSE TO BE PAID
A3: CH | B3: MPFOWA | C3: 0 | D3: 0 | H3: 1 | I3: =H3*$T$7 -> 117.81166
A4: GYM | B4: MPFOWA | C4: 0 | D4: 0 | H4: 1 | I4: =H4*$T$7 -> 117.81166 | S4: TOTAL FIXED EXPENSE | T4: ='ANNUAL-EXPENSE-DETAILS'!V5 -> 0
A5: BSMT | B5: MPFOWA | C5: 0 | D5: 0 | H5: 1 | I5: =H5*$T$7 -> 117.81166 | S5: TOTAL WATER EXPENSE | T5: ='ANNUAL-EXPENSE-DETAILS'!U5 -> 0
A6: F1 | B6: =VLOOKUP(A6,Members!$A$2:$B$65,2,FALSE) -> Shailesh Srivastava | C6: 0 | D6: =SUM($C$3:$C$5)/64 -> 0 | E6: =C6+D6 -> 0 | F6: =IF($C$70=0, 0, E6/$C$70) -> 0 | G6: =F6*$T$5 -> 0 | H6: 3 | I6: =$T$7*H6 -> 353.43498 | J6: =G6+$T$9+I6 -> 358.9574 | K6: =$T$11/64 -> 0 | L6: 0 | M6: 0 | O6: 0 | P6: 0 | R6: =(SUM(J6:P6))*$B$2 -> 0
A7: F2 | B7: =VLOOKUP(A7,Members!$A$2:$B$65,2,FALSE) -> Rama P | C7: 0 | D7: =SUM($C$3:$C$5)/64 -> 0 | E7: =C7+D7 -> 0 | F7: =IF($C$70=0, 0, E7/$C$70) -> 0 | G7: =F7*$T$5 -> 0 | H7: 4 | I7: =$T$7*H7 -> 471.24664 | J7: =G7+$T$9+I7 -> 476.76906 | K7: =$T$11/64 -> 0 | L7: 0 | M7: 0 | O7: 0 | P7: 0 | R7: =(SUM(J7:P7))*$B$2 -> 0 | S7: RENT PER METER | T7: 117.81166
A8: F3 | B8: =VLOOKUP(A8,Members!$A$2:$B$65,2,FALSE) -> Samrat Kar | C8: 0 | D8: =SUM($C$3:$C$5)/64 -> 0 | E8: =C8+D8 -> 0 | F8: =IF($C$70=0, 0, E8/$C$70) -> 0 | G8: =F8*$T$5 -> 0 | H8: 4 | I8: =$T$7*H8 -> 471.24664 | J8: =G8+$T$9+I8 -> 476.76906 | K8: =$T$11/64 -> 0 | L8: 0 | M8: 0 | O8: 0 | P8: 0 | R8: =(SUM(J8:P8))*$B$2 -> 0 | S8: COMMON AREA METER RENT | T8: =$T$7*3 -> 353.43498
A9: F4 | B9: =VLOOKUP(A9,Members!$A$2:$B$65,2,FALSE) -> Renu R | C9: 0 | D9: =SUM($C$3:$C$5)/64 -> 0 | E9: =C9+D9 -> 0 | F9: =IF($C$70=0, 0, E9/$C$70) -> 0 | G9: =F9*$T$5 -> 0 | H9: 4 | I9: =$T$7*H9 -> 471.24664 | J9: =G9+$T$9+I9 -> 476.76906 | K9: =$T$11/64 -> 0 | L9: 0 | M9: 0 | O9: 0 | P9: 0 | R9: =(SUM(J9:P9))*$B$2 -> 0 | S9: COMMON AREA METER RENT/FLAT | T9: =T8/64 -> 5.5224215
A10: F5 | B10: =VLOOKUP(A10,Members!$A$2:$B$65,2,FALSE) -> Vamsidhar Bethanabatla | C10: 0 | D10: =SUM($C$3:$C$5)/64 -> 0 | E10: =C10+D10 -> 0 | F10: =IF($C$70=0, 0, E10/$C$70) -> 0 | G10: =F10*$T$5 -> 0 | H10: 3 | I10: =$T$7*H10 -> 353.43498 | J10: =G10+$T$9+I10 -> 358.9574 | K10: =$T$11/64 -> 0 | L10: 0 | M10: 0 | O10: 0 | P10: 0 | R10: =(SUM(J10:P10))*$B$2 -> 0
A11: F6 | B11: =VLOOKUP(A11,Members!$A$2:$B$65,2,FALSE) -> Viral Shah | C11: 0 | D11: =SUM($C$3:$C$5)/64 -> 0 | E11: =C11+D11 -> 0 | F11: =IF($C$70=0, 0, E11/$C$70) -> 0 | G11: =F11*$T$5 -> 0 | H11: 3 | I11: =$T$7*H11 -> 353.43498 | J11: =G11+$T$9+I11 -> 358.9574 | K11: =$T$11/64 -> 0 | L11: 0 | M11: 0 | O11: 0 | P11: 0 | R11: =(SUM(J11:P11))*$B$2 -> 0 | S11: TOTAL FIXED EXPENSE | T11: ='ANNUAL-EXPENSE-DETAILS'!V5 -> 0
A12: F7 | B12: =VLOOKUP(A12,Members!$A$2:$B$65,2,FALSE) -> Vimal NK | C12: 0 | D12: =SUM($C$3:$C$5)/64 -> 0 | E12: =C12+D12 -> 0 | F12: =IF($C$70=0, 0, E12/$C$70) -> 0 | G12: =F12*$T$5 -> 0 | H12: 3 | I12: =$T$7*H12 -> 353.43498 | J12: =G12+$T$9+I12 -> 358.9574 | K12: =$T$11/64 -> 0 | L12: 0 | M12: 0 | O12: 0 | P12: 0 | R12: =(SUM(J12:P12))*$B$2 -> 0
A13: F8 | B13: =VLOOKUP(A13,Members!$A$2:$B$65,2,FALSE) -> Ruhi Agrawal | C13: 0 | D13: =SUM($C$3:$C$5)/64 -> 0 | E13: =C13+D13 -> 0 | F13: =IF($C$70=0, 0, E13/$C$70) -> 0 | G13: =F13*$T$5 -> 0 | H13: 3 | I13: =$T$7*H13 -> 353.43498 | J13: =G13+$T$9+I13 -> 358.9574 | K13: =$T$11/64 -> 0 | L13: 0 | M13: 0 | O13: 0 | P13: 0 | R13: =(SUM(J13:P13))*$B$2 -> 0
A14: F9 | B14: =VLOOKUP(A14,Members!$A$2:$B$65,2,FALSE) -> Vijay Suswaram | C14: 0 | D14: =SUM($C$3:$C$5)/64 -> 0 | E14: =C14+D14 -> 0 | F14: =IF($C$70=0, 0, E14/$C$70) -> 0 | G14: =F14*$T$5 -> 0 | H14: 4 | I14: =$T$7*H14 -> 471.24664 | J14: =G14+$T$9+I14 -> 476.76906 | K14: =$T$11/64 -> 0 | L14: 0 | M14: 0 | O14: 0 | P14: 0 | R14: =(SUM(J14:P14))*$B$2 -> 0 | S14: BALANCE IN ACCOUNT ON 30-JUN-2023
A15: F10 | B15: =VLOOKUP(A15,Members!$A$2:$B$65,2,FALSE) -> Aby Thomas | C15: 0 | D15: =SUM($C$3:$C$5)/64 -> 0 | E15: =C15+D15 -> 0 | F15: =IF($C$70=0, 0, E15/$C$70) -> 0 | G15: =F15*$T$5 -> 0 | H15: 3 | I15: =$T$7*H15 -> 353.43498 | J15: =G15+$T$9+I15 -> 358.9574 | K15: =$T$11/64 -> 0 | L15: 0 | M15: 0 | O15: 0 | P15: 0 | R15: =(SUM(J15:P15))*$B$2 -> 0 | S15: TOTAL NON MAINTENANCE CORPUS COLLECTION
A16: F11 | B16: =VLOOKUP(A16,Members!$A$2:$B$65,2,FALSE) -> Renu R | C16: 0 | D16: =SUM($C$3:$C$5)/64 -> 0 | E16: =C16+D16 -> 0 | F16: =IF($C$70=0, 0, E16/$C$70) -> 0 | G16: =F16*$T$5 -> 0 | H16: 3 | I16: =$T$7*H16 -> 353.43498 | J16: =G16+$T$9+I16 -> 358.9574 | K16: =$T$11/64 -> 0 | L16: 0 | M16: 0 | O16: 0 | P16: 0 | R16: =(SUM(J16:P16))*$B$2 -> 0 | S16: TOTAL FD DONE
A17: F12 | B17: =VLOOKUP(A17,Members!$A$2:$B$65,2,FALSE) -> Kavitha T | C17: 0 | D17: =SUM($C$3:$C$5)/64 -> 0 | E17: =C17+D17 -> 0 | F17: =IF($C$70=0, 0, E17/$C$70) -> 0 | G17: =F17*$T$5 -> 0 | H17: 3 | I17: =$T$7*H17 -> 353.43498 | J17: =G17+$T$9+I17 -> 358.9574 | K17: =$T$11/64 -> 0 | L17: 0 | M17: 0 | O17: 0 | P17: 0 | R17: =(SUM(J17:P17))*$B$2 -> 0 | S17: AMOUNT AVAILABLE FOR NON MAINTENANCE CORPUS | T17: =T15-T16 -> 0
A18: F13 | B18: =VLOOKUP(A18,Members!$A$2:$B$65,2,FALSE) -> Srinivasa Rao | C18: 0 | D18: =SUM($C$3:$C$5)/64 -> 0 | E18: =C18+D18 -> 0 | F18: =IF($C$70=0, 0, E18/$C$70) -> 0 | G18: =F18*$T$5 -> 0 | H18: 4 | I18: =$T$7*H18 -> 471.24664 | J18: =G18+$T$9+I18 -> 476.76906 | K18: =$T$11/64 -> 0 | L18: 0 | M18: 0 | O18: 0 | P18: 0 | R18: =(SUM(J18:P18))*$B$2 -> 0 | S18: AMOUNT AVAILABLE FOR MAINTENANCE | T18: =T14-T17 -> 0
A19: F14 | B19: =VLOOKUP(A19,Members!$A$2:$B$65,2,FALSE) -> Hemant Patel | C19: 0 | D19: =SUM($C$3:$C$5)/64 -> 0 | E19: =C19+D19 -> 0 | F19: =IF($C$70=0, 0, E19/$C$70) -> 0 | G19: =F19*$T$5 -> 0 | H19: 4 | I19: =$T$7*H19 -> 471.24664 | J19: =G19+$T$9+I19 -> 476.76906 | K19: =$T$11/64 -> 0 | L19: 0 | M19: 0 | O19: 0 | P19: 0 | R19: =(SUM(J19:P19))*$B$2 -> 0
A20: F15 | B20: =VLOOKUP(A20,Members!$A$2:$B$65,2,FALSE) -> Senthil.Vijayaragavan | C20: 0 | D20: =SUM($C$3:$C$5)/64 -> 0 | E20: =C20+D20 -> 0 | F20: =IF($C$70=0, 0, E20/$C$70) -> 0 | G20: =F20*$T$5 -> 0 | H20: 4 | I20: =$T$7*H20 -> 471.24664 | J20: =G20+$T$9+I20 -> 476.76906 | K20: =$T$11/64 -> 0 | L20: 0 | M20: 0 | O20: 0 | P20: 0 | R20: =(SUM(J20:P20))*$B$2 -> 0
A21: F16 | B21: =VLOOKUP(A21,Members!$A$2:$B$65,2,FALSE) -> Sreeja Sudharma | C21: 0 | D21: =SUM($C$3:$C$5)/64 -> 0 | E21: =C21+D21 -> 0 | F21: =IF($C$70=0, 0, E21/$C$70) -> 0 | G21: =F21*$T$5 -> 0 | H21: 3 | I21: =$T$7*H21 -> 353.43498 | J21: =G21+$T$9+I21 -> 358.9574 | K21: =$T$11/64 -> 0 | L21: 0 | M21: 0 | O21: 0 | P21: 0 | R21: =(SUM(J21:P21))*$B$2 -> 0
A22: G1 | B22: =VLOOKUP(A22,Members!$A$2:$B$65,2,FALSE) -> Digvijay Verma | C22: 0 | D22: =SUM($C$3:$C$5)/64 -> 0 | E22: =C22+D22 -> 0 | F22: =IF($C$70=0, 0, E22/$C$70) -> 0 | G22: =F22*$T$5 -> 0 | H22: 3 | I22: =$T$7*H22 -> 353.43498 | J22: =G22+$T$9+I22 -> 358.9574 | K22: =$T$11/64 -> 0 | L22: 0 | M22: 0 | O22: 0 | P22: 0 | R22: =(SUM(J22:P22))*$B$2 -> 0
A23: G2 | B23: =VLOOKUP(A23,Members!$A$2:$B$65,2,FALSE) -> Kaushik Kasibhatla | C23: 0 | D23: =SUM($C$3:$C$5)/64 -> 0 | E23: =C23+D23 -> 0 | F23: =IF($C$70=0, 0, E23/$C$70) -> 0 | G23: =F23*$T$5 -> 0 | H23: 4 | I23: =$T$7*H23 -> 471.24664 | J23: =G23+$T$9+I23 -> 476.76906 | K23: =$T$11/64 -> 0 | L23: 0 | M23: 0 | O23: 0 | P23: 0 | R23: =(SUM(J23:P23))*$B$2 -> 0
A24: G3 | B24: =VLOOKUP(A24,Members!$A$2:$B$65,2,FALSE) -> Balakrishnan | C24: 0 | D24: =SUM($C$3:$C$5)/64 -> 0 | E24: =C24+D24 -> 0 | F24: =IF($C$70=0, 0, E24/$C$70) -> 0 | G24: =F24*$T$5 -> 0 | H24: 4 | I24: =$T$7*H24 -> 471.24664 | J24: =G24+$T$9+I24 -> 476.76906 | K24: =$T$11/64 -> 0 | L24: 0 | M24: 0 | O24: 0 | P24: 0 | R24: =(SUM(J24:P24))*$B$2 -> 0
A25: G4 | B25: =VLOOKUP(A25,Members!$A$2:$B$65,2,FALSE) -> Ashwin Pandith | C25: 0 | D25: =SUM($C$3:$C$5)/64 -> 0 | E25: =C25+D25 -> 0 | F25: =IF($C$70=0, 0, E25/$C$70) -> 0 | G25: =F25*$T$5 -> 0 | H25: 4 | I25: =$T$7*H25 -> 471.24664 | J25: =G25+$T$9+I25 -> 476.76906 | K25: =$T$11/64 -> 0 | L25: 0 | M25: 0 | O25: 0 | P25: 0 | R25: =(SUM(J25:P25))*$B$2 -> 0
A26: G5 | B26: =VLOOKUP(A26,Members!$A$2:$B$65,2,FALSE) -> Mayank Phophaliya | C26: 0 | D26: =SUM($C$3:$C$5)/64 -> 0 | E26: =C26+D26 -> 0 | F26: =IF($C$70=0, 0, E26/$C$70) -> 0 | G26: =F26*$T$5 -> 0 | H26: 3 | I26: =$T$7*H26 -> 353.43498 | J26: =G26+$T$9+I26 -> 358.9574 | K26: =$T$11/64 -> 0 | L26: 0 | M26: 0 | O26: 0 | P26: 0 | R26: =(SUM(J26:P26))*$B$2 -> 0
A27: G6 | B27: =VLOOKUP(A27,Members!$A$2:$B$65,2,FALSE) -> Srinath | C27: 0 | D27: =SUM($C$3:$C$5)/64 -> 0 | E27: =C27+D27 -> 0 | F27: =IF($C$70=0, 0, E27/$C$70) -> 0 | G27: =F27*$T$5 -> 0 | H27: 3 | I27: =$T$7*H27 -> 353.43498 | J27: =G27+$T$9+I27 -> 358.9574 | K27: =$T$11/64 -> 0 | L27: 0 | M27: 0 | O27: 0 | P27: 0 | R27: =(SUM(J27:P27))*$B$2 -> 0
A28: G7 | B28: =VLOOKUP(A28,Members!$A$2:$B$65,2,FALSE) -> Prince Richfield | C28: 0 | D28: =SUM($C$3:$C$5)/64 -> 0 | E28: =C28+D28 -> 0 | F28: =IF($C$70=0, 0, E28/$C$70) -> 0 | G28: =F28*$T$5 -> 0 | H28: 3 | I28: =$T$7*H28 -> 353.43498 | J28: =G28+$T$9+I28 -> 358.9574 | K28: =$T$11/64 -> 0 | L28: 0 | M28: 0 | O28: 0 | P28: 0 | R28: =(SUM(J28:P28))*$B$2 -> 0
A29: G8 | B29: =VLOOKUP(A29,Members!$A$2:$B$65,2,FALSE) -> Arun M | C29: 0 | D29: =SUM($C$3:$C$5)/64 -> 0 | E29: =C29+D29 -> 0 | F29: =IF($C$70=0, 0, E29/$C$70) -> 0 | G29: =F29*$T$5 -> 0 | H29: 3 | I29: =$T$7*H29 -> 353.43498 | J29: =G29+$T$9+I29 -> 358.9574 | K29: =$T$11/64 -> 0 | L29: 0 | M29: 0 | O29: 0 | P29: 0 | R29: =(SUM(J29:P29))*$B$2 -> 0
A30: G9 | B30: =VLOOKUP(A30,Members!$A$2:$B$65,2,FALSE) -> Chandramouli | C30: 0 | D30: =SUM($C$3:$C$5)/64 -> 0 | E30: =C30+D30 -> 0 | F30: =IF($C$70=0, 0, E30/$C$70) -> 0 | G30: =F30*$T$5 -> 0 | H30: 5 | I30: =$T$7*H30 -> 589.0583 | J30: =G30+$T$9+I30 -> 594.58072 | K30: =$T$11/64 -> 0 | L30: 0 | M30: 0 | O30: 0 | P30: 0 | R30: =(SUM(J30:P30))*$B$2 -> 0
... A69: T16 | B69: =VLOOKUP(A69,Members!$A$2:$B$65,2,FALSE) -> Madhusoodanan P.R. | C69: 0 | D69: =SUM($C$3:$C$5)/64 -> 0 | E69: =C69+D69 -> 0 | F69: =IF($C$70=0, 0, E69/$C$70) -> 0 | G69: =F69*$T$5 -> 0 | H69: 3 | I69: =$T$7*H69 -> 353.43498 | J69: =G69+$T$9+I69 -> 358.9574 | K69: =$T$11/64 -> 0 | L69: 0 | M69: 0 | O69: 0 | P69: 0 | R69: =(SUM(J69:P69))*$B$2 -> 0
B70: TOTAL | C70: =SUM(C3:C69) -> 0 | D70: =SUM(D3:D69) -> 0 | E70: =SUM(E3:E69) -> 0 | F70: =IF($C$70=0, 0, E70/$C$70) -> 0 | G70: =SUM(G3:G69) -> 0 | H70: =SUM(H3:H69) -> 223 | I70: =SUM(I3:I69) -> 26272 | J70: =SUM(J3:J69) -> 26272 | K70: =SUM(K3:K69) -> 0 | L70: =SUM(L3:L69) -> 0 | M70: =SUM(M3:M69) -> 0 | N70: =SUM(N3:N69) -> 0 | ... P70: =SUM(P3:P69) -> 0 | R70: =SUM(R3:R69) -> 0

Sheet June2026-COLLECTION
A1: FLAT # | C1: Amount | D1: Date | E1: Amount | F1: Date | G1: Amount | H1: Date | I1: Amount | J1: Date | K1: Total
A2: F1 | B2: =VLOOKUP(A2,Members!$A$2:$B$65,2,FALSE) -> Shailesh Srivastava | K2: =SUM(C2,E2,G2,I2) -> 0
A3: F2 | B3: =VLOOKUP(A3,Members!$A$2:$B$65,2,FALSE) -> Rama P | K3: =SUM(C3,E3,G3,I3) -> 0
A4: F3 | B4: =VLOOKUP(A4,Members!$A$2:$B$65,2,FALSE) -> Samrat Kar | K4: =SUM(C4,E4,G4,I4) -> 0
A5: F4 | B5: =VLOOKUP(A5,Members!$A$2:$B$65,2,FALSE) -> Renu R | K5: =SUM(C5,E5,G5,I5) -> 0
A6: F5 | B6: =VLOOKUP(A6,Members!$A$2:$B$65,2,FALSE) -> Vamsidhar Bethanabatla | K6: =SUM(C6,E6,G6,I6) -> 0
A7: F6 | B7: =VLOOKUP(A7,Members!$A$2:$B$65,2,FALSE) -> Viral Shah | K7: =SUM(C7,E7,G7,I7) -> 0
A8: F7 | B8: =VLOOKUP(A8,Members!$A$2:$B$65,2,FALSE) -> Vimal NK | K8: =SUM(C8,E8,G8,I8) -> 0
A9: F8 | B9: =VLOOKUP(A9,Members!$A$2:$B$65,2,FALSE) -> Ruhi Agrawal | K9: =SUM(C9,E9,G9,I9) -> 0
A10: F9 | B10: =VLOOKUP(A10,Members!$A$2:$B$65,2,FALSE) -> Vijay Suswaram | K10: =SUM(C10,E10,G10,I10) -> 0
A11: F10 | B11: =VLOOKUP(A11,Members!$A$2:$B$65,2,FALSE) -> Aby Thomas | K11: =SUM(C11,E11,G11,I11) -> 0
A12: F11 | B12: =VLOOKUP(A12,Members!$A$2:$B$65,2,FALSE) -> Renu R | K12: =SUM(C12,E12,G12,I12) -> 0
A13: F12 | B13: =VLOOKUP(A13,Members!$A$2:$B$65,2,FALSE) -> Kavitha T | K13: =SUM(C13,E13,G13,I13) -> 0
... A65: T16 | B65: =VLOOKUP(A65,Members!$A$2:$B$65,2,FALSE) -> Madhusoodanan P.R. | K65: =SUM(C65,E65,G65,I65) -> 0
A66: TOTAL | K66: =SUM(K2:K65) -> 0

Sheet July2026-EXPENSE
B1: JUL 2026 EXPENSES
A2: FLAT # | B2: 0 | C2: WATER USED IN LTRS | D2: COMMON AREA EQUALLY DEVIDED | E2: TOTAL FRESH WATER CONSUMED | F2: %OF TOTAL USED | G2: WATER EXPENSE SHARING BY % | H2: #METERS | I2: METER RENT | J2: VARIABLE EXPENSE = COMMON AREA METER RENT + WATER EXPENSE+ FLAT METER RENT | K2: FIXED EXPENSE SHARE | L2: PARKING FEE | M2: CLUB BOOKING FEE | N2: SHIFTING FEE | O2: GYM USAGE FEE | R2: TOTAL EXPENSE TO BE PAID
A3: CH | B3: MPFOWA | C3: 0 | D3: 0 | H3: 1 | I3: =T7 -> 117.81166
A4: GYM | B4: MPFOWA | C4: 0 | D4: 0 | H4: 1 | I4: =T7 -> 117.81166 | S4: TOTAL FIXED EXPENSE | T4: ='ANNUAL-EXPENSE-DETAILS'!V6 -> 0
A5: BSMT | B5: MPFOWA | C5: 0 | D5: 0 | H5: 1 | I5: =T7 -> 117.81166 | S5: TOTAL WATER EXPENSE | T5: ='ANNUAL-EXPENSE-DETAILS'!U6 -> 0
A6: F1 | B6: =VLOOKUP(A6,Members!$A$2:$B$65,2,FALSE) -> Shailesh Srivastava | C6: 0 | D6: =SUM($C$3:$C$5)/64 -> 0 | E6: =C6+D6 -> 0 | F6: =IF($C$70=0, 0, E6/$C$70) -> 0 | G6: =F6*$T$5 -> 0 | H6: 3 | I6: =$T$7*H6 -> 353.43498 | J6: =G6+$T$9+I6 -> 358.9574 | K6: =$T$11/64 -> 0 | L6: 0 | M6: 0 | N6: 0 | O6: 0 | R6: =(J6+K6+L6+M6+N6+O6)*$B$2 -> 0
A7: F2 | B7: =VLOOKUP(A7,Members!$A$2:$B$65,2,FALSE) -> Rama P | C7: 0 | D7: =SUM($C$3:$C$5)/64 -> 0 | E7: =C7+D7 -> 0 | F7: =IF($C$70=0, 0, E7/$C$70) -> 0 | G7: =F7*$T$5 -> 0 | H7: 4 | I7: =$T$7*H7 -> 471.24664 | J7: =G7+$T$9+I7 -> 476.76906 | K7: =$T$11/64 -> 0 | L7: 0 | M7: 0 | N7: 0 | O7: 0 | R7: =(J7+K7+L7+M7+N7+O7)*$B$2 -> 0 | S7: RENT PER METER | T7: 117.81166
A8: F3 | B8: =VLOOKUP(A8,Members!$A$2:$B$65,2,FALSE) -> Samrat Kar | C8: 0 | D8: =SUM($C$3:$C$5)/64 -> 0 | E8: =C8+D8 -> 0 | F8: =IF($C$70=0, 0, E8/$C$70) -> 0 | G8: =F8*$T$5 -> 0 | H8: 4 | I8: =$T$7*H8 -> 471.24664 | J8: =G8+$T$9+I8 -> 476.76906 | K8: =$T$11/64 -> 0 | L8: 0 | M8: 0 | N8: 0 | O8: 0 | R8: =(J8+K8+L8+M8+N8+O8)*$B$2 -> 0 | S8: COMMON AREA METER RENT | T8: =$T$7*3 -> 353.43498
A9: F4 | B9: =VLOOKUP(A9,Members!$A$2:$B$65,2,FALSE) -> Renu R | C9: 0 | D9: =SUM($C$3:$C$5)/64 -> 0 | E9: =C9+D9 -> 0 | F9: =IF($C$70=0, 0, E9/$C$70) -> 0 | G9: =F9*$T$5 -> 0 | H9: 4 | I9: =$T$7*H9 -> 471.24664 | J9: =G9+$T$9+I9 -> 476.76906 | K9: =$T$11/64 -> 0 | L9: 0 | M9: 0 | N9: 0 | O9: 0 | R9: =(J9+K9+L9+M9+N9+O9)*$B$2 -> 0 | S9: COMMON AREA METER RENT/FLAT | T9: =T8/64 -> 5.5224215
A10: F5 | B10: =VLOOKUP(A10,Members!$A$2:$B$65,2,FALSE) -> Vamsidhar Bethanabatla | C10: 0 | D10: =SUM($C$3:$C$5)/64 -> 0 | E10: =C10+D10 -> 0 | F10: =IF($C$70=0, 0, E10/$C$70) -> 0 | G10: =F10*$T$5 -> 0 | H10: 3 | I10: =$T$7*H10 -> 353.43498 | J10: =G10+$T$9+I10 -> 358.9574 | K10: =$T$11/64 -> 0 | L10: 0 | M10: 0 | N10: 0 | O10: 0 | R10: =(J10+K10+L10+M10+N10+O10)*$B$2 -> 0
A11: F6 | B11: =VLOOKUP(A11,Members!$A$2:$B$65,2,FALSE) -> Viral Shah | C11: 0 | D11: =SUM($C$3:$C$5)/64 -> 0 | E11: =C11+D11 -> 0 | F11: =IF($C$70=0, 0, E11/$C$70) -> 0 | G11: =F11*$T$5 -> 0 | H11: 3 | I11: =$T$7*H11 -> 353.43498 | J11: =G11+$T$9+I11 -> 358.9574 | K11: =$T$11/64 -> 0 | L11: 0 | M11: 0 | N11: 0 | O11: 0 | R11: =(J11+K11+L11+M11+N11+O11)*$B$2 -> 0 | S11: TOTAL FIXED EXPENSE | T11: ='ANNUAL-EXPENSE-DETAILS'!V6 -> 0
A12: F7 | B12: =VLOOKUP(A12,Members!$A$2:$B$65,2,FALSE) -> Vimal NK | C12: 0 | D12: =SUM($C$3:$C$5)/64 -> 0 | E12: =C12+D12 -> 0 | F12: =IF($C$70=0, 0, E12/$C$70) -> 0 | G12: =F12*$T$5 -> 0 | H12: 3 | I12: =$T$7*H12 -> 353.43498 | J12: =G12+$T$9+I12 -> 358.9574 | K12: =$T$11/64 -> 0 | L12: 0 | M12: 0 | N12: 0 | O12: 0 | R12: =(J12+K12+L12+M12+N12+O12)*$B$2 -> 0
A13: F8 | B13: =VLOOKUP(A13,Members!$A$2:$B$65,2,FALSE) -> Ruhi Agrawal | C13: 0 | D13: =SUM($C$3:$C$5)/64 -> 0 | E13: =C13+D13 -> 0 | F13: =IF($C$70=0, 0, E13/$C$70) -> 0 | G13: =F13*$T$5 -> 0 | H13: 3 | I13: =$T$7*H13 -> 353.43498 | J13: =G13+$T$9+I13 -> 358.9574 | K13: =$T$11/64 -> 0 | L13: 0 | M13: 0 | N13: 0 | O13: 0 | R13: =(J13+K13+L13+M13+N13+O13)*$B$2 -> 0
A14: F9 | B14: =VLOOKUP(A14,Members!$A$2:$B$65,2,FALSE) -> Vijay Suswaram | C14: 0 | D14: =SUM($C$3:$C$5)/64 -> 0 | E14: =C14+D14 -> 0 | F14: =IF($C$70=0, 0, E14/$C$70) -> 0 | G14: =F14*$T$5 -> 0 | H14: 4 | I14: =$T$7*H14 -> 471.24664 | J14: =G14+$T$9+I14 -> 476.76906 | K14: =$T$11/64 -> 0 | L14: 0 | M14: 0 | N14: 0 | O14: 0 | R14: =(J14+K14+L14+M14+N14+O14)*$B$2 -> 0 | S14: BALANCE IN ACCOUNT ON 31-JULY-2023
A15: F10 | B15: =VLOOKUP(A15,Members!$A$2:$B$65,2,FALSE) -> Aby Thomas | C15: 0 | D15: =SUM($C$3:$C$5)/64 -> 0 | E15: =C15+D15 -> 0 | F15: =IF($C$70=0, 0, E15/$C$70) -> 0 | G15: =F15*$T$5 -> 0 | H15: 3 | I15: =$T$7*H15 -> 353.43498 | J15: =G15+$T$9+I15 -> 358.9574 | K15: =$T$11/64 -> 0 | L15: 0 | M15: 0 | N15: 0 | O15: 0 | R15: =(J15+K15+L15+M15+N15+O15)*$B$2 -> 0 | S15: TOTAL NON MAINTENANCE CORPUS COLLECTION
A16: F11 | B16: =VLOOKUP(A16,Members!$A$2:$B$65,2,FALSE) -> Renu R | C16: 0 | D16: =SUM($C$3:$C$5)/64 -> 0 | E16: =C16+D16 -> 0 | F16: =IF($C$70=0, 0, E16/$C$70) -> 0 | G16: =F16*$T$5 -> 0 | H16: 3 | I16: =$T$7*H16 -> 353.43498 | J16: =G16+$T$9+I16 -> 358.9574 | K16: =$T$11/64 -> 0 | L16: 0 | M16: 0 | N16: 0 | O16: 0 | R16: =(J16+K16+L16+M16+N16+O16)*$B$2 -> 0 | S16: TOTAL FD DONE
A17: F12 | B17: =VLOOKUP(A17,Members!$A$2:$B$65,2,FALSE) -> Kavitha T | C17: 0 | D17: =SUM($C$3:$C$5)/64 -> 0 | E17: =C17+D17 -> 0 | F17: =IF($C$70=0, 0, E17/$C$70) -> 0 | G17: =F17*$T$5 -> 0 | H17: 3 | I17: =$T$7*H17 -> 353.43498 | J17: =G17+$T$9+I17 -> 358.9574 | K17: =$T$11/64 -> 0 | L17: 0 | M17: 0 | N17: 0 | O17: 0 | R17: =(J17+K17+L17+M17+N17+O17)*$B$2 -> 0 | S17: AMOUNT AVAILABLE FOR NON MAINTENANCE CORPUS | T17: =T15-T16 -> 0
A18: F13 | B18: =VLOOKUP(A18,Members!$A$2:$B$65,2,FALSE) -> Srinivasa Rao | C18: 0 | D18: =SUM($C$3:$C$5)/64 -> 0 | E18: =C18+D18 -> 0 | F18: =IF($C$70=0, 0, E18/$C$70) -> 0 | G18: =F18*$T$5 -> 0 | H18: 4 | I18: =$T$7*H18 -> 471.24664 | J18: =G18+$T$9+I18 -> 476.76906 | K18: =$T$11/64 -> 0 | L18: 0 | M18: 0 | N18: 0 | O18: 0 | R18: =(J18+K18+L18+M18+N18+O18)*$B$2 -> 0 | S18: AMOUNT AVAILABLE FOR MAINTENANCE | T18: =T14-T17 -> 0
A19: F14 | B19: =VLOOKUP(A19,Members!$A$2:$B$65,2,FALSE) -> Hemant Patel | C19: 0 | D19: =SUM($C$3:$C$5)/64 -> 0 | E19: =C19+D19 -> 0 | F19: =IF($C$70=0, 0, E19/$C$70) -> 0 | G19: =F19*$T$5 -> 0 | H19: 4 | I19: =$T$7*H19 -> 471.24664 | J19: =G19+$T$9+I19 -> 476.76906 | K19: =$T$11/64 -> 0 | L19: 0 | M19: 0 | N19: 0 | O19: 0 | R19: =(J19+K19+L19+M19+N19+O19)*$B$2 -> 0
A20: F15 | B20: =VLOOKUP(A20,Members!$A$2:$B$65,2,FALSE) -> Senthil.Vijayaragavan | C20: 0 | D20: =SUM($C$3:$C$5)/64 -> 0 | E20: =C20+D20 -> 0 | F20: =IF($C$70=0, 0, E20/$C$70) -> 0 | G20: =F20*$T$5 -> 0 | H20: 4 | I20: =$T$7*H20 -> 471.24664 | J20: =G20+$T$9+I20 -> 476.76906 | K20: =$T$11/64 -> 0 | L20: 0 | M20: 0 | N20: 0 | O20: 0 | R20: =(J20+K20+L20+M20+N20+O20)*$B$2 -> 0
A21: F16 | B21: =VLOOKUP(A21,Members!$A$2:$B$65,2,FALSE) -> Sreeja Sudharma | C21: 0 | D21: =SUM($C$3:$C$5)/64 -> 0 | E21: =C21+D21 -> 0 | F21: =IF($C$70=0, 0, E21/$C$70) -> 0 | G21: =F21*$T$5 -> 0 | H21: 3 | I21: =$T$7*H21 -> 353.43498 | J21: =G21+$T$9+I21 -> 358.9574 | K21: =$T$11/64 -> 0 | L21: 0 | M21: 0 | N21: 0 | O21: 0 | R21: =(J21+K21+L21+M21+N21+O21)*$B$2 -> 0
A22: G1 | B22: =VLOOKUP(A22,Members!$A$2:$B$65,2,FALSE) -> Digvijay Verma | C22: 0 | D22: =SUM($C$3:$C$5)/64 -> 0 | E22: =C22+D22 -> 0 | F22: =IF($C$70=0, 0, E22/$C$70) -> 0 | G22: =F22*$T$5 -> 0 | H22: 3 | I22: =$T$7*H22 -> 353.43498 | J22: =G22+$T$9+I22 -> 358.9574 | K22: =$T$11/64 -> 0 | L22: 0 | M22: 0 | N22: 0 | O22: 0 | R22: =(J22+K22+L22+M22+N22+O22)*$B$2 -> 0
A23: G2 | B23: =VLOOKUP(A23,Members!$A$2:$B$65,2,FALSE) -> Kaushik Kasibhatla | C23: 0 | D23: =SUM($C$3:$C$5)/64 -> 0 | E23: =C23+D23 -> 0 | F23: =IF($C$70=0, 0, E23/$C$70) -> 0 | G23: =F23*$T$5 -> 0 | H23: 4 | I23: =$T$7*H23 -> 471.24664 | J23: =G23+$T$9+I23 -> 476.76906 | K23: =$T$11/64 -> 0 | L23: 0 | M23: 0 | N23: 0 | O23: 0 | R23: =(J23+K23+L23+M23+N23+O23)*$B$2 -> 0
A24: G3 | B24: =VLOOKUP(A24,Members!$A$2:$B$65,2,FALSE) -> Balakrishnan | C24: 0 | D24: =SUM($C$3:$C$5)/64 -> 0 | E24: =C24+D24 -> 0 | F24: =IF($C$70=0, 0, E24/$C$70) -> 0 | G24: =F24*$T$5 -> 0 | H24: 4 | I24: =$T$7*H24 -> 471.24664 | J24: =G24+$T$9+I24 -> 476.76906 | K24: =$T$11/64 -> 0 | L24: 0 | M24: 0 | N24: 0 | O24: 0 | R24: =(J24+K24+L24+M24+N24+O24)*$B$2 -> 0
A25: G4 | B25: =VLOOKUP(A25,Members!$A$2:$B$65,2,FALSE) -> Ashwin Pandith | C25: 0 | D25: =SUM($C$3:$C$5)/64 -> 0 | E25: =C25+D25 -> 0 | F25: =IF($C$70=0, 0, E25/$C$70) -> 0 | G25: =F25*$T$5 -> 0 | H25: 4 | I25: =$T$7*H25 -> 471.24664 | J25: =G25+$T$9+I25 -> 476.76906 | K25: =$T$11/64 -> 0 | L25: 0 | M25: 0 | N25: 0 | O25: 0 | R25: =(J25+K25+L25+M25+N25+O25)*$B$2 -> 0
A26: G5 | B26: =VLOOKUP(A26,Members!$A$2:$B$65,2,FALSE) -> Mayank Phophaliya | C26: 0 | D26: =SUM($C$3:$C$5)/64 -> 0 | E26: =C26+D26 -> 0 | F26: =IF($C$70=0, 0, E26/$C$70) -> 0 | G26: =F26*$T$5 -> 0 | H26: 3 | I26: =$T$7*H26 -> 353.43498 | J26: =G26+$T$9+I26 -> 358.9574 | K26: =$T$11/64 -> 0 | L26: 0 | M26: 0 | N26: 0 | O26: 0 | R26: =(J26+K26+L26+M26+N26+O26)*$B$2 -> 0
A27: G6 | B27: =VLOOKUP(A27,Members!$A$2:$B$65,2,FALSE) -> Srinath | C27: 0 | D27: =SUM($C$3:$C$5)/64 -> 0 | E27: =C27+D27 -> 0 | F27: =IF($C$70=0, 0, E27/$C$70) -> 0 | G27: =F27*$T$5 -> 0 | H27: 3 | I27: =$T$7*H27 -> 353.43498 | J27: =G27+$T$9+I27 -> 358.9574 | K27: =$T$11/64 -> 0 | L27: 0 | M27: 0 | N27: 0 | O27: 0 | R27: =(J27+K27+L27+M27+N27+O27)*$B$2 -> 0
A28: G7 | B28: =VLOOKUP(A28,Members!$A$2:$B$65,2,FALSE) -> Prince Richfield | C28: 0 | D28: =SUM($C$3:$C$5)/64 -> 0 | E28: =C28+D28 -> 0 | F28: =IF($C$70=0, 0, E28/$C$70) -> 0 | G28: =F28*$T$5 -> 0 | H28: 3 | I28: =$T$7*H28 -> 353.43498 | J28: =G28+$T$9+I28 -> 358.9574 | K28: =$T$11/64 -> 0 | L28: 0 | M28: 0 | N28: 0 | O28: 0 | R28: =(J28+K28+L28+M28+N28+O28)*$B$2 -> 0
A29: G8 | B29: =VLOOKUP(A29,Members!$A$2:$B$65,2,FALSE) -> Arun M | C29: 0 | D29: =SUM($C$3:$C$5)/64 -> 0 | E29: =C29+D29 -> 0 | F29: =IF($C$70=0, 0, E29/$C$70) -> 0 | G29: =F29*$T$5 -> 0 | H29: 3 | I29: =$T$7*H29 -> 353.43498 | J29: =G29+$T$9+I29 -> 358.9574 | K29: =$T$11/64 -> 0 | L29: 0 | M29: 0 | N29: 0 | O29: 0 | R29: =(J29+K29+L29+M29+N29+O29)*$B$2 -> 0
A30: G9 | B30: =VLOOKUP(A30,Members!$A$2:$B$65,2,FALSE) -> Chandramouli | C30: 0 | D30: =SUM($C$3:$C$5)/64 -> 0 | E30: =C30+D30 -> 0 | F30: =IF($C$70=0, 0, E30/$C$70) -> 0 | G30: =F30*$T$5 -> 0 | H30: 5 | I30: =$T$7*H30 -> 589.0583 | J30: =G30+$T$9+I30 -> 594.58072 | K30: =$T$11/64 -> 0 | L30: 0 | M30: 0 | N30: 0 | O30: 0 | R30: =(J30+K30+L30+M30+N30+O30)*$B$2 -> 0
... A69: T16 | B69: =VLOOKUP(A69,Members!$A$2:$B$65,2,FALSE) -> Madhusoodanan P.R. | C69: 0 | D69: =SUM($C$3:$C$5)/64 -> 0 | E69: =C69+D69 -> 0 | F69: =IF($C$70=0, 0, E69/$C$70) -> 0 | G69: =F69*$T$5 -> 0 | H69: 3 | I69: =$T$7*H69 -> 353.43498 | J69: =G69+$T$9+I69 -> 358.9574 | K69: =$T$11/64 -> 0 | L69: 0 | M69: 0 | N69: 0 | O69: 0 | R69: =(J69+K69+L69+M69+N69+O69)*$B$2 -> 0
B70: TOTAL | C70: =SUM(C3:C69) -> 0 | D70: =SUM(D3:D69) -> 0 | E70: =SUM(E3:E69) -> 0 | F70: =SUM(F3:F69) -> 0 | G70: =SUM(G3:G69) -> 0 | H70: =SUM(H3:H69) -> 223 | I70: =SUM(I3:I69) -> 26272 | J70: =SUM(J3:J69) -> 26272 | ... O70: =SUM(O3:O69) -> 0 | R70: =SUM(R3:R69) -> 0

Sheet July2026-COLLECTION
A1: FLAT # | C1: Amount | D1: Date | E1: Amount | F1: Date | G1: Amount | H1: Date | I1: Amount | J1: Date | K1: Total
A2: F1 | B2: =VLOOKUP(A2,Members!$A$2:$B$65,2,FALSE) -> Shailesh Srivastava | K2: =SUM(C2,E2,G2,I2) -> 0
A3: F2 | B3: =VLOOKUP(A3,Members!$A$2:$B$65,2,FALSE) -> Rama P | K3: =SUM(C3,E3,G3,I3) -> 0
A4: F3 | B4: =VLOOKUP(A4,Members!$A$2:$B$65,2,FALSE) -> Samrat Kar | K4: =SUM(C4,E4,G4,I4) -> 0
A5: F4 | B5: =VLOOKUP(A5,Members!$A$2:$B$65,2,FALSE) -> Renu R | K5: =SUM(C5,E5,G5,I5) -> 0
A6: F5 | B6: =VLOOKUP(A6,Members!$A$2:$B$65,2,FALSE) -> Vamsidhar Bethanabatla | K6: =SUM(C6,E6,G6,I6) -> 0
A7: F6 | B7: =VLOOKUP(A7,Members!$A$2:$B$65,2,FALSE) -> Viral Shah | K7: =SUM(C7,E7,G7,I7) -> 0
A8: F7 | B8: =VLOOKUP(A8,Members!$A$2:$B$65,2,FALSE) -> Vimal NK | K8: =SUM(C8,E8,G8,I8) -> 0
A9: F8 | B9: =VLOOKUP(A9,Members!$A$2:$B$65,2,FALSE) -> Ruhi Agrawal | K9: =SUM(C9,E9,G9,I9) -> 0
A10: F9 | B10: =VLOOKUP(A10,Members!$A$2:$B$65,2,FALSE) -> Vijay Suswaram | K10: =SUM(C10,E10,G10,I10) -> 0
A11: F10 | B11: =VLOOKUP(A11,Members!$A$2:$B$65,2,FALSE) -> Aby Thomas | K11: =SUM(C11,E11,G11,I11) -> 0
A12: F11 | B12: =VLOOKUP(A12,Members!$A$2:$B$65,2,FALSE) -> Renu R | K12: =SUM(C12,E12,G12,I12) -> 0
A13: F12 | B13: =VLOOKUP(A13,Members!$A$2:$B$65,2,FALSE) -> Kavitha T | K13: =SUM(C13,E13,G13,I13) -> 0
... A65: T16 | B65: =VLOOKUP(A65,Members!$A$2:$B$65,2,FALSE) -> Madhusoodanan P.R. | K65: =SUM(C65,E65,G65,I65) -> 0
A66: TOTAL | K66: =SUM(K2:K65) -> 0

Sheet Aug2026-EXPENSE
B1: AUG 2026 EXPENSES
