Workbook

Sheet Apr2026-EXPENSE
B1: APR 2026 EXPENSES
A2: FLAT # | B2: 1 | C2: WATER USED IN LTRS | D2: COMMON AREA WATER EQUALLY DIVIDED (L) | E2: TOTAL FRESH WATER CONSUMED(L) | F2: %OF TOTAL WATER USED | G2: WATER EXPENSE SHARING BY % | H2: #METERS | I2: METER RENT (Rs) | J2: TOTAL VARIABLE = (COMMON AREA METER RENT + WATER EXPENSE+ FLAT METER RENT (Rs)) | K2: FIXED EXPENSE SHARE(Rs) | L2: PARKING FEE(Rs) | M2: CLUB HOUSE FEE (Rs) | N2: SHIFTING FEE (Rs) | O2: GYM USAGE FEE(Rs) | P2: COVID+ GARBAGE FEE (Rs) | Q2: ANNUAL MEMBERSHIP FEE - 2022-2023 (Rs) | R2: TOTAL EXPENSE TO BE PAID (Rs)
A3: CH | B3: MPFOWA | C3: 0 | D3: 0 | H3: 1 | I3: =T7
A4: GYM | B4: MPFOWA | C4: 0 | D4: 0 | H4: 1 | I4: =T7 | S4: TOTAL FIXED EXPENSE | T4: ='ANNUAL-EXPENSE-DETAILS'!BF3
A5: BSMT | B5: MPFOWA | C5: 0 | D5: 0 | H5: 1 | I5: =T7 | S5: TOTAL WATER EXPENSE | T5: ='ANNUAL-EXPENSE-DETAILS'!BE3
A6: F1 | B6: Shailesh Srivastava / Azeem Nawaz | C6: 0 | D6: =SUM($C$3:$C$5)/64 | E6: =C6+D6 | F6: =IF($C$70=0, 0, E6/$C$70) | G6: =F6*$T$5 | H6: 3 | I6: =$T$7*H6 | J6: =G6+$T$9+I6 | K6: =$T$4/64 | L6: 0 | M6: 0 | N6: 0 | O6: 0 | P6: 0 | Q6: 0 | R6: =(J6+K6+L6+M6+Q6+N6+O6+P6)*$B$2
A7: F2 | B7: Shanthanu | C7: 0 | D7: =SUM($C$3:$C$5)/64 | E7: =C7+D7 | F7: =IF($C$70=0, 0, E7/$C$70) | G7: =F7*$T$5 | H7: 4 | I7: =$T$7*H7 | J7: =G7+$T$9+I7 | K7: =$T$4/64 | L7: 0 | M7: 0 | N7: 0 | O7: 0 | P7: 0 | Q7: 0 | R7: =(J7+K7+L7+M7+Q7+N7+O7+P7)*$B$2 | S7: RENT PER METER (Rs) | T7: 112.21
A8: F3 | B8: Samrat Kar | C8: 0 | D8: =SUM($C$3:$C$5)/64 | E8: =C8+D8 | F8: =IF($C$70=0, 0, E8/$C$70) | G8: =F8*$T$5 | H8: 4 | I8: =$T$7*H8 | J8: =G8+$T$9+I8 | K8: =$T$4/64 | L8: 0 | M8: 0 | N8: 0 | O8: 0 | P8: 0 | Q8: 0 | R8: =(J8+K8+L8+M8+Q8+N8+O8+P8)*$B$2 | S8: COMMON AREA METER RENT(Rs) | T8: =$T$7*3
A9: F4 | B9: Renu R | C9: 0 | D9: =SUM($C$3:$C$5)/64 | E9: =C9+D9 | F9: =IF($C$70=0, 0, E9/$C$70) | G9: =F9*$T$5 | H9: 4 | I9: =$T$7*H9 | J9: =G9+$T$9+I9 | K9: =$T$4/64 | L9: 0 | M9: 0 | N9: 0 | O9: 0 | P9: 0 | Q9: 0 | R9: =(J9+K9+L9+M9+Q9+N9+O9+P9)*$B$2 | S9: COMMON AREA METER RENT/FLAT (Rs) | T9: =T8/64
A10: F5 | B10: Vamsidhar Bethanabatla / Madhuri Anumula | C10: 0 | D10: =SUM($C$3:$C$5)/64 | E10: =C10+D10 | F10: =IF($C$70=0, 0, E10/$C$70) | G10: =F10*$T$5 | H10: 3 | I10: =$T$7*H10 | J10: =G10+$T$9+I10 | K10: =$T$4/64 | L10: 0 | M10: 0 | N10: 0 | O10: 0 | P10: 0 | Q10: 0 | R10: =(J10+K10+L10+M10+Q10+N10+O10+P10)*$B$2
A11: F6 | B11: Meghana Viral Shah and Vviral Shah (Owner) / Sangeet and Swagat (Tenent) | C11: 0 | D11: =SUM($C$3:$C$5)/64 | E11: =C11+D11 | F11: =IF($C$70=0, 0, E11/$C$70) | G11: =F11*$T$5 | H11: 3 | I11: =$T$7*H11 | J11: =G11+$T$9+I11 | K11: =$T$4/64 | L11: 0 | M11: 0 | N11: 0 | O11: 0 | P11: 0 | Q11: 0 | R11: =(J11+K11+L11+M11+Q11+N11+O11+P11)*$B$2 | S11: BALANCE IN ACCOUNT ON 30-Apr-2023
A12: F7 | B12: Vimal NK | C12: 0 | D12: =SUM($C$3:$C$5)/64 | E12: =C12+D12 | F12: =IF($C$70=0, 0, E12/$C$70) | G12: =F12*$T$5 | H12: 3 | I12: =$T$7*H12 | J12: =G12+$T$9+I12 | K12: =$T$4/64 | L12: 0 | M12: 0 | N12: 0 | O12: 0 | P12: 0 | Q12: 0 | R12: =(J12+K12+L12+M12+Q12+N12+O12+P12)*$B$2 | S12: TOTAL NON MAINTENANCE CORPUS COLLECTION
A13: F8 | B13: Sujeet Kumar (Tenant)/Sreejith Menon (Owner) | C13: 0 | D13: =SUM($C$3:$C$5)/64 | E13: =C13+D13 | F13: =IF($C$70=0, 0, E13/$C$70) | G13: =F13*$T$5 | H13: 3 | I13: =$T$7*H13 | J13: =G13+$T$9+I13 | K13: =$T$4/64 | L13: 0 | M13: 0 | N13: 0 | O13: 0 | P13: 0 | Q13: 0 | R13: =(J13+K13+L13+M13+Q13+N13+O13+P13)*$B$2 | S13: TOTAL FD DONE
A14: F9 | B14: Vijay Suswaram (Owner) / Divya Shikha (Tenant) | C14: 0 | D14: =SUM($C$3:$C$5)/64 | E14: =C14+D14 | F14: =IF($C$70=0, 0, E14/$C$70) | G14: =F14*$T$5 | H14: 4 | I14: =$T$7*H14 | J14: =G14+$T$9+I14 | K14: =$T$4/64 | L14: 0 | M14: 0 | N14: 0 | O14: 0 | P14: 0 | Q14: 0 | R14: =(J14+K14+L14+M14+Q14+N14+O14+P14)*$B$2 | S14: AMOUNT AVAILABLE FOR NON MAINTENANCE CORPUS IN CURRENT AC | T14: =T12-T13
A15: F10 | B15: Aby Thomas | C15: 0 | D15: =SUM($C$3:$C$5)/64 | E15: =C15+D15 | F15: =IF($C$70=0, 0, E15/$C$70) | G15: =F15*$T$5 | H15: 3 | I15: =$T$7*H15 | J15: =G15+$T$9+I15 | K15: =$T$4/64 | L15: 0 | M15: 0 | N15: 0 | O15: 0 | P15: 0 | Q15: 0 | R15: =(J15+K15+L15+M15+Q15+N15+O15+P15)*$B$2 | S15: Pending vendor payments
A16: F11 | B16: Niwin Anto | C16: 0 | D16: =SUM($C$3:$C$5)/64 | E16: =C16+D16 | F16: =IF($C$70=0, 0, E16/$C$70) | G16: =F16*$T$5 | H16: 3 | I16: =$T$7*H16 | J16: =G16+$T$9+I16 | K16: =$T$4/64 | L16: 0 | M16: 0 | N16: 0 | O16: 0 | P16: 0 | Q16: 0 | R16: =(J16+K16+L16+M16+Q16+N16+O16+P16)*$B$2 | S16: AMOUNT AVAILABLE FOR MAINTENANCE | T16: =T11-T14-T15
A17: F12 | B17: Anirudh Singh | C17: 0 | D17: =SUM($C$3:$C$5)/64 | E17: =C17+D17 | F17: =IF($C$70=0, 0, E17/$C$70) | G17: =F17*$T$5 | H17: 3 | I17: =$T$7*H17 | J17: =G17+$T$9+I17 | K17: =$T$4/64 | L17: 0 | M17: 0 | N17: 0 | O17: 0 | P17: 0 | Q17: 0 | R17: =(J17+K17+L17+M17+Q17+N17+O17+P17)*$B$2 | S17: TOTAL EXPENSE FOR THE MONTH | T17: ='ANNUAL-EXPENSE-DETAILS'!BI9
A18: F13 | B18: Sanchay Saxena | C18: 0 | D18: =SUM($C$3:$C$5)/64 | E18: =C18+D18 | F18: =IF($C$70=0, 0, E18/$C$70) | G18: =F18*$T$5 | H18: 4 | I18: =$T$7*H18 | J18: =G18+$T$9+I18 | K18: =$T$4/64 | L18: 0 | M18: 0 | N18: 0 | O18: 0 | P18: 0 | Q18: 0 | R18: =(J18+K18+L18+M18+Q18+N18+O18+P18)*$B$2 | S18: Maintenance deficit | T18: =T16-T17
A19: F14 | B19: Hemant Patel | C19: 0 | D19: =SUM($C$3:$C$5)/64 | E19: =C19+D19 | F19: =IF($C$70=0, 0, E19/$C$70) | G19: =F19*$T$5 | H19: 4 | I19: =$T$7*H19 | J19: =G19+$T$9+I19 | K19: =$T$4/64 | L19: 0 | M19: 0 | N19: 0 | O19: 0 | P19: 0 | Q19: 0 | R19: =(J19+K19+L19+M19+Q19+N19+O19+P19)*$B$2
A20: F15 | B20: Senthil.Vijayaragavan | C20: 0 | D20: =SUM($C$3:$C$5)/64 | E20: =C20+D20 | F20: =IF($C$70=0, 0, E20/$C$70) | G20: =F20*$T$5 | H20: 4 | I20: =$T$7*H20 | J20: =G20+$T$9+I20 | K20: =$T$4/64 | L20: 0 | M20: 0 | N20: 0 | O20: 0 | P20: 0 | Q20: 0 | R20: =(J20+K20+L20+M20+Q20+N20+O20+P20)*$B$2
A21: F16 | B21: Sreeja Sudharma | C21: 0 | D21: =SUM($C$3:$C$5)/64 | E21: =C21+D21 | F21: =IF($C$70=0, 0, E21/$C$70) | G21: =F21*$T$5 | H21: 3 | I21: =$T$7*H21 | J21: =G21+$T$9+I21 | K21: =$T$4/64 | L21: 0 | M21: 0 | N21: 0 | O21: 0 | P21: 0 | Q21: 0 | R21: =(J21+K21+L21+M21+Q21+N21+O21+P21)*$B$2
A22: G1 | B22: Venkataramanan C | C22: 0 | D22: =SUM($C$3:$C$5)/64 | E22: =C22+D22 | F22: =IF($C$70=0, 0, E22/$C$70) | G22: =F22*$T$5 | H22: 3 | I22: =$T$7*H22 | J22: =G22+$T$9+I22 | K22: =$T$4/64 | L22: 0 | M22: 0 | N22: 0 | O22: 0 | P22: 0 | Q22: 0 | R22: =(J22+K22+L22+M22+Q22+N22+O22+P22)*$B$2
A23: G2 | B23: Kaushik Kasibhatla | C23: 0 | D23: =SUM($C$3:$C$5)/64 | E23: =C23+D23 | F23: =IF($C$70=0, 0, E23/$C$70) | G23: =F23*$T$5 | H23: 4 | I23: =$T$7*H23 | J23: =G23+$T$9+I23 | K23: =$T$4/64 | L23: 0 | M23: 0 | N23: 0 | O23: 0 | P23: 0 | Q23: 0 | R23: =(J23+K23+L23+M23+Q23+N23+O23+P23)*$B$2
A24: G3 | B24: Balakrishnan | C24: 0 | D24: =SUM($C$3:$C$5)/64 | E24: =C24+D24 | F24: =IF($C$70=0, 0, E24/$C$70) | G24: =F24*$T$5 | H24: 4 | I24: =$T$7*H24 | J24: =G24+$T$9+I24 | K24: =$T$4/64 | L24: 0 | M24: 0 | N24: 0 | O24: 0 | P24: 0 | Q24: 0 | R24: =(J24+K24+L24+M24+Q24+N24+O24+P24)*$B$2
A25: G4 | B25: Ashwin Pandith | C25: 0 | D25: =SUM($C$3:$C$5)/64 | E25: =C25+D25 | F25: =IF($C$70=0, 0, E25/$C$70) | G25: =F25*$T$5 | H25: 4 | I25: =$T$7*H25 | J25: =G25+$T$9+I25 | K25: =$T$4/64 | L25: 0 | M25: 0 | N25: 0 | O25: 0 | P25: 0 | Q25: 0 | R25: =(J25+K25+L25+M25+Q25+N25+O25+P25)*$B$2
A26: G5 | B26: Mayank Phophaliya | C26: 0 | D26: =SUM($C$3:$C$5)/64 | E26: =C26+D26 | F26: =IF($C$70=0, 0, E26/$C$70) | G26: =F26*$T$5 | H26: 3 | I26: =$T$7*H26 | J26: =G26+$T$9+I26 | K26: =$T$4/64 | L26: 0 | M26: 0 | N26: 0 | O26: 0 | P26: 0 | Q26: 0 | R26: =(J26+K26+L26+M26+Q26+N26+O26+P26)*$B$2
A27: G6 | B27: Mohit Daga | C27: 0 | D27: =SUM($C$3:$C$5)/64 | E27: =C27+D27 | F27: =IF($C$70=0, 0, E27/$C$70) | G27: =F27*$T$5 | H27: 3 | I27: =$T$7*H27 | J27: =G27+$T$9+I27 | K27: =$T$4/64 | L27: 0 | M27: 0 | N27: 0 | O27: 0 | P27: 0 | Q27: 0 | R27: =(J27+K27+L27+M27+Q27+N27+O27+P27)*$B$2
A28: G7 | B28: Prince Richfield | C28: 0 | D28: =SUM($C$3:$C$5)/64 | E28: =C28+D28 | F28: =IF($C$70=0, 0, E28/$C$70) | G28: =F28*$T$5 | H28: 3 | I28: =$T$7*H28 | J28: =G28+$T$9+I28 | K28: =$T$4/64 | L28: 0 | M28: 0 | N28: 0 | O28: 0 | P28: 0 | Q28: 0 | R28: =(J28+K28+L28+M28+Q28+N28+O28+P28)*$B$2
A29: G8 | B29: Ranjithkumar R / Sameer (tenant) / Princy (tenant) | C29: 0 | D29: =SUM($C$3:$C$5)/64 | E29: =C29+D29 | F29: =IF($C$70=0, 0, E29/$C$70) | G29: =F29*$T$5 | H29: 3 | I29: =$T$7*H29 | J29: =G29+$T$9+I29 | K29: =$T$4/64 | L29: 0 | M29: 0 | N29: 0 | O29: 0 | P29: 0 | Q29: 0 | R29: =(J29+K29+L29+M29+Q29+N29+O29+P29)*$B$2
A30: G9 | B30: Chandramouli | C30: 0 | D30: =SUM($C$3:$C$5)/64 | E30: =C30+D30 | F30: =IF($C$70=0, 0, E30/$C$70) | G30: =F30*$T$5 | H30: 5 | I30: =$T$7*H30 | J30: =G30+$T$9+I30 | K30: =$T$4/64 | L30: 0 | M30: 0 | N30: 0 | O30: 0 | P30: 0 | Q30: 0 | R30: =(J30+K30+L30+M30+Q30+N30+O30+P30)*$B$2
... A69: T16 | B69: Madhusoodanan P.R. | C69: 0 | D69: =SUM($C$3:$C$5)/64 | E69: =C69+D69 | F69: =IF($C$70=0, 0, E69/$C$70) | G69: =F69*$T$5 | H69: 3 | I69: =$T$7*H69 | J69: =G69+$T$9+I69 | K69: =$T$4/64 | L69: 0 | M69: 0 | N69: 0 | O69: 0 | P69: 0 | Q69: 0 | R69: =(J69+K69+L69+M69+Q69+N69+O69+P69)*$B$2
A70: TOTAL | B70: TOTAL | C70: =SUM(C3:C69) | D70: =SUM(D3:D69) | E70: =SUM(E5:E69) | F70: =SUM(F6:F69) | G70: =SUM(G6:G69) | H70: =SUM(H3:H69) | I70: =SUM(I3:I69) | J70: =SUM(J6:J69) | K70: =SUM(K6:K69) | L70: =SUM(L6:L69) | M70: =SUM(M6:M69) | N70: =SUM(N6:N69) | O70: =SUM(O6:O69) | P70: =SUM(P6:P69) | Q70: =SUM(Q6:Q69) | R70: =SUM(R6:R69)

Sheet Apr2026-COLLECTION
A1: FLAT # | C1: Amount | D1: Date | E1: Amount | F1: Date | G1: Amount | H1: Date | I1: Amount | J1: Date | K1: Total
A2: F1 | B2: Shailesh Srivastava / Azeem Nawaz | K2: =SUM(C2,E2,G2,I2)
A3: F2 | B3: Shanthanu | K3: =SUM(C3,E3,G3,I3)
A4: F3 | B4: Samrat Kar | K4: =SUM(C4,E4,G4,I4)
A5: F4 | B5: Renu R | K5: =SUM(C5,E5,G5,I5)
A6: F5 | B6: Vamsidhar Bethanabatla / Madhuri Anumula | K6: =SUM(C6,E6,G6,I6)
A7: F6 | B7: Meghana Viral Shah and Vviral Shah (Owner) / Sangeet and Swagat (Tenent) | K7: =SUM(C7,E7,G7,I7)
A8: F7 | B8: Vimal NK | K8: =SUM(C8,E8,G8,I8)
A9: F8 | B9: Sujeet Kumar (Tenant)/Sreejith Menon (Owner) | K9: =SUM(C9,E9,G9,I9)
A10: F9 | B10: Vijay Suswaram (Owner) / Divya Shikha (Tenant) | K10: =SUM(C10,E10,G10,I10)
A11: F10 | B11: Aby Thomas | K11: =SUM(C11,E11,G11,I11)
A12: F11 | B12: N. Geetha | K12: =SUM(C12,E12,G12,I12)
A13: F12 | B13: Anirudh Singh | K13: =SUM(C13,E13,G13,I13)
... A65: T16 | B65: Madhusoodanan P.R. | K65: =SUM(C65,E65,G65,I65)
A66: TOTAL | K66: =SUM(K2:K65)

Sheet May2026-EXPENSE
A1: 1 | B1: MAY 2026 EXPENSES
A2: FLAT # | B2: 1 | C2: WATER USED IN LTRS | D2: COMMON AREA EQUALLY DEVIDED | E2: TOTAL FRESH WATER CONSUMED | F2: %OF TOTAL USED | G2: WATER EXPENSE SHARING BY % | H2: #METERS | I2: METER RENT | J2: VARIABLE EXPENSE = COMMON AREA METER RENT + WATER EXPENSE+ FLAT METER RENT | K2: FIXED EXPENSE SHARE | L2: PARKING FEE | M2: CLUB HOUSE BOOKING | N2: SHIFTING FEE | O2: GYM USAGE FEE | P2: POLYCARBONATE SHEET REPAIR | R2: TOTAL EXPENSE TO BE PAID
A3: CH | B3: MPFOWA | C3: 0 | D3: 0 | H3: 1 | I3: =T7
A4: GYM | B4: MPFOWA | C4: 0 | D4: 0 | H4: 1 | I4: =T7 | S4: TOTAL FIXED EXPENSE | T4: ='ANNUAL-EXPENSE-DETAILS'!BF4
A5: BSMT | B5: MPFOWA | C5: 0 | D5: 0 | H5: 1 | I5: =T7 | S5: TOTAL WATER EXPENSE | T5: ='ANNUAL-EXPENSE-DETAILS'!BE4
A6: F1 | B6: Shailesh Srivastava / Azeem Nawaz | C6: 0 | D6: =SUM($C$3:$C$5)/64 | E6: =C6+D6 | F6: =IF($C$70=0, 0, E6/$C$70) | G6: =F6*$T$5 | H6: 3 | I6: =$T$7*H6 | J6: =G6+$T$9+I6 | K6: =$T$4/64 | L6: 0 | M6: 0 | N6: 0 | O6: 0 | R6: =(SUM(J6:P6)*$B$2)
A7: F2 | B7: Shanthanu | C7: 0 | D7: =SUM($C$3:$C$5)/64 | E7: =C7+D7 | F7: =IF($C$70=0, 0, E7/$C$70) | G7: =F7*$T$5 | H7: 4 | I7: =$T$7*H7 | J7: =G7+$T$9+I7 | K7: =$T$4/64 | L7: 0 | M7: 0 | N7: 0 | O7: 0 | R7: =(SUM(J7:P7)*$B$2) | S7: RENT PER METER | T7: 117.81166
A8: F3 | B8: Samrat Kar | C8: 0 | D8: =SUM($C$3:$C$5)/64 | E8: =C8+D8 | F8: =IF($C$70=0, 0, E8/$C$70) | G8: =F8*$T$5 | H8: 4 | I8: =$T$7*H8 | J8: =G8+$T$9+I8 | K8: =$T$4/64 | L8: 0 | M8: 0 | N8: 0 | O8: 0 | R8: =(SUM(J8:P8)*$B$2) | S8: COMMON AREA METER RENT | T8: =$T$7*3
A9: F4 | B9: Renu R | C9: 0 | D9: =SUM($C$3:$C$5)/64 | E9: =C9+D9 | F9: =IF($C$70=0, 0, E9/$C$70) | G9: =F9*$T$5 | H9: 4 | I9: =$T$7*H9 | J9: =G9+$T$9+I9 | K9: =$T$4/64 | L9: 0 | M9: 0 | N9: 0 | O9: 0 | R9: =(SUM(J9:P9)*$B$2) | S9: COMMON AREA METER RENT/FLAT | T9: =T8/64
A10: F5 | B10: Vamsidhar Bethanabatla / Madhuri Anumula | C10: 0 | D10: =SUM($C$3:$C$5)/64 | E10: =C10+D10 | F10: =IF($C$70=0, 0, E10/$C$70) | G10: =F10*$T$5 | H10: 3 | I10: =$T$7*H10 | J10: =G10+$T$9+I10 | K10: =$T$4/64 | L10: 0 | M10: 0 | N10: 0 | O10: 0 | R10: =(SUM(J10:P10)*$B$2)
A11: F6 | B11: Meghana Viral Shah and Vviral Shah (Owner) / Sangeet and Swagat (Tenent) | C11: 0 | D11: =SUM($C$3:$C$5)/64 | E11: =C11+D11 | F11: =IF($C$70=0, 0, E11/$C$70) | G11: =F11*$T$5 | H11: 3 | I11: =$T$7*H11 | J11: =G11+$T$9+I11 | K11: =$T$4/64 | L11: 0 | M11: 0 | N11: 0 | O11: 0 | R11: =(SUM(J11:P11)*$B$2)
A12: F7 | B12: Vimal NK | C12: 0 | D12: =SUM($C$3:$C$5)/64 | E12: =C12+D12 | F12: =IF($C$70=0, 0, E12/$C$70) | G12: =F12*$T$5 | H12: 3 | I12: =$T$7*H12 | J12: =G12+$T$9+I12 | K12: =$T$4/64 | L12: 0 | M12: 0 | N12: 0 | O12: 0 | R12: =(SUM(J12:P12)*$B$2) | S12: BALANCE IN ACCOUNT TILL 31MAY2023
A13: F8 | B13: Sujeet Kumar (Tenant)/Sreejith Menon (Owner) | C13: 0 | D13: =SUM($C$3:$C$5)/64 | E13: =C13+D13 | F13: =IF($C$70=0, 0, E13/$C$70) | G13: =F13*$T$5 | H13: 3 | I13: =$T$7*H13 | J13: =G13+$T$9+I13 | K13: =$T$4/64 | L13: 0 | M13: 0 | N13: 0 | O13: 0 | R13: =(SUM(J13:P13)*$B$2) | S13: TOTAL NON MAINTENANCE CORPUS COLLECTION
A14: F9 | B14: Vijay Suswaram (Owner) / Divya Shikha (Tenant) | C14: 0 | D14: =SUM($C$3:$C$5)/64 | E14: =C14+D14 | F14: =IF($C$70=0, 0, E14/$C$70) | G14: =F14*$T$5 | H14: 4 | I14: =$T$7*H14 | J14: =G14+$T$9+I14 | K14: =$T$4/64 | L14: 0 | M14: 0 | N14: 0 | O14: 0 | R14: =(SUM(J14:P14)*$B$2) | S14: TOTAL FD DONE
A15: F10 | B15: Aby Thomas | C15: 0 | D15: =SUM($C$3:$C$5)/64 | E15: =C15+D15 | F15: =IF($C$70=0, 0, E15/$C$70) | G15: =F15*$T$5 | H15: 3 | I15: =$T$7*H15 | J15: =G15+$T$9+I15 | K15: =$T$4/64 | L15: 0 | M15: 0 | N15: 0 | O15: 0 | R15: =(SUM(J15:P15)*$B$2) | S15: Pending vendor payments
A16: F11 | B16: Niwin Anto | C16: 0 | D16: =SUM($C$3:$C$5)/64 | E16: =C16+D16 | F16: =IF($C$70=0, 0, E16/$C$70) | G16: =F16*$T$5 | H16: 3 | I16: =$T$7*H16 | J16: =G16+$T$9+I16 | K16: =$T$4/64 | L16: 0 | M16: 0 | N16: 0 | O16: 0 | R16: =(SUM(J16:P16)*$B$2) | S16: AMOUNT AVAILABLE FOR NON MAINTENANCE CORPUS | T16: =T13-T14
A17: F12 | B17: Anirudh Singh | C17: 0 | D17: =SUM($C$3:$C$5)/64 | E17: =C17+D17 | F17: =IF($C$70=0, 0, E17/$C$70) | G17: =F17*$T$5 | H17: 3 | I17: =$T$7*H17 | J17: =G17+$T$9+I17 | K17: =$T$4/64 | L17: 0 | M17: 0 | N17: 0 | O17: 0 | R17: =(SUM(J17:P17)*$B$2) | S17: AMOUNT AVAILABLE FOR MAINTENANCE | T17: =T12-T15-T16
A18: F13 | B18: Sanchay Saxena | C18: 0 | D18: =SUM($C$3:$C$5)/64 | E18: =C18+D18 | F18: =IF($C$70=0, 0, E18/$C$70) | G18: =F18*$T$5 | H18: 4 | I18: =$T$7*H18 | J18: =G18+$T$9+I18 | K18: =$T$4/64 | L18: 0 | M18: 0 | N18: 0 | O18: 0 | R18: =(SUM(J18:P18)*$B$2) | S18: Maintenance Deficit | T18: =T17-(T4+T5+23830)
A19: F14 | B19: Hemant Patel | C19: 0 | D19: =SUM($C$3:$C$5)/64 | E19: =C19+D19 | F19: =IF($C$70=0, 0, E19/$C$70) | G19: =F19*$T$5 | H19: 4 | I19: =$T$7*H19 | J19: =G19+$T$9+I19 | K19: =$T$4/64 | L19: 0 | M19: 0 | N19: 0 | O19: 0 | R19: =(SUM(J19:P19)*$B$2)
A20: F15 | B20: Senthil.Vijayaragavan | C20: 0 | D20: =SUM($C$3:$C$5)/64 | E20: =C20+D20 | F20: =IF($C$70=0, 0, E20/$C$70) | G20: =F20*$T$5 | H20: 4 | I20: =$T$7*H20 | J20: =G20+$T$9+I20 | K20: =$T$4/64 | L20: 0 | M20: 0 | N20: 0 | O20: 0 | R20: =(SUM(J20:P20)*$B$2)
A21: F16 | B21: Sreeja Sudharma | C21: 0 | D21: =SUM($C$3:$C$5)/64 | E21: =C21+D21 | F21: =IF($C$70=0, 0, E21/$C$70) | G21: =F21*$T$5 | H21: 3 | I21: =$T$7*H21 | J21: =G21+$T$9+I21 | K21: =$T$4/64 | L21: 0 | M21: 0 | N21: 0 | O21: 0 | R21: =(SUM(J21:P21)*$B$2)
A22: G1 | B22: Venkataramanan C | C22: 0 | D22: =SUM($C$3:$C$5)/64 | E22: =C22+D22 | F22: =IF($C$70=0, 0, E22/$C$70) | G22: =F22*$T$5 | H22: 3 | I22: =$T$7*H22 | J22: =G22+$T$9+I22 | K22: =$T$4/64 | L22: 0 | M22: 0 | N22: 0 | O22: 0 | R22: =(SUM(J22:P22)*$B$2)
A23: G2 | B23: Kaushik Kasibhatla | C23: 0 | D23: =SUM($C$3:$C$5)/64 | E23: =C23+D23 | F23: =IF($C$70=0, 0, E23/$C$70) | G23: =F23*$T$5 | H23: 4 | I23: =$T$7*H23 | J23: =G23+$T$9+I23 | K23: =$T$4/64 | L23: 0 | M23: 0 | N23: 0 | O23: 0 | R23: =(SUM(J23:P23)*$B$2)
A24: G3 | B24: Balakrishnan | C24: 0 | D24: =SUM($C$3:$C$5)/64 | E24: =C24+D24 | F24: =IF($C$70=0, 0, E24/$C$70) | G24: =F24*$T$5 | H24: 4 | I24: =$T$7*H24 | J24: =G24+$T$9+I24 | K24: =$T$4/64 | L24: 0 | M24: 0 | N24: 0 | O24: 0 | R24: =(SUM(J24:P24)*$B$2)
A25: G4 | B25: Ashwin Pandith | C25: 0 | D25: =SUM($C$3:$C$5)/64 | E25: =C25+D25 | F25: =IF($C$70=0, 0, E25/$C$70) | G25: =F25*$T$5 | H25: 4 | I25: =$T$7*H25 | J25: =G25+$T$9+I25 | K25: =$T$4/64 | L25: 0 | M25: 0 | N25: 0 | O25: 0 | R25: =(SUM(J25:P25)*$B$2)
A26: G5 | B26: Mayank Phophaliya | C26: 0 | D26: =SUM($C$3:$C$5)/64 | E26: =C26+D26 | F26: =IF($C$70=0, 0, E26/$C$70) | G26: =F26*$T$5 | H26: 3 | I26: =$T$7*H26 | J26: =G26+$T$9+I26 | K26: =$T$4/64 | L26: 0 | M26: 0 | N26: 0 | O26: 0 | R26: =(SUM(J26:P26)*$B$2)
A27: G6 | B27: Mohit Daga | C27: 0 | D27: =SUM($C$3:$C$5)/64 | E27: =C27+D27 | F27: =IF($C$70=0, 0, E27/$C$70) | G27: =F27*$T$5 | H27: 3 | I27: =$T$7*H27 | J27: =G27+$T$9+I27 | K27: =$T$4/64 | L27: 0 | M27: 0 | N27: 0 | O27: 0 | R27: =(SUM(J27:P27)*$B$2)
A28: G7 | B28: Prince Richfield | C28: 0 | D28: =SUM($C$3:$C$5)/64 | E28: =C28+D28 | F28: =IF($C$70=0, 0, E28/$C$70) | G28: =F28*$T$5 | H28: 3 | I28: =$T$7*H28 | J28: =G28+$T$9+I28 | K28: =$T$4/64 | L28: 0 | M28: 0 | N28: 0 | O28: 0 | R28: =(SUM(J28:P28)*$B$2)
A29: G8 | B29: Ranjithkumar R / Sameer (tenant) / Princy (tenant) | C29: 0 | D29: =SUM($C$3:$C$5)/64 | E29: =C29+D29 | F29: =IF($C$70=0, 0, E29/$C$70) | G29: =F29*$T$5 | H29: 3 | I29: =$T$7*H29 | J29: =G29+$T$9+I29 | K29: =$T$4/64 | L29: 0 | M29: 0 | N29: 0 | O29: 0 | R29: =(SUM(J29:P29)*$B$2)
A30: G9 | B30: Chandramouli | C30: 0 | D30: =SUM($C$3:$C$5)/64 | E30: =C30+D30 | F30: =IF($C$70=0, 0, E30/$C$70) | G30: =F30*$T$5 | H30: 5 | I30: =$T$7*H30 | J30: =G30+$T$9+I30 | K30: =$T$4/64 | L30: 0 | M30: 0 | N30: 0 | O30: 0 | R30: =(SUM(J30:P30)*$B$2)
... A69: T16 | B69: Madhusoodanan P.R. | C69: 0 | D69: =SUM($C$3:$C$5)/64 | E69: =C69+D69 | F69: =IF($C$70=0, 0, E69/$C$70) | G69: =F69*$T$5 | H69: 3 | I69: =$T$7*H69 | J69: =G69+$T$9+I69 | K69: =$T$4/64 | L69: 0 | M69: 0 | N69: 0 | O69: 0 | R69: =(SUM(J69:P69)*$B$2)
A70: TOTAL | B70: TOTAL | C70: =SUM(C3:C69) | D70: =SUM(D3:D69) | E70: =SUM(E5:E69) | F70: =SUM(F6:F69) | G70: =SUM(G6:G69) | H70: =SUM(H3:H69) | I70: =SUM(I3:I69) | J70: =SUM(J6:J69) | K70: =SUM(K6:K69) | L70: =SUM(L3:L69) | M70: =SUM(M3:M69) | N70: =SUM(N3:N69) | O70: =SUM(O3:O69) | P70: =SUM(P3:P69) | R70: =SUM(R3:R69)

Sheet May2026-COLLECTION
A1: FLAT # | C1: Amount | D1: Date | E1: Amount | F1: Date | G1: Amount | H1: Date | I1: Amount | J1: Date | K1: Total
A2: F1 | B2: Shailesh Srivastava / Azeem Nawaz | K2: =SUM(C2,E2,G2,I2)
A3: F2 | B3: Shanthanu | K3: =SUM(C3,E3,G3,I3)
A4: F3 | B4: Samrat Kar | K4: =SUM(C4,E4,G4,I4)
A5: F4 | B5: Renu R | K5: =SUM(C5,E5,G5,I5)
A6: F5 | B6: Vamsidhar Bethanabatla / Madhuri Anumula | K6: =SUM(C6,E6,G6,I6)
A7: F6 | B7: Meghana Viral Shah and Vviral Shah (Owner) / Sangeet and Swagat (Tenent) | K7: =SUM(C7,E7,G7,I7)
A8: F7 | B8: Vimal NK | K8: =SUM(C8,E8,G8,I8)
A9: F8 | B9: Sujeet Kumar (Tenant)/Sreejith Menon (Owner) | K9: =SUM(C9,E9,G9,I9)
A10: F9 | B10: Vijay Suswaram (Owner) / Divya Shikha (Tenant) | K10: =SUM(C10,E10,G10,I10)
A11: F10 | B11: Aby Thomas | K11: =SUM(C11,E11,G11,I11)
A12: F11 | B12: Niwin Anto | K12: =SUM(C12,E12,G12,I12)
A13: F12 | B13: Anirudh Singh | K13: =SUM(C13,E13,G13,I13)
... A65: T16 | B65: Madhusoodanan P.R. | K65: =SUM(C65,E65,G65,I65)
A66: TOTAL | K66: =SUM(K2:K65)

Sheet June2026-EXPENSE
B1: JUN 2026 EXPENSES
A2: FLAT # | B2: 1 | C2: WATER USED IN LTRS (L) | D2: COMMON AREA EQUALLY DEVIDED | E2: TOTAL FRESH WATER CONSUMED | F2: %OF TOTAL USED | G2: WATER EXPENSE SHARING BY % | H2: #METERS | I2: METER RENT | J2: VARIABLE EXPENSE = COMMON AREA METER RENT + WATER EXPENSE+ FLAT METER RENT | K2: FIXED EXPENSE SHARE | L2: PARKING FEE | M2: CLUB BOOKING FEE | N2: POLYCARBONATE PROJECT CANCELLATION CREDIT AMOUNT | O2: SHIFTING FEE | P2: GYM USAGE FEE | R2: TOTAL EXPENSE TO BE PAID
A3: CH | B3: MPFOWA | C3: 0 | D3: 0 | H3: 1 | I3: =H3*$T$7
A4: GYM | B4: MPFOWA | C4: 0 | D4: 0 | H4: 1 | I4: =H4*$T$7 | S4: TOTAL FIXED EXPENSE | T4: ='ANNUAL-EXPENSE-DETAILS'!BF5
A5: BSMT | B5: MPFOWA | C5: 0 | D5: 0 | H5: 1 | I5: =H5*$T$7 | S5: TOTAL WATER EXPENSE | T5: ='ANNUAL-EXPENSE-DETAILS'!BE5
A6: F1 | B6: Shailesh Srivastava / Azeem Nawaz | C6: 0 | D6: =SUM($C$3:$C$5)/64 | E6: =C6+D6 | F6: =IF($C$70=0, 0, E6/$C$70) | G6: =F6*$T$5 | H6: 3 | I6: =$T$7*H6 | J6: =G6+$T$9+I6 | K6: =$T$11/64 | L6: 0 | M6: 0 | O6: 0 | P6: 0 | R6: =(SUM(J6:P6))*$B$2
A7: F2 | B7: Shanthanu | C7: 0 | D7: =SUM($C$3:$C$5)/64 | E7: =C7+D7 | F7: =IF($C$70=0, 0, E7/$C$70) | G7: =F7*$T$5 | H7: 4 | I7: =$T$7*H7 | J7: =G7+$T$9+I7 | K7: =$T$11/64 | L7: 0 | M7: 0 | O7: 0 | P7: 0 | R7: =(SUM(J7:P7))*$B$2 | S7: RENT PER METER | T7: 117.81166
A8: F3 | B8: Samrat Kar | C8: 0 | D8: =SUM($C$3:$C$5)/64 | E8: =C8+D8 | F8: =IF($C$70=0, 0, E8/$C$70) | G8: =F8*$T$5 | H8: 4 | I8: =$T$7*H8 | J8: =G8+$T$9+I8 | K8: =$T$11/64 | L8: 0 | M8: 0 | O8: 0 | P8: 0 | R8: =(SUM(J8:P8))*$B$2 | S8: COMMON AREA METER RENT | T8: =$T$7*3
A9: F4 | B9: Renu R | C9: 0 | D9: =SUM($C$3:$C$5)/64 | E9: =C9+D9 | F9: =IF($C$70=0, 0, E9/$C$70) | G9: =F9*$T$5 | H9: 4 | I9: =$T$7*H9 | J9: =G9+$T$9+I9 | K9: =$T$11/64 | L9: 0 | M9: 0 | O9: 0 | P9: 0 | R9: =(SUM(J9:P9))*$B$2 | S9: COMMON AREA METER RENT/FLAT | T9: =T8/64
A10: F5 | B10: Vamsidhar Bethanabatla / Madhuri Anumula | C10: 0 | D10: =SUM($C$3:$C$5)/64 | E10: =C10+D10 | F10: =IF($C$70=0, 0, E10/$C$70) | G10: =F10*$T$5 | H10: 3 | I10: =$T$7*H10 | J10: =G10+$T$9+I10 | K10: =$T$11/64 | L10: 0 | M10: 0 | O10: 0 | P10: 0 | R10: =(SUM(J10:P10))*$B$2
A11: F6 | B11: Meghana Viral Shah and Vviral Shah (Owner) / Sangeet and Swagat (Tenent) | C11: 0 | D11: =SUM($C$3:$C$5)/64 | E11: =C11+D11 | F11: =IF($C$70=0, 0, E11/$C$70) | G11: =F11*$T$5 | H11: 3 | I11: =$T$7*H11 | J11: =G11+$T$9+I11 | K11: =$T$11/64 | L11: 0 | M11: 0 | O11: 0 | P11: 0 | R11: =(SUM(J11:P11))*$B$2 | S11: TOTAL FIXED EXPENSE | T11: ='ANNUAL-EXPENSE-DETAILS'!BF5
A12: F7 | B12: Vimal NK | C12: 0 | D12: =SUM($C$3:$C$5)/64 | E12: =C12+D12 | F12: =IF($C$70=0, 0, E12/$C$70) | G12: =F12*$T$5 | H12: 3 | I12: =$T$7*H12 | J12: =G12+$T$9+I12 | K12: =$T$11/64 | L12: 0 | M12: 0 | O12: 0 | P12: 0 | R12: =(SUM(J12:P12))*$B$2
A13: F8 | B13: Sujeet Kumar (Tenant)/Sreejith Menon (Owner) | C13: 0 | D13: =SUM($C$3:$C$5)/64 | E13: =C13+D13 | F13: =IF($C$70=0, 0, E13/$C$70) | G13: =F13*$T$5 | H13: 3 | I13: =$T$7*H13 | J13: =G13+$T$9+I13 | K13: =$T$11/64 | L13: 0 | M13: 0 | O13: 0 | P13: 0 | R13: =(SUM(J13:P13))*$B$2
A14: F9 | B14: Vijay Suswaram (Owner) / Divya Shikha (Tenant) | C14: 0 | D14: =SUM($C$3:$C$5)/64 | E14: =C14+D14 | F14: =IF($C$70=0, 0, E14/$C$70) | G14: =F14*$T$5 | H14: 4 | I14: =$T$7*H14 | J14: =G14+$T$9+I14 | K14: =$T$11/64 | L14: 0 | M14: 0 | O14: 0 | P14: 0 | R14: =(SUM(J14:P14))*$B$2 | S14: BALANCE IN ACCOUNT ON 30-JUN-2023
A15: F10 | B15: Aby Thomas | C15: 0 | D15: =SUM($C$3:$C$5)/64 | E15: =C15+D15 | F15: =IF($C$70=0, 0, E15/$C$70) | G15: =F15*$T$5 | H15: 3 | I15: =$T$7*H15 | J15: =G15+$T$9+I15 | K15: =$T$11/64 | L15: 0 | M15: 0 | O15: 0 | P15: 0 | R15: =(SUM(J15:P15))*$B$2 | S15: TOTAL NON MAINTENANCE CORPUS COLLECTION
A16: F11 | B16: Niwin Anto | C16: 0 | D16: =SUM($C$3:$C$5)/64 | E16: =C16+D16 | F16: =IF($C$70=0, 0, E16/$C$70) | G16: =F16*$T$5 | H16: 3 | I16: =$T$7*H16 | J16: =G16+$T$9+I16 | K16: =$T$11/64 | L16: 0 | M16: 0 | O16: 0 | P16: 0 | R16: =(SUM(J16:P16))*$B$2 | S16: TOTAL FD DONE
A17: F12 | B17: Anirudh Singh | C17: 0 | D17: =SUM($C$3:$C$5)/64 | E17: =C17+D17 | F17: =IF($C$70=0, 0, E17/$C$70) | G17: =F17*$T$5 | H17: 3 | I17: =$T$7*H17 | J17: =G17+$T$9+I17 | K17: =$T$11/64 | L17: 0 | M17: 0 | O17: 0 | P17: 0 | R17: =(SUM(J17:P17))*$B$2 | S17: AMOUNT AVAILABLE FOR NON MAINTENANCE CORPUS | T17: =T15-T16
A18: F13 | B18: Sanchay Saxena | C18: 0 | D18: =SUM($C$3:$C$5)/64 | E18: =C18+D18 | F18: =IF($C$70=0, 0, E18/$C$70) | G18: =F18*$T$5 | H18: 4 | I18: =$T$7*H18 | J18: =G18+$T$9+I18 | K18: =$T$11/64 | L18: 0 | M18: 0 | O18: 0 | P18: 0 | R18: =(SUM(J18:P18))*$B$2 | S18: AMOUNT AVAILABLE FOR MAINTENANCE | T18: =T14-T17
A19: F14 | B19: Hemant Patel | C19: 0 | D19: =SUM($C$3:$C$5)/64 | E19: =C19+D19 | F19: =IF($C$70=0, 0, E19/$C$70) | G19: =F19*$T$5 | H19: 4 | I19: =$T$7*H19 | J19: =G19+$T$9+I19 | K19: =$T$11/64 | L19: 0 | M19: 0 | O19: 0 | P19: 0 | R19: =(SUM(J19:P19))*$B$2
A20: F15 | B20: Senthil.Vijayaragavan | C20: 0 | D20: =SUM($C$3:$C$5)/64 | E20: =C20+D20 | F20: =IF($C$70=0, 0, E20/$C$70) | G20: =F20*$T$5 | H20: 4 | I20: =$T$7*H20 | J20: =G20+$T$9+I20 | K20: =$T$11/64 | L20: 0 | M20: 0 | O20: 0 | P20: 0 | R20: =(SUM(J20:P20))*$B$2
A21: F16 | B21: Sreeja Sudharma | C21: 0 | D21: =SUM($C$3:$C$5)/64 | E21: =C21+D21 | F21: =IF($C$70=0, 0, E21/$C$70) | G21: =F21*$T$5 | H21: 3 | I21: =$T$7*H21 | J21: =G21+$T$9+I21 | K21: =$T$11/64 | L21: 0 | M21: 0 | O21: 0 | P21: 0 | R21: =(SUM(J21:P21))*$B$2
A22: G1 | B22: Venkataramanan C | C22: 0 | D22: =SUM($C$3:$C$5)/64 | E22: =C22+D22 | F22: =IF($C$70=0, 0, E22/$C$70) | G22: =F22*$T$5 | H22: 3 | I22: =$T$7*H22 | J22: =G22+$T$9+I22 | K22: =$T$11/64 | L22: 0 | M22: 0 | O22: 0 | P22: 0 | R22: =(SUM(J22:P22))*$B$2
A23: G2 | B23: Kaushik Kasibhatla | C23: 0 | D23: =SUM($C$3:$C$5)/64 | E23: =C23+D23 | F23: =IF($C$70=0, 0, E23/$C$70) | G23: =F23*$T$5 | H23: 4 | I23: =$T$7*H23 | J23: =G23+$T$9+I23 | K23: =$T$11/64 | L23: 0 | M23: 0 | O23: 0 | P23: 0 | R23: =(SUM(J23:P23))*$B$2
A24: G3 | B24: Balakrishnan | C24: 0 | D24: =SUM($C$3:$C$5)/64 | E24: =C24+D24 | F24: =IF($C$70=0, 0, E24/$C$70) | G24: =F24*$T$5 | H24: 4 | I24: =$T$7*H24 | J24: =G24+$T$9+I24 | K24: =$T$11/64 | L24: 0 | M24: 0 | O24: 0 | P24: 0 | R24: =(SUM(J24:P24))*$B$2
A25: G4 | B25: Ashwin Pandith | C25: 0 | D25: =SUM($C$3:$C$5)/64 | E25: =C25+D25 | F25: =IF($C$70=0, 0, E25/$C$70) | G25: =F25*$T$5 | H25: 4 | I25: =$T$7*H25 | J25: =G25+$T$9+I25 | K25: =$T$11/64 | L25: 0 | M25: 0 | O25: 0 | P25: 0 | R25: =(SUM(J25:P25))*$B$2
A26: G5 | B26: Mayank Phophaliya | C26: 0 | D26: =SUM($C$3:$C$5)/64 | E26: =C26+D26 | F26: =IF($C$70=0, 0, E26/$C$70) | G26: =F26*$T$5 | H26: 3 | I26: =$T$7*H26 | J26: =G26+$T$9+I26 | K26: =$T$11/64 | L26: 0 | M26: 0 | O26: 0 | P26: 0 | R26: =(SUM(J26:P26))*$B$2
A27: G6 | B27: Mohit Daga | C27: 0 | D27: =SUM($C$3:$C$5)/64 | E27: =C27+D27 | F27: =IF($C$70=0, 0, E27/$C$70) | G27: =F27*$T$5 | H27: 3 | I27: =$T$7*H27 | J27: =G27+$T$9+I27 | K27: =$T$11/64 | L27: 0 | M27: 0 | O27: 0 | P27: 0 | R27: =(SUM(J27:P27))*$B$2
A28: G7 | B28: Prince Richfield | C28: 0 | D28: =SUM($C$3:$C$5)/64 | E28: =C28+D28 | F28: =IF($C$70=0, 0, E28/$C$70) | G28: =F28*$T$5 | H28: 3 | I28: =$T$7*H28 | J28: =G28+$T$9+I28 | K28: =$T$11/64 | L28: 0 | M28: 0 | O28: 0 | P28: 0 | R28: =(SUM(J28:P28))*$B$2
A29: G8 | B29: Ranjithkumar R / Sameer (tenant) / Princy (tenant) | C29: 0 | D29: =SUM($C$3:$C$5)/64 | E29: =C29+D29 | F29: =IF($C$70=0, 0, E29/$C$70) | G29: =F29*$T$5 | H29: 3 | I29: =$T$7*H29 | J29: =G29+$T$9+I29 | K29: =$T$11/64 | L29: 0 | M29: 0 | O29: 0 | P29: 0 | R29: =(SUM(J29:P29))*$B$2
A30: G9 | B30: Chandramouli | C30: 0 | D30: =SUM($C$3:$C$5)/64 | E30: =C30+D30 | F30: =IF($C$70=0, 0, E30/$C$70) | G30: =F30*$T$5 | H30: 5 | I30: =$T$7*H30 | J30: =G30+$T$9+I30 | K30: =$T$11/64 | L30: 0 | M30: 0 | O30: 0 | P30: 0 | R30: =(SUM(J30:P30))*$B$2
... A69: T16 | B69: Madhusoodanan P.R. | C69: 0 | D69: =SUM($C$3:$C$5)/64 | E69: =C69+D69 | F69: =IF($C$70=0, 0, E69/$C$70) | G69: =F69*$T$5 | H69: 3 | I69: =$T$7*H69 | J69: =G69+$T$9+I69 | K69: =$T$11/64 | L69: 0 | M69: 0 | O69: 0 | P69: 0 | R69: =(SUM(J69:P69))*$B$2
B70: TOTAL | C70: =SUM(C3:C69) | D70: =SUM(D3:D69) | E70: =SUM(E3:E69) | F70: =IF($C$70=0, 0, E70/$C$70) | G70: =SUM(G3:G69) | H70: =SUM(H3:H69) | I70: =SUM(I3:I69) | J70: =SUM(J3:J69) | K70: =SUM(K3:K69) | L70: =SUM(L3:L69) | M70: =SUM(M3:M69) | N70: =SUM(N3:N69) | ... P70: =SUM(P3:P69) | R70: =SUM(R3:R69)

Sheet June2026-COLLECTION
A1: FLAT # | C1: Amount | D1: Date | E1: Amount | F1: Date | G1: Amount | H1: Date | I1: Amount | J1: Date | K1: Total
A2: F1 | B2: Shailesh Srivastava / Azeem Nawaz | K2: =SUM(C2,E2,G2,I2)
A3: F2 | B3: Shanthanu | K3: =SUM(C3,E3,G3,I3)
A4: F3 | B4: Samrat Kar | K4: =SUM(C4,E4,G4,I4)
A5: F4 | B5: Renu R | K5: =SUM(C5,E5,G5,I5)
A6: F5 | B6: Vamsidhar Bethanabatla / Madhuri Anumula | K6: =SUM(C6,E6,G6,I6)
A7: F6 | B7: Meghana Viral Shah and Vviral Shah (Owner) / Sangeet and Swagat (Tenent) | K7: =SUM(C7,E7,G7,I7)
A8: F7 | B8: Vimal NK | K8: =SUM(C8,E8,G8,I8)
A9: F8 | B9: Sujeet Kumar (Tenant)/Sreejith Menon (Owner) | K9: =SUM(C9,E9,G9,I9)
A10: F9 | B10: Vijay Suswaram (Owner) / Divya Shikha (Tenant) | K10: =SUM(C10,E10,G10,I10)
A11: F10 | B11: Aby Thomas | K11: =SUM(C11,E11,G11,I11)
A12: F11 | B12: Niwin Anto | K12: =SUM(C12,E12,G12,I12)
A13: F12 | B13: Anirudh Singh | K13: =SUM(C13,E13,G13,I13)
... A65: T16 | B65: Madhusoodanan P.R. | K65: =SUM(C65,E65,G65,I65)
A66: TOTAL | K66: =SUM(K2:K65)

Sheet July2026-EXPENSE
B1: JUL 2026 EXPENSES
A2: FLAT # | B2: 1 | C2: WATER USED IN LTRS | D2: COMMON AREA EQUALLY DEVIDED | E2: TOTAL FRESH WATER CONSUMED | F2: %OF TOTAL USED | G2: WATER EXPENSE SHARING BY % | H2: #METERS | I2: METER RENT | J2: VARIABLE EXPENSE = COMMON AREA METER RENT + WATER EXPENSE+ FLAT METER RENT | K2: FIXED EXPENSE SHARE | L2: PARKING FEE | M2: CLUB BOOKING FEE | N2: SHIFTING FEE | O2: GYM USAGE FEE | R2: TOTAL EXPENSE TO BE PAID
A3: CH | B3: MPFOWA | C3: 0 | D3: 0 | H3: 1 | I3: =T7
A4: GYM | B4: MPFOWA | C4: 0 | D4: 0 | H4: 1 | I4: =T7 | S4: TOTAL FIXED EXPENSE | T4: ='ANNUAL-EXPENSE-DETAILS'!BF6
A5: BSMT | B5: MPFOWA | C5: 0 | D5: 0 | H5: 1 | I5: =T7 | S5: TOTAL WATER EXPENSE | T5: ='ANNUAL-EXPENSE-DETAILS'!BE6
A6: F1 | B6: Shailesh Srivastava / Azeem Nawaz | C6: 0 | D6: =SUM($C$3:$C$5)/64 | E6: =C6+D6 | F6: =IF($C$70=0, 0, E6/$C$70) | G6: =F6*$T$5 | H6: 3 | I6: =$T$7*H6 | J6: =G6+$T$9+I6 | K6: =$T$11/64 | L6: 0 | M6: 0 | N6: 0 | O6: 0 | R6: =(J6+K6+L6+M6+N6+O6)*$B$2
A7: F2 | B7: Shanthanu | C7: 0 | D7: =SUM($C$3:$C$5)/64 | E7: =C7+D7 | F7: =IF($C$70=0, 0, E7/$C$70) | G7: =F7*$T$5 | H7: 4 | I7: =$T$7*H7 | J7: =G7+$T$9+I7 | K7: =$T$11/64 | L7: 0 | M7: 0 | N7: 0 | O7: 0 | R7: =(J7+K7+L7+M7+N7+O7)*$B$2 | S7: RENT PER METER | T7: 117.81166
A8: F3 | B8: Samrat Kar | C8: 0 | D8: =SUM($C$3:$C$5)/64 | E8: =C8+D8 | F8: =IF($C$70=0, 0, E8/$C$70) | G8: =F8*$T$5 | H8: 4 | I8: =$T$7*H8 | J8: =G8+$T$9+I8 | K8: =$T$11/64 | L8: 0 | M8: 0 | N8: 0 | O8: 0 | R8: =(J8+K8+L8+M8+N8+O8)*$B$2 | S8: COMMON AREA METER RENT | T8: =$T$7*3
A9: F4 | B9: Renu R | C9: 0 | D9: =SUM($C$3:$C$5)/64 | E9: =C9+D9 | F9: =IF($C$70=0, 0, E9/$C$70) | G9: =F9*$T$5 | H9: 4 | I9: =$T$7*H9 | J9: =G9+$T$9+I9 | K9: =$T$11/64 | L9: 0 | M9: 0 | N9: 0 | O9: 0 | R9: =(J9+K9+L9+M9+N9+O9)*$B$2 | S9: COMMON AREA METER RENT/FLAT | T9: =T8/64
A10: F5 | B10: Vamsidhar Bethanabatla / Madhuri Anumula | C10: 0 | D10: =SUM($C$3:$C$5)/64 | E10: =C10+D10 | F10: =IF($C$70=0, 0, E10/$C$70) | G10: =F10*$T$5 | H10: 3 | I10: =$T$7*H10 | J10: =G10+$T$9+I10 | K10: =$T$11/64 | L10: 0 | M10: 0 | N10: 0 | O10: 0 | R10: =(J10+K10+L10+M10+N10+O10)*$B$2
A11: F6 | B11: Meghana Viral Shah and Vviral Shah (Owner) / Sangeet and Swagat (Tenent) | C11: 0 | D11: =SUM($C$3:$C$5)/64 | E11: =C11+D11 | F11: =IF($C$70=0, 0, E11/$C$70) | G11: =F11*$T$5 | H11: 3 | I11: =$T$7*H11 | J11: =G11+$T$9+I11 | K11: =$T$11/64 | L11: 0 | M11: 0 | N11: 0 | O11: 0 | R11: =(J11+K11+L11+M11+N11+O11)*$B$2 | S11: TOTAL FIXED EXPENSE | T11: ='ANNUAL-EXPENSE-DETAILS'!BF6
A12: F7 | B12: Vimal NK | C12: 0 | D12: =SUM($C$3:$C$5)/64 | E12: =C12+D12 | F12: =IF($C$70=0, 0, E12/$C$70) | G12: =F12*$T$5 | H12: 3 | I12: =$T$7*H12 | J12: =G12+$T$9+I12 | K12: =$T$11/64 | L12: 0 | M12: 0 | N12: 0 | O12: 0 | R12: =(J12+K12+L12+M12+N12+O12)*$B$2
A13: F8 | B13: Sujeet Kumar (Tenant)/Sreejith Menon (Owner) | C13: 0 | D13: =SUM($C$3:$C$5)/64 | E13: =C13+D13 | F13: =IF($C$70=0, 0, E13/$C$70) | G13: =F13*$T$5 | H13: 3 | I13: =$T$7*H13 | J13: =G13+$T$9+I13 | K13: =$T$11/64 | L13: 0 | M13: 0 | N13: 0 | O13: 0 | R13: =(J13+K13+L13+M13+N13+O13)*$B$2
A14: F9 | B14: Vijay Suswaram (Owner) / Divya Shikha (Tenant) | C14: 0 | D14: =SUM($C$3:$C$5)/64 | E14: =C14+D14 | F14: =IF($C$70=0, 0, E14/$C$70) | G14: =F14*$T$5 | H14: 4 | I14: =$T$7*H14 | J14: =G14+$T$9+I14 | K14: =$T$11/64 | L14: 0 | M14: 0 | N14: 0 | O14: 0 | R14: =(J14+K14+L14+M14+N14+O14)*$B$2 | S14: BALANCE IN ACCOUNT ON 31-JULY-2023
A15: F10 | B15: Aby Thomas | C15: 0 | D15: =SUM($C$3:$C$5)/64 | E15: =C15+D15 | F15: =IF($C$70=0, 0, E15/$C$70) | G15: =F15*$T$5 | H15: 3 | I15: =$T$7*H15 | J15: =G15+$T$9+I15 | K15: =$T$11/64 | L15: 0 | M15: 0 | N15: 0 | O15: 0 | R15: =(J15+K15+L15+M15+N15+O15)*$B$2 | S15: TOTAL NON MAINTENANCE CORPUS COLLECTION
A16: F11 | B16: Niwin Anto | C16: 0 | D16: =SUM($C$3:$C$5)/64 | E16: =C16+D16 | F16: =IF($C$70=0, 0, E16/$C$70) | G16: =F16*$T$5 | H16: 3 | I16: =$T$7*H16 | J16: =G16+$T$9+I16 | K16: =$T$11/64 | L16: 0 | M16: 0 | N16: 0 | O16: 0 | R16: =(J16+K16+L16+M16+N16+O16)*$B$2 | S16: TOTAL FD DONE
A17: F12 | B17: Anirudh Singh | C17: 0 | D17: =SUM($C$3:$C$5)/64 | E17: =C17+D17 | F17: =IF($C$70=0, 0, E17/$C$70) | G17: =F17*$T$5 | H17: 3 | I17: =$T$7*H17 | J17: =G17+$T$9+I17 | K17: =$T$11/64 | L17: 0 | M17: 0 | N17: 0 | O17: 0 | R17: =(J17+K17+L17+M17+N17+O17)*$B$2 | S17: AMOUNT AVAILABLE FOR NON MAINTENANCE CORPUS | T17: =T15-T16
A18: F13 | B18: Sanchay Saxena | C18: 0 | D18: =SUM($C$3:$C$5)/64 | E18: =C18+D18 | F18: =IF($C$70=0, 0, E18/$C$70) | G18: =F18*$T$5 | H18: 4 | I18: =$T$7*H18 | J18: =G18+$T$9+I18 | K18: =$T$11/64 | L18: 0 | M18: 0 | N18: 0 | O18: 0 | R18: =(J18+K18+L18+M18+N18+O18)*$B$2 | S18: AMOUNT AVAILABLE FOR MAINTENANCE | T18: =T14-T17
A19: F14 | B19: Hemant Patel | C19: 0 | D19: =SUM($C$3:$C$5)/64 | E19: =C19+D19 | F19: =IF($C$70=0, 0, E19/$C$70) | G19: =F19*$T$5 | H19: 4 | I19: =$T$7*H19 | J19: =G19+$T$9+I19 | K19: =$T$11/64 | L19: 0 | M19: 0 | N19: 0 | O19: 0 | R19: =(J19+K19+L19+M19+N19+O19)*$B$2
A20: F15 | B20: Senthil.Vijayaragavan | C20: 0 | D20: =SUM($C$3:$C$5)/64 | E20: =C20+D20 | F20: =IF($C$70=0, 0, E20/$C$70) | G20: =F20*$T$5 | H20: 4 | I20: =$T$7*H20 | J20: =G20+$T$9+I20 | K20: =$T$11/64 | L20: 0 | M20: 0 | N20: 0 | O20: 0 | R20: =(J20+K20+L20+M20+N20+O20)*$B$2
A21: F16 | B21: Sreeja Sudharma | C21: 0 | D21: =SUM($C$3:$C$5)/64 | E21: =C21+D21 | F21: =IF($C$70=0, 0, E21/$C$70) | G21: =F21*$T$5 | H21: 3 | I21: =$T$7*H21 | J21: =G21+$T$9+I21 | K21: =$T$11/64 | L21: 0 | M21: 0 | N21: 0 | O21: 0 | R21: =(J21+K21+L21+M21+N21+O21)*$B$2
A22: G1 | B22: Venkataramanan C | C22: 0 | D22: =SUM($C$3:$C$5)/64 | E22: =C22+D22 | F22: =IF($C$70=0, 0, E22/$C$70) | G22: =F22*$T$5 | H22: 3 | I22: =$T$7*H22 | J22: =G22+$T$9+I22 | K22: =$T$11/64 | L22: 0 | M22: 0 | N22: 0 | O22: 0 | R22: =(J22+K22+L22+M22+N22+O22)*$B$2
A23: G2 | B23: Kaushik Kasibhatla | C23: 0 | D23: =SUM($C$3:$C$5)/64 | E23: =C23+D23 | F23: =IF($C$70=0, 0, E23/$C$70) | G23: =F23*$T$5 | H23: 4 | I23: =$T$7*H23 | J23: =G23+$T$9+I23 | K23: =$T$11/64 | L23: 0 | M23: 0 | N23: 0 | O23: 0 | R23: =(J23+K23+L23+M23+N23+O23)*$B$2
A24: G3 | B24: Balakrishnan | C24: 0 | D24: =SUM($C$3:$C$5)/64 | E24: =C24+D24 | F24: =IF($C$70=0, 0, E24/$C$70) | G24: =F24*$T$5 | H24: 4 | I24: =$T$7*H24 | J24: =G24+$T$9+I24 | K24: =$T$11/64 | L24: 0 | M24: 0 | N24: 0 | O24: 0 | R24: =(J24+K24+L24+M24+N24+O24)*$B$2
A25: G4 | B25: Ashwin Pandith | C25: 0 | D25: =SUM($C$3:$C$5)/64 | E25: =C25+D25 | F25: =IF($C$70=0, 0, E25/$C$70) | G25: =F25*$T$5 | H25: 4 | I25: =$T$7*H25 | J25: =G25+$T$9+I25 | K25: =$T$11/64 | L25: 0 | M25: 0 | N25: 0 | O25: 0 | R25: =(J25+K25+L25+M25+N25+O25)*$B$2
A26: G5 | B26: Mayank Phophaliya | C26: 0 | D26: =SUM($C$3:$C$5)/64 | E26: =C26+D26 | F26: =IF($C$70=0, 0, E26/$C$70) | G26: =F26*$T$5 | H26: 3 | I26: =$T$7*H26 | J26: =G26+$T$9+I26 | K26: =$T$11/64 | L26: 0 | M26: 0 | N26: 0 | O26: 0 | R26: =(J26+K26+L26+M26+N26+O26)*$B$2
A27: G6 | B27: Mohit Daga | C27: 0 | D27: =SUM($C$3:$C$5)/64 | E27: =C27+D27 | F27: =IF($C$70=0, 0, E27/$C$70) | G27: =F27*$T$5 | H27: 3 | I27: =$T$7*H27 | J27: =G27+$T$9+I27 | K27: =$T$11/64 | L27: 0 | M27: 0 | N27: 0 | O27: 0 | R27: =(J27+K27+L27+M27+N27+O27)*$B$2
A28: G7 | B28: Prince Richfield | C28: 0 | D28: =SUM($C$3:$C$5)/64 | E28: =C28+D28 | F28: =IF($C$70=0, 0, E28/$C$70) | G28: =F28*$T$5 | H28: 3 | I28: =$T$7*H28 | J28: =G28+$T$9+I28 | K28: =$T$11/64 | L28: 0 | M28: 0 | N28: 0 | O28: 0 | R28: =(J28+K28+L28+M28+N28+O28)*$B$2
A29: G8 | B29: Ranjithkumar R / Sameer (tenant) / Princy (tenant) | C29: 0 | D29: =SUM($C$3:$C$5)/64 | E29: =C29+D29 | F29: =IF($C$70=0, 0, E29/$C$70) | G29: =F29*$T$5 | H29: 3 | I29: =$T$7*H29 | J29: =G29+$T$9+I29 | K29: =$T$11/64 | L29: 0 | M29: 0 | N29: 0 | O29: 0 | R29: =(J29+K29+L29+M29+N29+O29)*$B$2
A30: G9 | B30: Chandramouli | C30: 0 | D30: =SUM($C$3:$C$5)/64 | E30: =C30+D30 | F30: =IF($C$70=0, 0, E30/$C$70) | G30: =F30*$T$5 | H30: 5 | I30: =$T$7*H30 | J30: =G30+$T$9+I30 | K30: =$T$11/64 | L30: 0 | M30: 0 | N30: 0 | O30: 0 | R30: =(J30+K30+L30+M30+N30+O30)*$B$2
... A69: T16 | B69: Madhusoodanan P.R. | C69: 0 | D69: =SUM($C$3:$C$5)/64 | E69: =C69+D69 | F69: =IF($C$70=0, 0, E69/$C$70) | G69: =F69*$T$5 | H69: 3 | I69: =$T$7*H69 | J69: =G69+$T$9+I69 | K69: =$T$11/64 | L69: 0 | M69: 0 | N69: 0 | O69: 0 | R69: =(J69+K69+L69+M69+N69+O69)*$B$2
B70: TOTAL | C70: =SUM(C3:C69) | D70: =SUM(D3:D69) | E70: =SUM(E3:E69) | F70: =SUM(F3:F69) | G70: =SUM(G3:G69) | H70: =SUM(H3:H69) | I70: =SUM(I3:I69) | J70: =SUM(J3:J69) | ... O70: =SUM(O3:O69) | R70: =SUM(R3:R69)

Sheet July2026-EXPENSE-Flatwise
A1: Expense Head | C1: {=TRANSPOSE('INCOME-EXPENSE-CYCLES'!A3:A66)} | D1: F2 | E1: F3 | F1: F4 | G1: F5 | H1: F6 | I1: F7 | J1: F8 | K1: F9 | L1: F10 | M1: F11 | N1: F12 | O1: F13 | P1: F14 | Q1: F15 | R1: F16 | S1: G1 | T1: G2 | U1: G3 | V1: G4 | W1: G5 | X1: G6 | Y1: G7 | Z1: G8 | AA1: G9 | AB1: G10 | AC1: G11 | AD1: G12 | AE1: G13 | AF1: G14 | AG1: G15 | AH1: G16 | AI1: S1 | AJ1: S2 | AK1: S3 | AL1: S4 | AM1: S5 | AN1: S6 | AO1: S7 | AP1: S8 | AQ1: S9 | AR1: S10 | AS1: S11 | AT1: S12 | AU1: S13 | AV1: S14 | AW1: S15 | AX1: S16 | AY1: T1 | AZ1: T2 | BA1: T3 | BB1: T4 | BC1: T5 | BD1: T6 | BE1: T7 | BF1: T8 | BG1: T9 | BH1: T10 | BI1: T11 | BJ1: T12 | BK1: T13 | BL1: T14 | BM1: T15 | BN1: T16
A2: Water consumption (Litres) | C2: {=TRANSPOSE('July2026-EXPENSE'!E6:E69)} | D2: 0 | E2: 0 | F2: 0 | G2: 0 | H2: 0 | I2: 0 | J2: 0 | K2: 0 | L2: 0 | M2: 0 | N2: 0 | O2: 0 | P2: 0 | Q2: 0 | R2: 0 | S2: 0 | T2: 0 | U2: 0 | V2: 0 | W2: 0 | X2: 0 | Y2: 0 | Z2: 0 | AA2: 0 | AB2: 0 | AC2: 0 | AD2: 0 | AE2: 0 | AF2: 0 | AG2: 0 | AH2: 0 | AI2: 0 | AJ2: 0 | AK2: 0 | AL2: 0 | AM2: 0 | AN2: 0 | AO2: 0 | AP2: 0 | AQ2: 0 | AR2: 0 | AS2: 0 | AT2: 0 | AU2: 0 | AV2: 0 | AW2: 0 | AX2: 0 | AY2: 0 | AZ2: 0 | BA2: 0 | BB2: 0 | BC2: 0 | BD2: 0 | BE2: 0 | BF2: 0 | BG2: 0 | BH2: 0 | BI2: 0 | BJ2: 0 | BK2: 0 | BL2: 0 | BM2: 0 | BN2: 0
A3: Water consumption (%age of total) | C3: {=TRANSPOSE('July2026-EXPENSE'!F6:F69)} | D3: 0 | E3: 0 | F3: 0 | G3: 0 | H3: 0 | I3: 0 | J3: 0 | K3: 0 | L3: 0 | M3: 0 | N3: 0 | O3: 0 | P3: 0 | Q3: 0 | R3: 0 | S3: 0 | T3: 0 | U3: 0 | V3: 0 | W3: 0 | X3: 0 | Y3: 0 | Z3: 0 | AA3: 0 | AB3: 0 | AC3: 0 | AD3: 0 | AE3: 0 | AF3: 0 | AG3: 0 | AH3: 0 | AI3: 0 | AJ3: 0 | AK3: 0 | AL3: 0 | AM3: 0 | AN3: 0 | AO3: 0 | AP3: 0 | AQ3: 0 | AR3: 0 | AS3: 0 | AT3: 0 | AU3: 0 | AV3: 0 | AW3: 0 | AX3: 0 | AY3: 0 | AZ3: 0 | BA3: 0 | BB3: 0 | BC3: 0 | BD3: 0 | BE3: 0 | BF3: 0 | BG3: 0 | BH3: 0 | BI3: 0 | BJ3: 0 | BK3: 0 | BL3: 0 | BM3: 0 | BN3: 0
A4: Water meter rent | C4: {=TRANSPOSE('July2026-EXPENSE'!I6:I69)} | D4: 0 | E4: 0 | F4: 0 | G4: 0 | H4: 0 | I4: 0 | J4: 0 | K4: 0 | L4: 0 | M4: 0 | N4: 0 | O4: 0 | P4: 0 | Q4: 0 | R4: 0 | S4: 0 | T4: 0 | U4: 0 | V4: 0 | W4: 0 | X4: 0 | Y4: 0 | Z4: 0 | AA4: 0 | AB4: 0 | AC4: 0 | AD4: 0 | AE4: 0 | AF4: 0 | AG4: 0 | AH4: 0 | AI4: 0 | AJ4: 0 | AK4: 0 | AL4: 0 | AM4: 0 | AN4: 0 | AO4: 0 | AP4: 0 | AQ4: 0 | AR4: 0 | AS4: 0 | AT4: 0 | AU4: 0 | AV4: 0 | AW4: 0 | AX4: 0 | AY4: 0 | AZ4: 0 | BA4: 0 | BB4: 0 | BC4: 0 | BD4: 0 | BE4: 0 | BF4: 0 | BG4: 0 | BH4: 0 | BI4: 0 | BJ4: 0 | BK4: 0 | BL4: 0 | BM4: 0 | BN4: 0
A5: Common meter rent (eq. distributed) | C5: ='July2026-EXPENSE'!$T$9 | D5: ='July2026-EXPENSE'!$T$9 | E5: ='July2026-EXPENSE'!$T$9 | F5: ='July2026-EXPENSE'!$T$9 | G5: ='July2026-EXPENSE'!$T$9 | H5: ='July2026-EXPENSE'!$T$9 | I5: ='July2026-EXPENSE'!$T$9 | J5: ='July2026-EXPENSE'!$T$9 | ... BN5: ='July2026-EXPENSE'!$T$9
A6: Total water related expense | C6: {=TRANSPOSE('July2026-EXPENSE'!J6:J69)} | D6: 0 | E6: 0 | F6: 0 | G6: 0 | H6: 0 | I6: 0 | J6: 0 | K6: 0 | L6: 0 | M6: 0 | N6: 0 | O6: 0 | P6: 0 | Q6: 0 | R6: 0 | S6: 0 | T6: 0 | U6: 0 | V6: 0 | W6: 0 | X6: 0 | Y6: 0 | Z6: 0 | AA6: 0 | AB6: 0 | AC6: 0 | AD6: 0 | AE6: 0 | AF6: 0 | AG6: 0 | AH6: 0 | AI6: 0 | AJ6: 0 | AK6: 0 | AL6: 0 | AM6: 0 | AN6: 0 | AO6: 0 | AP6: 0 | AQ6: 0 | AR6: 0 | AS6: 0 | AT6: 0 | AU6: 0 | AV6: 0 | AW6: 0 | AX6: 0 | AY6: 0 | AZ6: 0 | BA6: 0 | BB6: 0 | BC6: 0 | BD6: 0 | BE6: 0 | BF6: 0 | BG6: 0 | BH6: 0 | BI6: 0 | BJ6: 0 | BK6: 0 | BL6: 0 | BM6: 0 | BN6: 0
A7: Society Parking Rent | C7: {=TRANSPOSE('July2026-EXPENSE'!L6:L69)} | D7: 0 | E7: 0 | F7: 0 | G7: 0 | H7: 0 | I7: 0 | J7: 0 | K7: 0 | L7: 0 | M7: 0 | N7: 0 | O7: 0 | P7: 0 | Q7: 0 | R7: 0 | S7: 0 | T7: 0 | U7: 0 | V7: 0 | W7: 0 | X7: 0 | Y7: 0 | Z7: 0 | AA7: 0 | AB7: 0 | AC7: 0 | AD7: 0 | AE7: 0 | AF7: 0 | AG7: 0 | AH7: 0 | AI7: 0 | AJ7: 0 | AK7: 0 | AL7: 0 | AM7: 0 | AN7: 0 | AO7: 0 | AP7: 0 | AQ7: 0 | AR7: 0 | AS7: 0 | AT7: 0 | AU7: 0 | AV7: 0 | AW7: 0 | AX7: 0 | AY7: 0 | AZ7: 0 | BA7: 0 | BB7: 0 | BC7: 0 | BD7: 0 | BE7: 0 | BF7: 0 | BG7: 0 | BH7: 0 | BI7: 0 | BJ7: 0 | BK7: 0 | BL7: 0 | BM7: 0 | BN7: 0
A8: Clubhouse booking fee | C8: {=TRANSPOSE('July2026-EXPENSE'!M6:M69)} | D8: 0 | E8: 0 | F8: 0 | G8: 0 | H8: 0 | I8: 0 | J8: 0 | K8: 0 | L8: 0 | M8: 0 | N8: 0 | O8: 0 | P8: 0 | Q8: 0 | R8: 0 | S8: 0 | T8: 0 | U8: 0 | V8: 0 | W8: 0 | X8: 0 | Y8: 0 | Z8: 0 | AA8: 0 | AB8: 0 | AC8: 0 | AD8: 0 | AE8: 0 | AF8: 0 | AG8: 0 | AH8: 0 | AI8: 0 | AJ8: 0 | AK8: 0 | AL8: 0 | AM8: 0 | AN8: 0 | AO8: 0 | AP8: 0 | AQ8: 0 | AR8: 0 | AS8: 0 | AT8: 0 | AU8: 0 | AV8: 0 | AW8: 0 | AX8: 0 | AY8: 0 | AZ8: 0 | BA8: 0 | BB8: 0 | BC8: 0 | BD8: 0 | BE8: 0 | BF8: 0 | BG8: 0 | BH8: 0 | BI8: 0 | BJ8: 0 | BK8: 0 | BL8: 0 | BM8: 0 | BN8: 0
A9: Moving in/out charges | C9: {=TRANSPOSE('July2026-EXPENSE'!N6:N69)} | D9: 0 | E9: 0 | F9: 0 | G9: 0 | H9: 0 | I9: 0 | J9: 0 | K9: 0 | L9: 0 | M9: 0 | N9: 0 | O9: 0 | P9: 0 | Q9: 0 | R9: 0 | S9: 0 | T9: 0 | U9: 0 | V9: 0 | W9: 0 | X9: 0 | Y9: 0 | Z9: 0 | AA9: 0 | AB9: 0 | AC9: 0 | AD9: 0 | AE9: 0 | AF9: 0 | AG9: 0 | AH9: 0 | AI9: 0 | AJ9: 0 | AK9: 0 | AL9: 0 | AM9: 0 | AN9: 0 | AO9: 0 | AP9: 0 | AQ9: 0 | AR9: 0 | AS9: 0 | AT9: 0 | AU9: 0 | AV9: 0 | AW9: 0 | AX9: 0 | AY9: 0 | AZ9: 0 | BA9: 0 | BB9: 0 | BC9: 0 | BD9: 0 | BE9: 0 | BF9: 0 | BG9: 0 | BH9: 0 | BI9: 0 | BJ9: 0 | BK9: 0 | BL9: 0 | BM9: 0 | BN9: 0
A10: Gym usage fee | C10: {=TRANSPOSE('July2026-EXPENSE'!O6:O69)} | D10: 0 | E10: 0 | F10: 0 | G10: 0 | H10: 0 | I10: 0 | J10: 0 | K10: 0 | L10: 0 | M10: 0 | N10: 0 | O10: 0 | P10: 0 | Q10: 0 | R10: 0 | S10: 0 | T10: 0 | U10: 0 | V10: 0 | W10: 0 | X10: 0 | Y10: 0 | Z10: 0 | AA10: 0 | AB10: 0 | AC10: 0 | AD10: 0 | AE10: 0 | AF10: 0 | AG10: 0 | AH10: 0 | AI10: 0 | AJ10: 0 | AK10: 0 | AL10: 0 | AM10: 0 | AN10: 0 | AO10: 0 | AP10: 0 | AQ10: 0 | AR10: 0 | AS10: 0 | AT10: 0 | AU10: 0 | AV10: 0 | AW10: 0 | AX10: 0 | AY10: 0 | AZ10: 0 | BA10: 0 | BB10: 0 | BC10: 0 | BD10: 0 | BE10: 0 | BF10: 0 | BG10: 0 | BH10: 0 | BI10: 0 | BJ10: 0 | BK10: 0 | BL10: 0 | BM10: 0 | BN10: 0
A11: {=TRANSPOSE('ANNUAL-EXPENSE-DETAILS'!B2:BC2)} | B11: {=TRANSPOSE('ANNUAL-EXPENSE-DETAILS'!B6:BC6)}
A12: STP SLUDGE CLEANING BALAJI | B12: 0
A13: STP MAINTENANCE | B13: 0 | C13: =$B13/64 | D13: =$B13/64 | E13: =$B13/64 | F13: =$B13/64 | G13: =$B13/64 | H13: =$B13/64 | I13: =$B13/64 | J13: =$B13/64 | ... BN13: =$B13/64
A14: STP MATERIALS | B14: 0 | C14: =$B14/64 | D14: =$B14/64 | E14: =$B14/64 | F14: =$B14/64 | G14: =$B14/64 | H14: =$B14/64 | I14: =$B14/64 | J14: =$B14/64 | ... BN14: =$B14/64
A15: STP REPAIR | B15: 0 | C15: =$B15/64 | D15: =$B15/64 | E15: =$B15/64 | F15: =$B15/64 | G15: =$B15/64 | H15: =$B15/64 | I15: =$B15/64 | J15: =$B15/64 | ... BN15: =$B15/64
A16: COMMON ELECTRICITY BILL | B16: 0 | C16: =$B16/64 | D16: =$B16/64 | E16: =$B16/64 | F16: =$B16/64 | G16: =$B16/64 | H16: =$B16/64 | I16: =$B16/64 | J16: =$B16/64 | ... BN16: =$B16/64
A17: BECOM Service tax | B17: 0 | C17: =$B17/64 | D17: =$B17/64 | E17: =$B17/64 | F17: =$B17/64 | G17: =$B17/64 | H17: =$B17/64 | I17: =$B17/64 | J17: =$B17/64 | ... BN17: =$B17/64
A18: SECURITY SERVICES | B18: 0 | C18: =$B18/64 | D18: =$B18/64 | E18: =$B18/64 | F18: =$B18/64 | G18: =$B18/64 | H18: =$B18/64 | I18: =$B18/64 | J18: =$B18/64 | ... BN18: =$B18/64
A19: GARBAGE REMOVAL | B19: 0 | C19: =$B19/64 | D19: =$B19/64 | E19: =$B19/64 | F19: =$B19/64 | G19: =$B19/64 | H19: =$B19/64 | I19: =$B19/64 | J19: =$B19/64 | ... BN19: =$B19/64
A20: PETTY CASH | B20: 0 | C20: =$B20/64 | D20: =$B20/64 | E20: =$B20/64 | F20: =$B20/64 | G20: =$B20/64 | H20: =$B20/64 | I20: =$B20/64 | J20: =$B20/64 | ... BN20: =$B20/64
A21: ELEVATOR MAINTENANCE | B21: 0 | C21: =$B21/64 | D21: =$B21/64 | E21: =$B21/64 | F21: =$B21/64 | G21: =$B21/64 | H21: =$B21/64 | I21: =$B21/64 | J21: =$B21/64 | ... BN21: =$B21/64
A22: MOTOR REPAIR | B22: 0 | C22: =$B22/64 | D22: =$B22/64 | E22: =$B22/64 | F22: =$B22/64 | G22: =$B22/64 | H22: =$B22/64 | I22: =$B22/64 | J22: =$B22/64 | ... BN22: =$B22/64
A23: PLUMBING MATERIAL | B23: 0 | C23: =$B23/64 | D23: =$B23/64 | E23: =$B23/64 | F23: =$B23/64 | G23: =$B23/64 | H23: =$B23/64 | I23: =$B23/64 | J23: =$B23/64 | ... BN23: =$B23/64
A24: ELECTRICITY MATERIAL | B24: 0 | C24: =$B24/64 | D24: =$B24/64 | E24: =$B24/64 | F24: =$B24/64 | G24: =$B24/64 | H24: =$B24/64 | I24: =$B24/64 | J24: =$B24/64 | ... BN24: =$B24/64
... A60: Speed Breaker near the gate | B60: 0 | C60: =$B60/64 | D60: =$B60/64 | E60: =$B60/64 | F60: =$B60/64 | G60: =$B60/64 | H60: =$B60/64 | I60: =$B60/64 | J60: =$B60/64 | ... BN60: =$B60/64
A61: Gym Equipment Repairs | B61: 0 | C61: =SUM(C6,C13:C60) | D61: =SUM(D6,D13:D60) | E61: =SUM(E6,E13:E60) | F61: =SUM(F6,F13:F60) | G61: =SUM(G6,G13:G60) | H61: =SUM(H6,H13:H60) | I61: =SUM(I6,I13:I60) | J61: =SUM(J6,J13:J60) | ... BN61: =SUM(BN6,BN13:BN60)
A62: Additional Waste Disposal | B62: 0
A63: Swimming Pool Cleaning | B63: 0
A64: HOUSE KEEPING MATERIALS | B64: 0

Sheet July2026-EXPENSE-Flatwise-Trans
A1: {=TRANSPOSE('July2026-EXPENSE-Flatwise'!A1:BN61)} | B1: Water consumption (Litres) | C1: Water consumption (%age of total) | D1: Water meter rent | E1: Common meter rent (eq. distributed) | F1: Total water related expense | G1: Society Parking Rent | H1: Clubhouse booking fee | I1: Moving in/out charges | J1: Gym usage fee | K1: DRINKING WATER SLN WATER SUP | L1: STP SLUDGE CLEANING BALAJI | M1: STP MAINTENANCE | N1: STP MATERIALS | O1: STP REPAIR | P1: COMMON ELECTRICITY BILL | Q1: BECOM Service tax | R1: SECURITY SERVICES | S1: GARBAGE REMOVAL | T1: PETTY CASH | U1: ELEVATOR MAINTENANCE | V1: MOTOR REPAIR | W1: PLUMBING MATERIAL | X1: ELECTRICITY MATERIAL | Y1: ELECTRICITY MATERIAL | Z1: TRANSFORMER REPAIR | AA1: GENERATOR MAINTENANCE EPITOME | AB1: GARDENING | AC1: PLUMBER WAGE | AD1: ELECTRICIAN WAGE | AE1: MANAGER WAGE | AF1: TANK AND SUMP CLEANING | AG1: SECURITY WATER EXPENSES GREENMART | AH1: SWIMMING POOL MOTOR REPAIR | AI1: CCTV REPAIR | AJ1: CCTV monitor | AK1: WATER PIPE | AL1: RAILING FOR STAIRCASE | AM1: Play area sand | AN1: BARBED WIRE REPAIR | AO1: DRIED LEAVES REMOVAL | AP1: DRAIN CLEANING | AQ1: Security room & Play area painting | AR1: Play area sand removal & cracks filling | AS1: Front garden cleaning and red soil filling | AT1: Landscaping work for STP water disposal | AU1: ACCOUNTING | AV1: Lift Painting | AW1: Lift wiring sepration | AX1: Earthing repair | AY1: Pest Control | AZ1: Freshwater pipe repair | BA1: NBH device replacement | BB1: NBH VMS | BC1: REPAIRS | BD1: Cricket Net | BE1: LOOK AHEAD EXPENSE | BF1: Rear bondary cleaning | BG1: 9,7,8,11 series terrace pipe repairs | BH1: Speed Breaker near the gate | BI1: Gym Equipment Repairs
A2: 0 | B2: 0 | C2: 0 | D2: 0 | E2: 0 | F2: 0 | G2: 0 | H2: 0 | I2: 0 | J2: 0 | K2: 0 | L2: 0 | M2: 0 | N2: 0 | O2: 0 | P2: 0 | Q2: 0 | R2: 0 | S2: 0 | T2: 0 | U2: 0 | V2: 0 | W2: 0 | X2: 0 | Y2: 0 | Z2: 0 | AA2: 0 | AB2: 0 | AC2: 0 | AD2: 0 | AE2: 0 | AF2: 0 | AG2: 0 | AH2: 0 | AI2: 0 | AJ2: 0 | AK2: 0 | AL2: 0 | AM2: 0 | AN2: 0 | AO2: 0 | AP2: 0 | AQ2: 0 | AR2: 0 | AS2: 0 | AT2: 0 | AU2: 0 | AV2: 0 | AW2: 0 | AX2: 0 | AY2: 0 | AZ2: 0 | BA2: 0 | BB2: 0 | BC2: 0 | BD2: 0 | BE2: 0 | BF2: 0 | BG2: 0 | BH2: 0 | BI2: 0
A3: F1 | B3: 0 | C3: 0 | D3: 0 | E3: 0 | F3: 0 | G3: 0 | H3: 0 | I3: 0 | J3: 0 | K3: 0 | L3: 0 | M3: 0 | N3: 0 | O3: 0 | P3: 0 | Q3: 0 | R3: 0 | S3: 0 | T3: 0 | U3: 0 | V3: 0 | W3: 0 | X3: 0 | Y3: 0 | Z3: 0 | AA3: 0 | AB3: 0 | AC3: 0 | AD3: 0 | AE3: 0 | AF3: 0 | AG3: 0 | AH3: 0 | AI3: 0 | AJ3: 0 | AK3: 0 | AL3: 0 | AM3: 0 | AN3: 0 | AO3: 0 | AP3: 0 | AQ3: 0 | AR3: 0 | AS3: 0 | AT3: 0 | AU3: 0 | AV3: 0 | AW3: 0 | AX3: 0 | AY3: 0 | AZ3: 0 | BA3: 0 | BB3: 0 | BC3: 0 | BD3: 0 | BE3: 0 | BF3: 0 | BG3: 0 | BH3: 0 | BI3: 0
A4: F2 | B4: 0 | C4: 0 | D4: 0 | E4: 0 | F4: 0 | G4: 0 | H4: 0 | I4: 0 | J4: 0 | K4: 0 | L4: 0 | M4: 0 | N4: 0 | O4: 0 | P4: 0 | Q4: 0 | R4: 0 | S4: 0 | T4: 0 | U4: 0 | V4: 0 | W4: 0 | X4: 0 | Y4: 0 | Z4: 0 | AA4: 0 | AB4: 0 | AC4: 0 | AD4: 0 | AE4: 0 | AF4: 0 | AG4: 0 | AH4: 0 | AI4: 0 | AJ4: 0 | AK4: 0 | AL4: 0 | AM4: 0 | AN4: 0 | AO4: 0 | AP4: 0 | AQ4: 0 | AR4: 0 | AS4: 0 | AT4: 0 | AU4: 0 | AV4: 0 | AW4: 0 | AX4: 0 | AY4: 0 | AZ4: 0 | BA4: 0 | BB4: 0 | BC4: 0 | BD4: 0 | BE4: 0 | BF4: 0 | BG4: 0 | BH4: 0 | BI4: 0
A5: F3 | B5: 0 | C5: 0 | D5: 0 | E5: 0 | F5: 0 | G5: 0 | H5: 0 | I5: 0 | J5: 0 | K5: 0 | L5: 0 | M5: 0 | N5: 0 | O5: 0 | P5: 0 | Q5: 0 | R5: 0 | S5: 0 | T5: 0 | U5: 0 | V5: 0 | W5: 0 | X5: 0 | Y5: 0 | Z5: 0 | AA5: 0 | AB5: 0 | AC5: 0 | AD5: 0 | AE5: 0 | AF5: 0 | AG5: 0 | AH5: 0 | AI5: 0 | AJ5: 0 | AK5: 0 | AL5: 0 | AM5: 0 | AN5: 0 | AO5: 0 | AP5: 0 | AQ5: 0 | AR5: 0 | AS5: 0 | AT5: 0 | AU5: 0 | AV5: 0 | AW5: 0 | AX5: 0 | AY5: 0 | AZ5: 0 | BA5: 0 | BB5: 0 | BC5: 0 | BD5: 0 | BE5: 0 | BF5: 0 | BG5: 0 | BH5: 0 | BI5: 0
A6: F4 | B6: 0 | C6: 0 | D6: 0 | E6: 0 | F6: 0 | G6: 0 | H6: 0 | I6: 0 | J6: 0 | K6: 0 | L6: 0 | M6: 0 | N6: 0 | O6: 0 | P6: 0 | Q6: 0 | R6: 0 | S6: 0 | T6: 0 | U6: 0 | V6: 0 | W6: 0 | X6: 0 | Y6: 0 | Z6: 0 | AA6: 0 | AB6: 0 | AC6: 0 | AD6: 0 | AE6: 0 | AF6: 0 | AG6: 0 | AH6: 0 | AI6: 0 | AJ6: 0 | AK6: 0 | AL6: 0 | AM6: 0 | AN6: 0 | AO6: 0 | AP6: 0 | AQ6: 0 | AR6: 0 | AS6: 0 | AT6: 0 | AU6: 0 | AV6: 0 | AW6: 0 | AX6: 0 | AY6: 0 | AZ6: 0 | BA6: 0 | BB6: 0 | BC6: 0 | BD6: 0 | BE6: 0 | BF6: 0 | BG6: 0 | BH6: 0 | BI6: 0
A7: F5 | B7: 0 | C7: 0 | D7: 0 | E7: 0 | F7: 0 | G7: 0 | H7: 0 | I7: 0 | J7: 0 | K7: 0 | L7: 0 | M7: 0 | N7: 0 | O7: 0 | P7: 0 | Q7: 0 | R7: 0 | S7: 0 | T7: 0 | U7: 0 | V7: 0 | W7: 0 | X7: 0 | Y7: 0 | Z7: 0 | AA7: 0 | AB7: 0 | AC7: 0 | AD7: 0 | AE7: 0 | AF7: 0 | AG7: 0 | AH7: 0 | AI7: 0 | AJ7: 0 | AK7: 0 | AL7: 0 | AM7: 0 | AN7: 0 | AO7: 0 | AP7: 0 | AQ7: 0 | AR7: 0 | AS7: 0 | AT7: 0 | AU7: 0 | AV7: 0 | AW7: 0 | AX7: 0 | AY7: 0 | AZ7: 0 | BA7: 0 | BB7: 0 | BC7: 0 | BD7: 0 | BE7: 0 | BF7: 0 | BG7: 0 | BH7: 0 | BI7: 0
A8: F6 | B8: 0 | C8: 0 | D8: 0 | E8: 0 | F8: 0 | G8: 0 | H8: 0 | I8: 0 | J8: 0 | K8: 0 | L8: 0 | M8: 0 | N8: 0 | O8: 0 | P8: 0 | Q8: 0 | R8: 0 | S8: 0 | T8: 0 | U8: 0 | V8: 0 | W8: 0 | X8: 0 | Y8: 0 | Z8: 0 | AA8: 0 | AB8: 0 | AC8: 0 | AD8: 0 | AE8: 0 | AF8: 0 | AG8: 0 | AH8: 0 | AI8: 0 | AJ8: 0 | AK8: 0 | AL8: 0 | AM8: 0 | AN8: 0 | AO8: 0 | AP8: 0 | AQ8: 0 | AR8: 0 | AS8: 0 | AT8: 0 | AU8: 0 | AV8: 0 | AW8: 0 | AX8: 0 | AY8: 0 | AZ8: 0 | BA8: 0 | BB8: 0 | BC8: 0 | BD8: 0 | BE8: 0 | BF8: 0 | BG8: 0 | BH8: 0 | BI8: 0
A9: F7 | B9: 0 | C9: 0 | D9: 0 | E9: 0 | F9: 0 | G9: 0 | H9: 0 | I9: 0 | J9: 0 | K9: 0 | L9: 0 | M9: 0 | N9: 0 | O9: 0 | P9: 0 | Q9: 0 | R9: 0 | S9: 0 | T9: 0 | U9: 0 | V9: 0 | W9: 0 | X9: 0 | Y9: 0 | Z9: 0 | AA9: 0 | AB9: 0 | AC9: 0 | AD9: 0 | AE9: 0 | AF9: 0 | AG9: 0 | AH9: 0 | AI9: 0 | AJ9: 0 | AK9: 0 | AL9: 0 | AM9: 0 | AN9: 0 | AO9: 0 | AP9: 0 | AQ9: 0 | AR9: 0 | AS9: 0 | AT9: 0 | AU9: 0 | AV9: 0 | AW9: 0 | AX9: 0 | AY9: 0 | AZ9: 0 | BA9: 0 | BB9: 0 | BC9: 0 | BD9: 0 | BE9: 0 | BF9: 0 | BG9: 0 | BH9: 0 | BI9: 0
A10: F8 | B10: 0 | C10: 0 | D10: 0 | E10: 0 | F10: 0 | G10: 0 | H10: 0 | I10: 0 | J10: 0 | K10: 0 | L10: 0 | M10: 0 | N10: 0 | O10: 0 | P10: 0 | Q10: 0 | R10: 0 | S10: 0 | T10: 0 | U10: 0 | V10: 0 | W10: 0 | X10: 0 | Y10: 0 | Z10: 0 | AA10: 0 | AB10: 0 | AC10: 0 | AD10: 0 | AE10: 0 | AF10: 0 | AG10: 0 | AH10: 0 | AI10: 0 | AJ10: 0 | AK10: 0 | AL10: 0 | AM10: 0 | AN10: 0 | AO10: 0 | AP10: 0 | AQ10: 0 | AR10: 0 | AS10: 0 | AT10: 0 | AU10: 0 | AV10: 0 | AW10: 0 | AX10: 0 | AY10: 0 | AZ10: 0 | BA10: 0 | BB10: 0 | BC10: 0 | BD10: 0 | BE10: 0 | BF10: 0 | BG10: 0 | BH10: 0 | BI10: 0
A11: F9 | B11: 0 | C11: 0 | D11: 0 | E11: 0 | F11: 0 | G11: 0 | H11: 0 | I11: 0 | J11: 0 | K11: 0 | L11: 0 | M11: 0 | N11: 0 | O11: 0 | P11: 0 | Q11: 0 | R11: 0 | S11: 0 | T11: 0 | U11: 0 | V11: 0 | W11: 0 | X11: 0 | Y11: 0 | Z11: 0 | AA11: 0 | AB11: 0 | AC11: 0 | AD11: 0 | AE11: 0 | AF11: 0 | AG11: 0 | AH11: 0 | AI11: 0 | AJ11: 0 | AK11: 0 | AL11: 0 | AM11: 0 | AN11: 0 | AO11: 0 | AP11: 0 | AQ11: 0 | AR11: 0 | AS11: 0 | AT11: 0 | AU11: 0 | AV11: 0 | AW11: 0 | AX11: 0 | AY11: 0 | AZ11: 0 | BA11: 0 | BB11: 0 | BC11: 0 | BD11: 0 | BE11: 0 | BF11: 0 | BG11: 0 | BH11: 0 | BI11: 0
A12: F10 | B12: 0 | C12: 0 | D12: 0 | E12: 0 | F12: 0 | G12: 0 | H12: 0 | I12: 0 | J12: 0 | K12: 0 | L12: 0 | M12: 0 | N12: 0 | O12: 0 | P12: 0 | Q12: 0 | R12: 0 | S12: 0 | T12: 0 | U12: 0 | V12: 0 | W12: 0 | X12: 0 | Y12: 0 | Z12: 0 | AA12: 0 | AB12: 0 | AC12: 0 | AD12: 0 | AE12: 0 | AF12: 0 | AG12: 0 | AH12: 0 | AI12: 0 | AJ12: 0 | AK12: 0 | AL12: 0 | AM12: 0 | AN12: 0 | AO12: 0 | AP12: 0 | AQ12: 0 | AR12: 0 | AS12: 0 | AT12: 0 | AU12: 0 | AV12: 0 | AW12: 0 | AX12: 0 | AY12: 0 | AZ12: 0 | BA12: 0 | BB12: 0 | BC12: 0 | BD12: 0 | BE12: 0 | BF12: 0 | BG12: 0 | BH12: 0 | BI12: 0
A13: F11 | B13: 0 | C13: 0 | D13: 0 | E13: 0 | F13: 0 | G13: 0 | H13: 0 | I13: 0 | J13: 0 | K13: 0 | L13: 0 | M13: 0 | N13: 0 | O13: 0 | P13: 0 | Q13: 0 | R13: 0 | S13: 0 | T13: 0 | U13: 0 | V13: 0 | W13: 0 | X13: 0 | Y13: 0 | Z13: 0 | AA13: 0 | AB13: 0 | AC13: 0 | AD13: 0 | AE13: 0 | AF13: 0 | AG13: 0 | AH13: 0 | AI13: 0 | AJ13: 0 | AK13: 0 | AL13: 0 | AM13: 0 | AN13: 0 | AO13: 0 | AP13: 0 | AQ13: 0 | AR13: 0 | AS13: 0 | AT13: 0 | AU13: 0 | AV13: 0 | AW13: 0 | AX13: 0 | AY13: 0 | AZ13: 0 | BA13: 0 | BB13: 0 | BC13: 0 | BD13: 0 | BE13: 0 | BF13: 0 | BG13: 0 | BH13: 0 | BI13: 0
A14: F12 | B14: 0 | C14: 0 | D14: 0 | E14: 0 | F14: 0 | G14: 0 | H14: 0 | I14: 0 | J14: 0 | K14: 0 | L14: 0 | M14: 0 | N14: 0 | O14: 0 | P14: 0 | Q14: 0 | R14: 0 | S14: 0 | T14: 0 | U14: 0 | V14: 0 | W14: 0 | X14: 0 | Y14: 0 | Z14: 0 | AA14: 0 | AB14: 0 | AC14: 0 | AD14: 0 | AE14: 0 | AF14: 0 | AG14: 0 | AH14: 0 | AI14: 0 | AJ14: 0 | AK14: 0 | AL14: 0 | AM14: 0 | AN14: 0 | AO14: 0 | AP14: 0 | AQ14: 0 | AR14: 0 | AS14: 0 | AT14: 0 | AU14: 0 | AV14: 0 | AW14: 0 | AX14: 0 | AY14: 0 | AZ14: 0 | BA14: 0 | BB14: 0 | BC14: 0 | BD14: 0 | BE14: 0 | BF14: 0 | BG14: 0 | BH14: 0 | BI14: 0
... A66: T16 | B66: 0 | C66: 0 | D66: 0 | E66: 0 | F66: 0 | G66: 0 | H66: 0 | I66: 0 | J66: 0 | K66: 0 | L66: 0 | M66: 0 | N66: 0 | O66: 0 | P66: 0 | Q66: 0 | R66: 0 | S66: 0 | T66: 0 | U66: 0 | V66: 0 | W66: 0 | X66: 0 | Y66: 0 | Z66: 0 | AA66: 0 | AB66: 0 | AC66: 0 | AD66: 0 | AE66: 0 | AF66: 0 | AG66: 0 | AH66: 0 | AI66: 0 | AJ66: 0 | AK66: 0 | AL66: 0 | AM66: 0 | AN66: 0 | AO66: 0 | AP66: 0 | AQ66: 0 | AR66: 0 | AS66: 0 | AT66: 0 | AU66: 0 | AV66: 0 | AW66: 0 | AX66: 0 | AY66: 0 | AZ66: 0 | BA66: 0 | BB66: 0 | BC66: 0 | BD66: 0 | BE66: 0 | BF66: 0 | BG66: 0 | BH66: 0 | BI66: 0

Sheet July2026-COLLECTION
A1: FLAT # | C1: Amount | D1: Date | E1: Amount | F1: Date | G1: Amount | H1: Date | I1: Amount | J1: Date | K1: Total
A2: F1 | B2: Shailesh Srivastava / Azeem Nawaz | K2: =SUM(C2,E2,G2,I2)
A3: F2 | B3: Shanthanu | K3: =SUM(C3,E3,G3,I3)
A4: F3 | B4: Samrat Kar | K4: =SUM(C4,E4,G4,I4)
A5: F4 | B5: Renu R | K5: =SUM(C5,E5,G5,I5)
A6: F5 | B6: Vamsidhar Bethanabatla / Madhuri Anumula | K6: =SUM(C6,E6,G6,I6)
A7: F6 | B7: Meghana Viral Shah and Vviral Shah (Owner) / Sangeet and Swagat (Tenent) | K7: =SUM(C7,E7,G7,I7)
A8: F7 | B8: Vimal NK | K8: =SUM(C8,E8,G8,I8)
A9: F8 | B9: Sujeet Kumar (Tenant)/Sreejith Menon (Owner) | K9: =SUM(C9,E9,G9,I9)
A10: F9 | B10: Vijay Suswaram (Owner) / Divya Shikha (Tenant) | K10: =SUM(C10,E10,G10,I10)
A11: F10 | B11: Aby Thomas | K11: =SUM(C11,E11,G11,I11)
A12: F11 | B12: N. Geetha | K12: =SUM(C12,E12,G12,I12)
A13: F12 | B13: Anirudh Singh | K13: =SUM(C13,E13,G13,I13)
... A65: T16 | B65: Madhusoodanan P.R. | K65: =SUM(C65,E65,G65,I65)
A66: TOTAL | K66: =SUM(K2:K65)

Sheet Aug2026-EXPENSE
B1: AUG 2026 EXPENSES
A2: FLAT # | B2: 1 | C2: WATER USED IN LTRS | D2: COMMON AREA EQUALLY DEVIDED | E2: TOTAL FRESH WATER CONSUMED | F2: %OF TOTAL USED | G2: WATER EXPENSE SHARING BY % | H2: #METERS | I2: METER RENT | J2: COMMON AREA METER RENT + WATER EXPENSE+ FLAT METER RENT | K2: FIXED EXPENSE SHARE | L2: PARKING FEE | M2: CLUB HOUSE BOOKING | N2: SHIFTING FEE | O2: GYM USAGE FEE | R2: TOTAL EXPENSE TO BE PAID
A3: CH | B3: MPFOWA | D3: 0 | H3: 1 | I3: =T7
A4: GYM | B4: MPFOWA | D4: 0 | H4: 1 | I4: =T7 | S4: TOTAL FIXED EXPENSE | T4: ='ANNUAL-EXPENSE-DETAILS'!BF7
A5: BSMT | B5: MPFOWA | D5: 0 | H5: 1 | I5: =T7 | S5: TOTAL WATER EXPENSE | T5: ='ANNUAL-EXPENSE-DETAILS'!BE7
A6: F1 | B6: Shailesh Srivastava / Azeem Nawaz | C6: 0 | D6: =SUM($C$3:$C$5)/64 | E6: =C6+D6 | F6: =IF($C$70=0, 0, E6/$C$70) | G6: =F6*$T$5 | H6: 3 | I6: =$T$7*H6 | J6: =G6+$T$9+I6 | K6: =$T$11/64 | L6: 0 | M6: 0 | N6: 0 | O6: 0 | R6: =(J6+K6+L6+M6+N6+O6)*$B$2
A7: F2 | B7: Shanthanu | C7: 0 | D7: =SUM($C$3:$C$5)/64 | E7: =C7+D7 | F7: =IF($C$70=0, 0, E7/$C$70) | G7: =F7*$T$5 | H7: 4 | I7: =$T$7*H7 | J7: =G7+$T$9+I7 | K7: =$T$11/64 | L7: 0 | M7: 0 | N7: 0 | O7: 0 | R7: =(J7+K7+L7+M7+N7+O7)*$B$2 | S7: RENT PER METER | T7: 117.81166
A8: F3 | B8: Samrat Kar | C8: 0 | D8: =SUM($C$3:$C$5)/64 | E8: =C8+D8 | F8: =IF($C$70=0, 0, E8/$C$70) | G8: =F8*$T$5 | H8: 4 | I8: =$T$7*H8 | J8: =G8+$T$9+I8 | K8: =$T$11/64 | L8: 0 | M8: 0 | N8: 0 | O8: 0 | R8: =(J8+K8+L8+M8+N8+O8)*$B$2 | S8: COMMON AREA METER RENT | T8: =$T$7*3
A9: F4 | B9: Renu R | C9: 0 | D9: =SUM($C$3:$C$5)/64 | E9: =C9+D9 | F9: =IF($C$70=0, 0, E9/$C$70) | G9: =F9*$T$5 | H9: 4 | I9: =$T$7*H9 | J9: =G9+$T$9+I9 | K9: =$T$11/64 | L9: 0 | M9: 0 | N9: 0 | O9: 0 | R9: =(J9+K9+L9+M9+N9+O9)*$B$2 | S9: COMMON AREA METER RENT/FLAT | T9: =T8/64
A10: F5 | B10: Vamsidhar Bethanabatla / Madhuri Anumula | C10: 0 | D10: =SUM($C$3:$C$5)/64 | E10: =C10+D10 | F10: =IF($C$70=0, 0, E10/$C$70) | G10: =F10*$T$5 | H10: 3 | I10: =$T$7*H10 | J10: =G10+$T$9+I10 | K10: =$T$11/64 | L10: 0 | M10: 0 | N10: 0 | O10: 0 | R10: =(J10+K10+L10+M10+N10+O10)*$B$2
A11: F6 | B11: Meghana Viral Shah and Vviral Shah (Owner) / Sangeet and Swagat (Tenent) | C11: 0 | D11: =SUM($C$3:$C$5)/64 | E11: =C11+D11 | F11: =IF($C$70=0, 0, E11/$C$70) | G11: =F11*$T$5 | H11: 3 | I11: =$T$7*H11 | J11: =G11+$T$9+I11 | K11: =$T$11/64 | L11: 0 | M11: 0 | N11: 0 | O11: 0 | R11: =(J11+K11+L11+M11+N11+O11)*$B$2 | S11: TOTAL FIXED EXPENSE | T11: ='ANNUAL-EXPENSE-DETAILS'!BF7
